2022-04-19 10:25:32,995 django.utils.autoreload INFO     Watching for file changes with StatReloader
2022-04-19 10:26:39,635 django.utils.autoreload INFO     C:\Users\amand\python-cordarme\drf-api\tamarcado\settings\dev.py changed, reloading.
2022-04-19 10:27:51,955 django.utils.autoreload INFO     Watching for file changes with StatReloader
2022-04-19 10:28:26,978 root         INFO     Fazendo requisição para BrasilAPI para a data: 2022-04-12
2022-04-19 10:28:26,986 urllib3.connectionpool DEBUG    Starting new HTTPS connection (1): brasilapi.com.br:443
2022-04-19 10:28:27,102 urllib3.connectionpool DEBUG    https://brasilapi.com.br:443 "GET /api/feriados/v1/2022 HTTP/1.1" 200 None
2022-04-28 11:12:09,261 django.utils.autoreload INFO     Watching for file changes with StatReloader
2022-04-28 11:12:21,208 django.request WARNING  Not Found: /
2022-04-28 11:12:21,388 django.request WARNING  Not Found: /favicon.ico
2022-04-28 12:36:52,719 django.request ERROR    Internal Server Error: /api/funcionarios/
Traceback (most recent call last):
  File "C:\Users\amand\python-cordarme\drf-api\venv\lib\site-packages\django\db\backends\utils.py", line 85, in _execute
    return self.cursor.execute(sql, params)
  File "C:\Users\amand\python-cordarme\drf-api\venv\lib\site-packages\django\db\backends\sqlite3\base.py", line 416, in execute
    return Database.Cursor.execute(self, query, params)
sqlite3.IntegrityError: NOT NULL constraint failed: agenda_funcionarios.prestador_id

The above exception was the direct cause of the following exception:

Traceback (most recent call last):
  File "C:\Users\amand\python-cordarme\drf-api\venv\lib\site-packages\django\core\handlers\exception.py", line 47, in inner
    response = get_response(request)
  File "C:\Users\amand\python-cordarme\drf-api\venv\lib\site-packages\django\core\handlers\base.py", line 181, in _get_response
    response = wrapped_callback(request, *callback_args, **callback_kwargs)
  File "C:\Users\amand\python-cordarme\drf-api\venv\lib\site-packages\django\views\decorators\csrf.py", line 54, in wrapped_view
    return view_func(*args, **kwargs)
  File "C:\Users\amand\python-cordarme\drf-api\venv\lib\site-packages\django\views\generic\base.py", line 69, in view
    return self.dispatch(request, *args, **kwargs)
  File "C:\Users\amand\python-cordarme\drf-api\venv\lib\site-packages\rest_framework\views.py", line 509, in dispatch
    response = self.handle_exception(exc)
  File "C:\Users\amand\python-cordarme\drf-api\venv\lib\site-packages\rest_framework\views.py", line 469, in handle_exception
    self.raise_uncaught_exception(exc)
  File "C:\Users\amand\python-cordarme\drf-api\venv\lib\site-packages\rest_framework\views.py", line 480, in raise_uncaught_exception
    raise exc
  File "C:\Users\amand\python-cordarme\drf-api\venv\lib\site-packages\rest_framework\views.py", line 506, in dispatch
    response = handler(request, *args, **kwargs)
  File "C:\Users\amand\python-cordarme\drf-api\agenda\views.py", line 158, in post
    Funcionarios.objects.create(
  File "C:\Users\amand\python-cordarme\drf-api\venv\lib\site-packages\django\db\models\manager.py", line 85, in manager_method
    return getattr(self.get_queryset(), name)(*args, **kwargs)
  File "C:\Users\amand\python-cordarme\drf-api\venv\lib\site-packages\django\db\models\query.py", line 457, in create
    obj.save(force_insert=True, using=self.db)
  File "C:\Users\amand\python-cordarme\drf-api\venv\lib\site-packages\django\db\models\base.py", line 743, in save
    self.save_base(using=using, force_insert=force_insert,
  File "C:\Users\amand\python-cordarme\drf-api\venv\lib\site-packages\django\db\models\base.py", line 780, in save_base
    updated = self._save_table(
  File "C:\Users\amand\python-cordarme\drf-api\venv\lib\site-packages\django\db\models\base.py", line 885, in _save_table
    results = self._do_insert(cls._base_manager, using, fields, returning_fields, raw)
  File "C:\Users\amand\python-cordarme\drf-api\venv\lib\site-packages\django\db\models\base.py", line 923, in _do_insert
    return manager._insert(
  File "C:\Users\amand\python-cordarme\drf-api\venv\lib\site-packages\django\db\models\manager.py", line 85, in manager_method
    return getattr(self.get_queryset(), name)(*args, **kwargs)
  File "C:\Users\amand\python-cordarme\drf-api\venv\lib\site-packages\django\db\models\query.py", line 1301, in _insert
    return query.get_compiler(using=using).execute_sql(returning_fields)
  File "C:\Users\amand\python-cordarme\drf-api\venv\lib\site-packages\django\db\models\sql\compiler.py", line 1441, in execute_sql
    cursor.execute(sql, params)
  File "C:\Users\amand\python-cordarme\drf-api\venv\lib\site-packages\django\db\backends\utils.py", line 99, in execute
    return super().execute(sql, params)
  File "C:\Users\amand\python-cordarme\drf-api\venv\lib\site-packages\django\db\backends\utils.py", line 67, in execute
    return self._execute_with_wrappers(sql, params, many=False, executor=self._execute)
  File "C:\Users\amand\python-cordarme\drf-api\venv\lib\site-packages\django\db\backends\utils.py", line 76, in _execute_with_wrappers
    return executor(sql, params, many, context)
  File "C:\Users\amand\python-cordarme\drf-api\venv\lib\site-packages\django\db\backends\utils.py", line 80, in _execute
    with self.db.wrap_database_errors:
  File "C:\Users\amand\python-cordarme\drf-api\venv\lib\site-packages\django\db\utils.py", line 90, in __exit__
    raise dj_exc_value.with_traceback(traceback) from exc_value
  File "C:\Users\amand\python-cordarme\drf-api\venv\lib\site-packages\django\db\backends\utils.py", line 85, in _execute
    return self.cursor.execute(sql, params)
  File "C:\Users\amand\python-cordarme\drf-api\venv\lib\site-packages\django\db\backends\sqlite3\base.py", line 416, in execute
    return Database.Cursor.execute(self, query, params)
django.db.utils.IntegrityError: NOT NULL constraint failed: agenda_funcionarios.prestador_id
2022-04-28 12:37:25,381 django.utils.autoreload INFO     Watching for file changes with StatReloader
2022-05-04 21:51:23,077 django.utils.autoreload INFO     Watching for file changes with StatReloader
2022-05-04 21:52:15,314 django.request ERROR    Internal Server Error: /api/estabelecimentos/
Traceback (most recent call last):
  File "C:\Users\amand\python-cordarme\drf-api\venv\lib\site-packages\django\db\backends\utils.py", line 85, in _execute
    return self.cursor.execute(sql, params)
  File "C:\Users\amand\python-cordarme\drf-api\venv\lib\site-packages\django\db\backends\sqlite3\base.py", line 416, in execute
    return Database.Cursor.execute(self, query, params)
sqlite3.IntegrityError: UNIQUE constraint failed: agenda_estabelecimento.nome_estabelecimento

The above exception was the direct cause of the following exception:

Traceback (most recent call last):
  File "C:\Users\amand\python-cordarme\drf-api\venv\lib\site-packages\django\core\handlers\exception.py", line 47, in inner
    response = get_response(request)
  File "C:\Users\amand\python-cordarme\drf-api\venv\lib\site-packages\django\core\handlers\base.py", line 181, in _get_response
    response = wrapped_callback(request, *callback_args, **callback_kwargs)
  File "C:\Users\amand\python-cordarme\drf-api\venv\lib\site-packages\django\views\decorators\csrf.py", line 54, in wrapped_view
    return view_func(*args, **kwargs)
  File "C:\Users\amand\python-cordarme\drf-api\venv\lib\site-packages\django\views\generic\base.py", line 69, in view
    return self.dispatch(request, *args, **kwargs)
  File "C:\Users\amand\python-cordarme\drf-api\venv\lib\site-packages\rest_framework\views.py", line 509, in dispatch
    response = self.handle_exception(exc)
  File "C:\Users\amand\python-cordarme\drf-api\venv\lib\site-packages\rest_framework\views.py", line 469, in handle_exception
    self.raise_uncaught_exception(exc)
  File "C:\Users\amand\python-cordarme\drf-api\venv\lib\site-packages\rest_framework\views.py", line 480, in raise_uncaught_exception
    raise exc
  File "C:\Users\amand\python-cordarme\drf-api\venv\lib\site-packages\rest_framework\views.py", line 506, in dispatch
    response = handler(request, *args, **kwargs)
  File "C:\Users\amand\python-cordarme\drf-api\venv\lib\site-packages\rest_framework\generics.py", line 242, in post
    return self.create(request, *args, **kwargs)
  File "C:\Users\amand\python-cordarme\drf-api\venv\lib\site-packages\rest_framework\mixins.py", line 19, in create
    self.perform_create(serializer)
  File "C:\Users\amand\python-cordarme\drf-api\venv\lib\site-packages\rest_framework\mixins.py", line 24, in perform_create
    serializer.save()
  File "C:\Users\amand\python-cordarme\drf-api\venv\lib\site-packages\rest_framework\serializers.py", line 212, in save
    self.instance = self.create(validated_data)
  File "C:\Users\amand\python-cordarme\drf-api\venv\lib\site-packages\rest_framework\serializers.py", line 962, in create
    instance = ModelClass._default_manager.create(**validated_data)
  File "C:\Users\amand\python-cordarme\drf-api\venv\lib\site-packages\django\db\models\manager.py", line 85, in manager_method
    return getattr(self.get_queryset(), name)(*args, **kwargs)
  File "C:\Users\amand\python-cordarme\drf-api\venv\lib\site-packages\django\db\models\query.py", line 457, in create
    obj.save(force_insert=True, using=self.db)
  File "C:\Users\amand\python-cordarme\drf-api\venv\lib\site-packages\django\db\models\base.py", line 743, in save
    self.save_base(using=using, force_insert=force_insert,
  File "C:\Users\amand\python-cordarme\drf-api\venv\lib\site-packages\django\db\models\base.py", line 780, in save_base
    updated = self._save_table(
  File "C:\Users\amand\python-cordarme\drf-api\venv\lib\site-packages\django\db\models\base.py", line 885, in _save_table
    results = self._do_insert(cls._base_manager, using, fields, returning_fields, raw)
  File "C:\Users\amand\python-cordarme\drf-api\venv\lib\site-packages\django\db\models\base.py", line 923, in _do_insert
    return manager._insert(
  File "C:\Users\amand\python-cordarme\drf-api\venv\lib\site-packages\django\db\models\manager.py", line 85, in manager_method
    return getattr(self.get_queryset(), name)(*args, **kwargs)
  File "C:\Users\amand\python-cordarme\drf-api\venv\lib\site-packages\django\db\models\query.py", line 1301, in _insert
    return query.get_compiler(using=using).execute_sql(returning_fields)
  File "C:\Users\amand\python-cordarme\drf-api\venv\lib\site-packages\django\db\models\sql\compiler.py", line 1441, in execute_sql
    cursor.execute(sql, params)
  File "C:\Users\amand\python-cordarme\drf-api\venv\lib\site-packages\django\db\backends\utils.py", line 99, in execute
    return super().execute(sql, params)
  File "C:\Users\amand\python-cordarme\drf-api\venv\lib\site-packages\django\db\backends\utils.py", line 67, in execute
    return self._execute_with_wrappers(sql, params, many=False, executor=self._execute)
  File "C:\Users\amand\python-cordarme\drf-api\venv\lib\site-packages\django\db\backends\utils.py", line 76, in _execute_with_wrappers
    return executor(sql, params, many, context)
  File "C:\Users\amand\python-cordarme\drf-api\venv\lib\site-packages\django\db\backends\utils.py", line 80, in _execute
    with self.db.wrap_database_errors:
  File "C:\Users\amand\python-cordarme\drf-api\venv\lib\site-packages\django\db\utils.py", line 90, in __exit__
    raise dj_exc_value.with_traceback(traceback) from exc_value
  File "C:\Users\amand\python-cordarme\drf-api\venv\lib\site-packages\django\db\backends\utils.py", line 85, in _execute
    return self.cursor.execute(sql, params)
  File "C:\Users\amand\python-cordarme\drf-api\venv\lib\site-packages\django\db\backends\sqlite3\base.py", line 416, in execute
    return Database.Cursor.execute(self, query, params)
django.db.utils.IntegrityError: UNIQUE constraint failed: agenda_estabelecimento.nome_estabelecimento
2022-05-04 21:52:52,686 django.request WARNING  Bad Request: /api/servicos/
2022-05-04 21:53:49,328 django.utils.autoreload INFO     C:\Users\amand\python-cordarme\drf-api\agenda\serializers.py changed, reloading.
2022-05-04 21:53:50,233 django.utils.autoreload INFO     Watching for file changes with StatReloader
2022-05-04 21:53:57,398 django.request ERROR    Internal Server Error: /api/estabelecimentos/
Traceback (most recent call last):
  File "C:\Users\amand\python-cordarme\drf-api\venv\lib\site-packages\django\core\handlers\exception.py", line 47, in inner
    response = get_response(request)
  File "C:\Users\amand\python-cordarme\drf-api\venv\lib\site-packages\django\core\handlers\base.py", line 181, in _get_response
    response = wrapped_callback(request, *callback_args, **callback_kwargs)
  File "C:\Users\amand\python-cordarme\drf-api\venv\lib\site-packages\django\views\decorators\csrf.py", line 54, in wrapped_view
    return view_func(*args, **kwargs)
  File "C:\Users\amand\python-cordarme\drf-api\venv\lib\site-packages\django\views\generic\base.py", line 69, in view
    return self.dispatch(request, *args, **kwargs)
  File "C:\Users\amand\python-cordarme\drf-api\venv\lib\site-packages\rest_framework\views.py", line 509, in dispatch
    response = self.handle_exception(exc)
  File "C:\Users\amand\python-cordarme\drf-api\venv\lib\site-packages\rest_framework\views.py", line 469, in handle_exception
    self.raise_uncaught_exception(exc)
  File "C:\Users\amand\python-cordarme\drf-api\venv\lib\site-packages\rest_framework\views.py", line 480, in raise_uncaught_exception
    raise exc
  File "C:\Users\amand\python-cordarme\drf-api\venv\lib\site-packages\rest_framework\views.py", line 506, in dispatch
    response = handler(request, *args, **kwargs)
  File "C:\Users\amand\python-cordarme\drf-api\venv\lib\site-packages\rest_framework\generics.py", line 242, in post
    return self.create(request, *args, **kwargs)
  File "C:\Users\amand\python-cordarme\drf-api\venv\lib\site-packages\rest_framework\mixins.py", line 18, in create
    serializer.is_valid(raise_exception=True)
  File "C:\Users\amand\python-cordarme\drf-api\venv\lib\site-packages\rest_framework\serializers.py", line 227, in is_valid
    self._validated_data = self.run_validation(self.initial_data)
  File "C:\Users\amand\python-cordarme\drf-api\venv\lib\site-packages\rest_framework\serializers.py", line 429, in run_validation
    value = self.validate(value)
  File "C:\Users\amand\python-cordarme\drf-api\agenda\serializers.py", line 195, in validate
    if Estabelecimento.objects.filter(servico=estabelecimento_request).exists():
  File "C:\Users\amand\python-cordarme\drf-api\venv\lib\site-packages\django\db\models\manager.py", line 85, in manager_method
    return getattr(self.get_queryset(), name)(*args, **kwargs)
  File "C:\Users\amand\python-cordarme\drf-api\venv\lib\site-packages\django\db\models\query.py", line 974, in filter
    return self._filter_or_exclude(False, args, kwargs)
  File "C:\Users\amand\python-cordarme\drf-api\venv\lib\site-packages\django\db\models\query.py", line 992, in _filter_or_exclude
    clone._filter_or_exclude_inplace(negate, args, kwargs)
  File "C:\Users\amand\python-cordarme\drf-api\venv\lib\site-packages\django\db\models\query.py", line 999, in _filter_or_exclude_inplace
    self._query.add_q(Q(*args, **kwargs))
  File "C:\Users\amand\python-cordarme\drf-api\venv\lib\site-packages\django\db\models\sql\query.py", line 1375, in add_q
    clause, _ = self._add_q(q_object, self.used_aliases)
  File "C:\Users\amand\python-cordarme\drf-api\venv\lib\site-packages\django\db\models\sql\query.py", line 1396, in _add_q
    child_clause, needed_inner = self.build_filter(
  File "C:\Users\amand\python-cordarme\drf-api\venv\lib\site-packages\django\db\models\sql\query.py", line 1271, in build_filter
    lookups, parts, reffed_expression = self.solve_lookup_type(arg)
  File "C:\Users\amand\python-cordarme\drf-api\venv\lib\site-packages\django\db\models\sql\query.py", line 1099, in solve_lookup_type
    _, field, _, lookup_parts = self.names_to_path(lookup_splitted, self.get_meta())
  File "C:\Users\amand\python-cordarme\drf-api\venv\lib\site-packages\django\db\models\sql\query.py", line 1522, in names_to_path
    raise FieldError("Cannot resolve keyword '%s' into field. "
django.core.exceptions.FieldError: Cannot resolve keyword 'servico' into field. Choices are: agendamento, funcionarios, id, nome_estabelecimento
2022-05-04 21:54:04,342 django.request ERROR    Internal Server Error: /api/estabelecimentos/
Traceback (most recent call last):
  File "C:\Users\amand\python-cordarme\drf-api\venv\lib\site-packages\django\core\handlers\exception.py", line 47, in inner
    response = get_response(request)
  File "C:\Users\amand\python-cordarme\drf-api\venv\lib\site-packages\django\core\handlers\base.py", line 181, in _get_response
    response = wrapped_callback(request, *callback_args, **callback_kwargs)
  File "C:\Users\amand\python-cordarme\drf-api\venv\lib\site-packages\django\views\decorators\csrf.py", line 54, in wrapped_view
    return view_func(*args, **kwargs)
  File "C:\Users\amand\python-cordarme\drf-api\venv\lib\site-packages\django\views\generic\base.py", line 69, in view
    return self.dispatch(request, *args, **kwargs)
  File "C:\Users\amand\python-cordarme\drf-api\venv\lib\site-packages\rest_framework\views.py", line 509, in dispatch
    response = self.handle_exception(exc)
  File "C:\Users\amand\python-cordarme\drf-api\venv\lib\site-packages\rest_framework\views.py", line 469, in handle_exception
    self.raise_uncaught_exception(exc)
  File "C:\Users\amand\python-cordarme\drf-api\venv\lib\site-packages\rest_framework\views.py", line 480, in raise_uncaught_exception
    raise exc
  File "C:\Users\amand\python-cordarme\drf-api\venv\lib\site-packages\rest_framework\views.py", line 506, in dispatch
    response = handler(request, *args, **kwargs)
  File "C:\Users\amand\python-cordarme\drf-api\venv\lib\site-packages\rest_framework\generics.py", line 242, in post
    return self.create(request, *args, **kwargs)
  File "C:\Users\amand\python-cordarme\drf-api\venv\lib\site-packages\rest_framework\mixins.py", line 18, in create
    serializer.is_valid(raise_exception=True)
  File "C:\Users\amand\python-cordarme\drf-api\venv\lib\site-packages\rest_framework\serializers.py", line 227, in is_valid
    self._validated_data = self.run_validation(self.initial_data)
  File "C:\Users\amand\python-cordarme\drf-api\venv\lib\site-packages\rest_framework\serializers.py", line 429, in run_validation
    value = self.validate(value)
  File "C:\Users\amand\python-cordarme\drf-api\agenda\serializers.py", line 195, in validate
    if Estabelecimento.objects.filter(servico=estabelecimento_request).exists():
  File "C:\Users\amand\python-cordarme\drf-api\venv\lib\site-packages\django\db\models\manager.py", line 85, in manager_method
    return getattr(self.get_queryset(), name)(*args, **kwargs)
  File "C:\Users\amand\python-cordarme\drf-api\venv\lib\site-packages\django\db\models\query.py", line 974, in filter
    return self._filter_or_exclude(False, args, kwargs)
  File "C:\Users\amand\python-cordarme\drf-api\venv\lib\site-packages\django\db\models\query.py", line 992, in _filter_or_exclude
    clone._filter_or_exclude_inplace(negate, args, kwargs)
  File "C:\Users\amand\python-cordarme\drf-api\venv\lib\site-packages\django\db\models\query.py", line 999, in _filter_or_exclude_inplace
    self._query.add_q(Q(*args, **kwargs))
  File "C:\Users\amand\python-cordarme\drf-api\venv\lib\site-packages\django\db\models\sql\query.py", line 1375, in add_q
    clause, _ = self._add_q(q_object, self.used_aliases)
  File "C:\Users\amand\python-cordarme\drf-api\venv\lib\site-packages\django\db\models\sql\query.py", line 1396, in _add_q
    child_clause, needed_inner = self.build_filter(
  File "C:\Users\amand\python-cordarme\drf-api\venv\lib\site-packages\django\db\models\sql\query.py", line 1271, in build_filter
    lookups, parts, reffed_expression = self.solve_lookup_type(arg)
  File "C:\Users\amand\python-cordarme\drf-api\venv\lib\site-packages\django\db\models\sql\query.py", line 1099, in solve_lookup_type
    _, field, _, lookup_parts = self.names_to_path(lookup_splitted, self.get_meta())
  File "C:\Users\amand\python-cordarme\drf-api\venv\lib\site-packages\django\db\models\sql\query.py", line 1522, in names_to_path
    raise FieldError("Cannot resolve keyword '%s' into field. "
django.core.exceptions.FieldError: Cannot resolve keyword 'servico' into field. Choices are: agendamento, funcionarios, id, nome_estabelecimento
2022-05-04 21:54:25,696 django.utils.autoreload INFO     C:\Users\amand\python-cordarme\drf-api\agenda\serializers.py changed, reloading.
2022-05-04 21:54:26,752 django.utils.autoreload INFO     Watching for file changes with StatReloader
2022-05-04 21:54:27,905 django.request ERROR    Internal Server Error: /api/estabelecimentos/
Traceback (most recent call last):
  File "C:\Users\amand\python-cordarme\drf-api\venv\lib\site-packages\django\core\handlers\exception.py", line 47, in inner
    response = get_response(request)
  File "C:\Users\amand\python-cordarme\drf-api\venv\lib\site-packages\django\core\handlers\base.py", line 181, in _get_response
    response = wrapped_callback(request, *callback_args, **callback_kwargs)
  File "C:\Users\amand\python-cordarme\drf-api\venv\lib\site-packages\django\views\decorators\csrf.py", line 54, in wrapped_view
    return view_func(*args, **kwargs)
  File "C:\Users\amand\python-cordarme\drf-api\venv\lib\site-packages\django\views\generic\base.py", line 69, in view
    return self.dispatch(request, *args, **kwargs)
  File "C:\Users\amand\python-cordarme\drf-api\venv\lib\site-packages\rest_framework\views.py", line 509, in dispatch
    response = self.handle_exception(exc)
  File "C:\Users\amand\python-cordarme\drf-api\venv\lib\site-packages\rest_framework\views.py", line 469, in handle_exception
    self.raise_uncaught_exception(exc)
  File "C:\Users\amand\python-cordarme\drf-api\venv\lib\site-packages\rest_framework\views.py", line 480, in raise_uncaught_exception
    raise exc
  File "C:\Users\amand\python-cordarme\drf-api\venv\lib\site-packages\rest_framework\views.py", line 506, in dispatch
    response = handler(request, *args, **kwargs)
  File "C:\Users\amand\python-cordarme\drf-api\venv\lib\site-packages\rest_framework\generics.py", line 242, in post
    return self.create(request, *args, **kwargs)
  File "C:\Users\amand\python-cordarme\drf-api\venv\lib\site-packages\rest_framework\mixins.py", line 18, in create
    serializer.is_valid(raise_exception=True)
  File "C:\Users\amand\python-cordarme\drf-api\venv\lib\site-packages\rest_framework\serializers.py", line 227, in is_valid
    self._validated_data = self.run_validation(self.initial_data)
  File "C:\Users\amand\python-cordarme\drf-api\venv\lib\site-packages\rest_framework\serializers.py", line 429, in run_validation
    value = self.validate(value)
  File "C:\Users\amand\python-cordarme\drf-api\agenda\serializers.py", line 195, in validate
    if Estabelecimento.objects.filter(
  File "C:\Users\amand\python-cordarme\drf-api\venv\lib\site-packages\django\db\models\manager.py", line 85, in manager_method
    return getattr(self.get_queryset(), name)(*args, **kwargs)
  File "C:\Users\amand\python-cordarme\drf-api\venv\lib\site-packages\django\db\models\query.py", line 974, in filter
    return self._filter_or_exclude(False, args, kwargs)
  File "C:\Users\amand\python-cordarme\drf-api\venv\lib\site-packages\django\db\models\query.py", line 992, in _filter_or_exclude
    clone._filter_or_exclude_inplace(negate, args, kwargs)
  File "C:\Users\amand\python-cordarme\drf-api\venv\lib\site-packages\django\db\models\query.py", line 999, in _filter_or_exclude_inplace
    self._query.add_q(Q(*args, **kwargs))
  File "C:\Users\amand\python-cordarme\drf-api\venv\lib\site-packages\django\db\models\sql\query.py", line 1375, in add_q
    clause, _ = self._add_q(q_object, self.used_aliases)
  File "C:\Users\amand\python-cordarme\drf-api\venv\lib\site-packages\django\db\models\sql\query.py", line 1396, in _add_q
    child_clause, needed_inner = self.build_filter(
  File "C:\Users\amand\python-cordarme\drf-api\venv\lib\site-packages\django\db\models\sql\query.py", line 1271, in build_filter
    lookups, parts, reffed_expression = self.solve_lookup_type(arg)
  File "C:\Users\amand\python-cordarme\drf-api\venv\lib\site-packages\django\db\models\sql\query.py", line 1099, in solve_lookup_type
    _, field, _, lookup_parts = self.names_to_path(lookup_splitted, self.get_meta())
  File "C:\Users\amand\python-cordarme\drf-api\venv\lib\site-packages\django\db\models\sql\query.py", line 1522, in names_to_path
    raise FieldError("Cannot resolve keyword '%s' into field. "
django.core.exceptions.FieldError: Cannot resolve keyword 'estabelecimento' into field. Choices are: agendamento, funcionarios, id, nome_estabelecimento
2022-05-04 21:54:29,499 django.request ERROR    Internal Server Error: /api/estabelecimentos/
Traceback (most recent call last):
  File "C:\Users\amand\python-cordarme\drf-api\venv\lib\site-packages\django\core\handlers\exception.py", line 47, in inner
    response = get_response(request)
  File "C:\Users\amand\python-cordarme\drf-api\venv\lib\site-packages\django\core\handlers\base.py", line 181, in _get_response
    response = wrapped_callback(request, *callback_args, **callback_kwargs)
  File "C:\Users\amand\python-cordarme\drf-api\venv\lib\site-packages\django\views\decorators\csrf.py", line 54, in wrapped_view
    return view_func(*args, **kwargs)
  File "C:\Users\amand\python-cordarme\drf-api\venv\lib\site-packages\django\views\generic\base.py", line 69, in view
    return self.dispatch(request, *args, **kwargs)
  File "C:\Users\amand\python-cordarme\drf-api\venv\lib\site-packages\rest_framework\views.py", line 509, in dispatch
    response = self.handle_exception(exc)
  File "C:\Users\amand\python-cordarme\drf-api\venv\lib\site-packages\rest_framework\views.py", line 469, in handle_exception
    self.raise_uncaught_exception(exc)
  File "C:\Users\amand\python-cordarme\drf-api\venv\lib\site-packages\rest_framework\views.py", line 480, in raise_uncaught_exception
    raise exc
  File "C:\Users\amand\python-cordarme\drf-api\venv\lib\site-packages\rest_framework\views.py", line 506, in dispatch
    response = handler(request, *args, **kwargs)
  File "C:\Users\amand\python-cordarme\drf-api\venv\lib\site-packages\rest_framework\generics.py", line 242, in post
    return self.create(request, *args, **kwargs)
  File "C:\Users\amand\python-cordarme\drf-api\venv\lib\site-packages\rest_framework\mixins.py", line 18, in create
    serializer.is_valid(raise_exception=True)
  File "C:\Users\amand\python-cordarme\drf-api\venv\lib\site-packages\rest_framework\serializers.py", line 227, in is_valid
    self._validated_data = self.run_validation(self.initial_data)
  File "C:\Users\amand\python-cordarme\drf-api\venv\lib\site-packages\rest_framework\serializers.py", line 429, in run_validation
    value = self.validate(value)
  File "C:\Users\amand\python-cordarme\drf-api\agenda\serializers.py", line 195, in validate
    if Estabelecimento.objects.filter(
  File "C:\Users\amand\python-cordarme\drf-api\venv\lib\site-packages\django\db\models\manager.py", line 85, in manager_method
    return getattr(self.get_queryset(), name)(*args, **kwargs)
  File "C:\Users\amand\python-cordarme\drf-api\venv\lib\site-packages\django\db\models\query.py", line 974, in filter
    return self._filter_or_exclude(False, args, kwargs)
  File "C:\Users\amand\python-cordarme\drf-api\venv\lib\site-packages\django\db\models\query.py", line 992, in _filter_or_exclude
    clone._filter_or_exclude_inplace(negate, args, kwargs)
  File "C:\Users\amand\python-cordarme\drf-api\venv\lib\site-packages\django\db\models\query.py", line 999, in _filter_or_exclude_inplace
    self._query.add_q(Q(*args, **kwargs))
  File "C:\Users\amand\python-cordarme\drf-api\venv\lib\site-packages\django\db\models\sql\query.py", line 1375, in add_q
    clause, _ = self._add_q(q_object, self.used_aliases)
  File "C:\Users\amand\python-cordarme\drf-api\venv\lib\site-packages\django\db\models\sql\query.py", line 1396, in _add_q
    child_clause, needed_inner = self.build_filter(
  File "C:\Users\amand\python-cordarme\drf-api\venv\lib\site-packages\django\db\models\sql\query.py", line 1271, in build_filter
    lookups, parts, reffed_expression = self.solve_lookup_type(arg)
  File "C:\Users\amand\python-cordarme\drf-api\venv\lib\site-packages\django\db\models\sql\query.py", line 1099, in solve_lookup_type
    _, field, _, lookup_parts = self.names_to_path(lookup_splitted, self.get_meta())
  File "C:\Users\amand\python-cordarme\drf-api\venv\lib\site-packages\django\db\models\sql\query.py", line 1522, in names_to_path
    raise FieldError("Cannot resolve keyword '%s' into field. "
django.core.exceptions.FieldError: Cannot resolve keyword 'estabelecimento' into field. Choices are: agendamento, funcionarios, id, nome_estabelecimento
2022-05-04 21:54:35,119 django.utils.autoreload INFO     C:\Users\amand\python-cordarme\drf-api\agenda\serializers.py changed, reloading.
2022-05-04 21:54:35,937 django.utils.autoreload INFO     Watching for file changes with StatReloader
2022-05-04 21:54:58,029 django.utils.autoreload INFO     C:\Users\amand\python-cordarme\drf-api\agenda\serializers.py changed, reloading.
2022-05-04 21:54:58,865 django.utils.autoreload INFO     Watching for file changes with StatReloader
2022-05-04 21:55:12,628 django.utils.autoreload INFO     C:\Users\amand\python-cordarme\drf-api\agenda\serializers.py changed, reloading.
2022-05-04 21:55:13,553 django.utils.autoreload INFO     Watching for file changes with StatReloader
2022-05-04 21:55:15,258 django.request WARNING  Bad Request: /api/estabelecimentos/
2022-05-04 21:56:58,969 django.request ERROR    Internal Server Error: /api/funcionarios/
Traceback (most recent call last):
  File "C:\Users\amand\python-cordarme\drf-api\venv\lib\site-packages\django\db\backends\utils.py", line 85, in _execute
    return self.cursor.execute(sql, params)
  File "C:\Users\amand\python-cordarme\drf-api\venv\lib\site-packages\django\db\backends\sqlite3\base.py", line 416, in execute
    return Database.Cursor.execute(self, query, params)
sqlite3.IntegrityError: NOT NULL constraint failed: agenda_funcionarios.prestador_id

The above exception was the direct cause of the following exception:

Traceback (most recent call last):
  File "C:\Users\amand\python-cordarme\drf-api\venv\lib\site-packages\django\core\handlers\exception.py", line 47, in inner
    response = get_response(request)
  File "C:\Users\amand\python-cordarme\drf-api\venv\lib\site-packages\django\core\handlers\base.py", line 181, in _get_response
    response = wrapped_callback(request, *callback_args, **callback_kwargs)
  File "C:\Users\amand\python-cordarme\drf-api\venv\lib\site-packages\django\views\decorators\csrf.py", line 54, in wrapped_view
    return view_func(*args, **kwargs)
  File "C:\Users\amand\python-cordarme\drf-api\venv\lib\site-packages\django\views\generic\base.py", line 69, in view
    return self.dispatch(request, *args, **kwargs)
  File "C:\Users\amand\python-cordarme\drf-api\venv\lib\site-packages\rest_framework\views.py", line 509, in dispatch
    response = self.handle_exception(exc)
  File "C:\Users\amand\python-cordarme\drf-api\venv\lib\site-packages\rest_framework\views.py", line 469, in handle_exception
    self.raise_uncaught_exception(exc)
  File "C:\Users\amand\python-cordarme\drf-api\venv\lib\site-packages\rest_framework\views.py", line 480, in raise_uncaught_exception
    raise exc
  File "C:\Users\amand\python-cordarme\drf-api\venv\lib\site-packages\rest_framework\views.py", line 506, in dispatch
    response = handler(request, *args, **kwargs)
  File "C:\Users\amand\python-cordarme\drf-api\agenda\views.py", line 158, in post
    Funcionarios.objects.create(
  File "C:\Users\amand\python-cordarme\drf-api\venv\lib\site-packages\django\db\models\manager.py", line 85, in manager_method
    return getattr(self.get_queryset(), name)(*args, **kwargs)
  File "C:\Users\amand\python-cordarme\drf-api\venv\lib\site-packages\django\db\models\query.py", line 457, in create
    obj.save(force_insert=True, using=self.db)
  File "C:\Users\amand\python-cordarme\drf-api\venv\lib\site-packages\django\db\models\base.py", line 743, in save
    self.save_base(using=using, force_insert=force_insert,
  File "C:\Users\amand\python-cordarme\drf-api\venv\lib\site-packages\django\db\models\base.py", line 780, in save_base
    updated = self._save_table(
  File "C:\Users\amand\python-cordarme\drf-api\venv\lib\site-packages\django\db\models\base.py", line 885, in _save_table
    results = self._do_insert(cls._base_manager, using, fields, returning_fields, raw)
  File "C:\Users\amand\python-cordarme\drf-api\venv\lib\site-packages\django\db\models\base.py", line 923, in _do_insert
    return manager._insert(
  File "C:\Users\amand\python-cordarme\drf-api\venv\lib\site-packages\django\db\models\manager.py", line 85, in manager_method
    return getattr(self.get_queryset(), name)(*args, **kwargs)
  File "C:\Users\amand\python-cordarme\drf-api\venv\lib\site-packages\django\db\models\query.py", line 1301, in _insert
    return query.get_compiler(using=using).execute_sql(returning_fields)
  File "C:\Users\amand\python-cordarme\drf-api\venv\lib\site-packages\django\db\models\sql\compiler.py", line 1441, in execute_sql
    cursor.execute(sql, params)
  File "C:\Users\amand\python-cordarme\drf-api\venv\lib\site-packages\django\db\backends\utils.py", line 99, in execute
    return super().execute(sql, params)
  File "C:\Users\amand\python-cordarme\drf-api\venv\lib\site-packages\django\db\backends\utils.py", line 67, in execute
    return self._execute_with_wrappers(sql, params, many=False, executor=self._execute)
  File "C:\Users\amand\python-cordarme\drf-api\venv\lib\site-packages\django\db\backends\utils.py", line 76, in _execute_with_wrappers
    return executor(sql, params, many, context)
  File "C:\Users\amand\python-cordarme\drf-api\venv\lib\site-packages\django\db\backends\utils.py", line 80, in _execute
    with self.db.wrap_database_errors:
  File "C:\Users\amand\python-cordarme\drf-api\venv\lib\site-packages\django\db\utils.py", line 90, in __exit__
    raise dj_exc_value.with_traceback(traceback) from exc_value
  File "C:\Users\amand\python-cordarme\drf-api\venv\lib\site-packages\django\db\backends\utils.py", line 85, in _execute
    return self.cursor.execute(sql, params)
  File "C:\Users\amand\python-cordarme\drf-api\venv\lib\site-packages\django\db\backends\sqlite3\base.py", line 416, in execute
    return Database.Cursor.execute(self, query, params)
django.db.utils.IntegrityError: NOT NULL constraint failed: agenda_funcionarios.prestador_id
2022-05-04 21:58:21,482 django.request ERROR    Internal Server Error: /api/funcionarios/
Traceback (most recent call last):
  File "C:\Users\amand\python-cordarme\drf-api\venv\lib\site-packages\django\db\backends\utils.py", line 85, in _execute
    return self.cursor.execute(sql, params)
  File "C:\Users\amand\python-cordarme\drf-api\venv\lib\site-packages\django\db\backends\sqlite3\base.py", line 416, in execute
    return Database.Cursor.execute(self, query, params)
sqlite3.IntegrityError: UNIQUE constraint failed: agenda_funcionarios.prestador_id, agenda_funcionarios.estabelecimento_id

The above exception was the direct cause of the following exception:

Traceback (most recent call last):
  File "C:\Users\amand\python-cordarme\drf-api\venv\lib\site-packages\django\core\handlers\exception.py", line 47, in inner
    response = get_response(request)
  File "C:\Users\amand\python-cordarme\drf-api\venv\lib\site-packages\django\core\handlers\base.py", line 181, in _get_response
    response = wrapped_callback(request, *callback_args, **callback_kwargs)
  File "C:\Users\amand\python-cordarme\drf-api\venv\lib\site-packages\django\views\decorators\csrf.py", line 54, in wrapped_view
    return view_func(*args, **kwargs)
  File "C:\Users\amand\python-cordarme\drf-api\venv\lib\site-packages\django\views\generic\base.py", line 69, in view
    return self.dispatch(request, *args, **kwargs)
  File "C:\Users\amand\python-cordarme\drf-api\venv\lib\site-packages\rest_framework\views.py", line 509, in dispatch
    response = self.handle_exception(exc)
  File "C:\Users\amand\python-cordarme\drf-api\venv\lib\site-packages\rest_framework\views.py", line 469, in handle_exception
    self.raise_uncaught_exception(exc)
  File "C:\Users\amand\python-cordarme\drf-api\venv\lib\site-packages\rest_framework\views.py", line 480, in raise_uncaught_exception
    raise exc
  File "C:\Users\amand\python-cordarme\drf-api\venv\lib\site-packages\rest_framework\views.py", line 506, in dispatch
    response = handler(request, *args, **kwargs)
  File "C:\Users\amand\python-cordarme\drf-api\agenda\views.py", line 158, in post
    Funcionarios.objects.create(
  File "C:\Users\amand\python-cordarme\drf-api\venv\lib\site-packages\django\db\models\manager.py", line 85, in manager_method
    return getattr(self.get_queryset(), name)(*args, **kwargs)
  File "C:\Users\amand\python-cordarme\drf-api\venv\lib\site-packages\django\db\models\query.py", line 457, in create
    obj.save(force_insert=True, using=self.db)
  File "C:\Users\amand\python-cordarme\drf-api\venv\lib\site-packages\django\db\models\base.py", line 743, in save
    self.save_base(using=using, force_insert=force_insert,
  File "C:\Users\amand\python-cordarme\drf-api\venv\lib\site-packages\django\db\models\base.py", line 780, in save_base
    updated = self._save_table(
  File "C:\Users\amand\python-cordarme\drf-api\venv\lib\site-packages\django\db\models\base.py", line 885, in _save_table
    results = self._do_insert(cls._base_manager, using, fields, returning_fields, raw)
  File "C:\Users\amand\python-cordarme\drf-api\venv\lib\site-packages\django\db\models\base.py", line 923, in _do_insert
    return manager._insert(
  File "C:\Users\amand\python-cordarme\drf-api\venv\lib\site-packages\django\db\models\manager.py", line 85, in manager_method
    return getattr(self.get_queryset(), name)(*args, **kwargs)
  File "C:\Users\amand\python-cordarme\drf-api\venv\lib\site-packages\django\db\models\query.py", line 1301, in _insert
    return query.get_compiler(using=using).execute_sql(returning_fields)
  File "C:\Users\amand\python-cordarme\drf-api\venv\lib\site-packages\django\db\models\sql\compiler.py", line 1441, in execute_sql
    cursor.execute(sql, params)
  File "C:\Users\amand\python-cordarme\drf-api\venv\lib\site-packages\django\db\backends\utils.py", line 99, in execute
    return super().execute(sql, params)
  File "C:\Users\amand\python-cordarme\drf-api\venv\lib\site-packages\django\db\backends\utils.py", line 67, in execute
    return self._execute_with_wrappers(sql, params, many=False, executor=self._execute)
  File "C:\Users\amand\python-cordarme\drf-api\venv\lib\site-packages\django\db\backends\utils.py", line 76, in _execute_with_wrappers
    return executor(sql, params, many, context)
  File "C:\Users\amand\python-cordarme\drf-api\venv\lib\site-packages\django\db\backends\utils.py", line 80, in _execute
    with self.db.wrap_database_errors:
  File "C:\Users\amand\python-cordarme\drf-api\venv\lib\site-packages\django\db\utils.py", line 90, in __exit__
    raise dj_exc_value.with_traceback(traceback) from exc_value
  File "C:\Users\amand\python-cordarme\drf-api\venv\lib\site-packages\django\db\backends\utils.py", line 85, in _execute
    return self.cursor.execute(sql, params)
  File "C:\Users\amand\python-cordarme\drf-api\venv\lib\site-packages\django\db\backends\sqlite3\base.py", line 416, in execute
    return Database.Cursor.execute(self, query, params)
django.db.utils.IntegrityError: UNIQUE constraint failed: agenda_funcionarios.prestador_id, agenda_funcionarios.estabelecimento_id
2022-05-04 21:58:46,413 root         INFO     Fazendo requisição para BrasilAPI para a data: 2022-04-12
2022-05-04 21:58:46,435 urllib3.connectionpool DEBUG    Starting new HTTPS connection (1): brasilapi.com.br:443
2022-05-04 21:58:47,128 urllib3.connectionpool DEBUG    https://brasilapi.com.br:443 "GET /api/feriados/v1/2022 HTTP/1.1" 200 None
2022-05-22 22:24:12,663 django.utils.autoreload INFO     Watching for file changes with StatReloader
2022-05-23 16:27:30,881 django.utils.autoreload INFO     Watching for file changes with StatReloader
