2022-04-19 10:25:32,995 django.utils.autoreload INFO     Watching for file changes with StatReloader
2022-04-19 10:26:39,635 django.utils.autoreload INFO     C:\Users\amand\python-cordarme\drf-api\tamarcado\settings\dev.py changed, reloading.
2022-04-19 10:27:51,955 django.utils.autoreload INFO     Watching for file changes with StatReloader
2022-04-19 10:28:26,978 root         INFO     Fazendo requisição para BrasilAPI para a data: 2022-04-12
2022-04-19 10:28:26,986 urllib3.connectionpool DEBUG    Starting new HTTPS connection (1): brasilapi.com.br:443
2022-04-19 10:28:27,102 urllib3.connectionpool DEBUG    https://brasilapi.com.br:443 "GET /api/feriados/v1/2022 HTTP/1.1" 200 None
2022-04-28 11:12:09,261 django.utils.autoreload INFO     Watching for file changes with StatReloader
2022-04-28 11:12:21,208 django.request WARNING  Not Found: /
2022-04-28 11:12:21,388 django.request WARNING  Not Found: /favicon.ico
2022-04-28 12:36:52,719 django.request ERROR    Internal Server Error: /api/funcionarios/
Traceback (most recent call last):
  File "C:\Users\amand\python-cordarme\drf-api\venv\lib\site-packages\django\db\backends\utils.py", line 85, in _execute
    return self.cursor.execute(sql, params)
  File "C:\Users\amand\python-cordarme\drf-api\venv\lib\site-packages\django\db\backends\sqlite3\base.py", line 416, in execute
    return Database.Cursor.execute(self, query, params)
sqlite3.IntegrityError: NOT NULL constraint failed: agenda_funcionarios.prestador_id

The above exception was the direct cause of the following exception:

Traceback (most recent call last):
  File "C:\Users\amand\python-cordarme\drf-api\venv\lib\site-packages\django\core\handlers\exception.py", line 47, in inner
    response = get_response(request)
  File "C:\Users\amand\python-cordarme\drf-api\venv\lib\site-packages\django\core\handlers\base.py", line 181, in _get_response
    response = wrapped_callback(request, *callback_args, **callback_kwargs)
  File "C:\Users\amand\python-cordarme\drf-api\venv\lib\site-packages\django\views\decorators\csrf.py", line 54, in wrapped_view
    return view_func(*args, **kwargs)
  File "C:\Users\amand\python-cordarme\drf-api\venv\lib\site-packages\django\views\generic\base.py", line 69, in view
    return self.dispatch(request, *args, **kwargs)
  File "C:\Users\amand\python-cordarme\drf-api\venv\lib\site-packages\rest_framework\views.py", line 509, in dispatch
    response = self.handle_exception(exc)
  File "C:\Users\amand\python-cordarme\drf-api\venv\lib\site-packages\rest_framework\views.py", line 469, in handle_exception
    self.raise_uncaught_exception(exc)
  File "C:\Users\amand\python-cordarme\drf-api\venv\lib\site-packages\rest_framework\views.py", line 480, in raise_uncaught_exception
    raise exc
  File "C:\Users\amand\python-cordarme\drf-api\venv\lib\site-packages\rest_framework\views.py", line 506, in dispatch
    response = handler(request, *args, **kwargs)
  File "C:\Users\amand\python-cordarme\drf-api\agenda\views.py", line 158, in post
    Funcionarios.objects.create(
  File "C:\Users\amand\python-cordarme\drf-api\venv\lib\site-packages\django\db\models\manager.py", line 85, in manager_method
    return getattr(self.get_queryset(), name)(*args, **kwargs)
  File "C:\Users\amand\python-cordarme\drf-api\venv\lib\site-packages\django\db\models\query.py", line 457, in create
    obj.save(force_insert=True, using=self.db)
  File "C:\Users\amand\python-cordarme\drf-api\venv\lib\site-packages\django\db\models\base.py", line 743, in save
    self.save_base(using=using, force_insert=force_insert,
  File "C:\Users\amand\python-cordarme\drf-api\venv\lib\site-packages\django\db\models\base.py", line 780, in save_base
    updated = self._save_table(
  File "C:\Users\amand\python-cordarme\drf-api\venv\lib\site-packages\django\db\models\base.py", line 885, in _save_table
    results = self._do_insert(cls._base_manager, using, fields, returning_fields, raw)
  File "C:\Users\amand\python-cordarme\drf-api\venv\lib\site-packages\django\db\models\base.py", line 923, in _do_insert
    return manager._insert(
  File "C:\Users\amand\python-cordarme\drf-api\venv\lib\site-packages\django\db\models\manager.py", line 85, in manager_method
    return getattr(self.get_queryset(), name)(*args, **kwargs)
  File "C:\Users\amand\python-cordarme\drf-api\venv\lib\site-packages\django\db\models\query.py", line 1301, in _insert
    return query.get_compiler(using=using).execute_sql(returning_fields)
  File "C:\Users\amand\python-cordarme\drf-api\venv\lib\site-packages\django\db\models\sql\compiler.py", line 1441, in execute_sql
    cursor.execute(sql, params)
  File "C:\Users\amand\python-cordarme\drf-api\venv\lib\site-packages\django\db\backends\utils.py", line 99, in execute
    return super().execute(sql, params)
  File "C:\Users\amand\python-cordarme\drf-api\venv\lib\site-packages\django\db\backends\utils.py", line 67, in execute
    return self._execute_with_wrappers(sql, params, many=False, executor=self._execute)
  File "C:\Users\amand\python-cordarme\drf-api\venv\lib\site-packages\django\db\backends\utils.py", line 76, in _execute_with_wrappers
    return executor(sql, params, many, context)
  File "C:\Users\amand\python-cordarme\drf-api\venv\lib\site-packages\django\db\backends\utils.py", line 80, in _execute
    with self.db.wrap_database_errors:
  File "C:\Users\amand\python-cordarme\drf-api\venv\lib\site-packages\django\db\utils.py", line 90, in __exit__
    raise dj_exc_value.with_traceback(traceback) from exc_value
  File "C:\Users\amand\python-cordarme\drf-api\venv\lib\site-packages\django\db\backends\utils.py", line 85, in _execute
    return self.cursor.execute(sql, params)
  File "C:\Users\amand\python-cordarme\drf-api\venv\lib\site-packages\django\db\backends\sqlite3\base.py", line 416, in execute
    return Database.Cursor.execute(self, query, params)
django.db.utils.IntegrityError: NOT NULL constraint failed: agenda_funcionarios.prestador_id
2022-04-28 12:37:25,381 django.utils.autoreload INFO     Watching for file changes with StatReloader
2022-05-04 21:51:23,077 django.utils.autoreload INFO     Watching for file changes with StatReloader
2022-05-04 21:52:15,314 django.request ERROR    Internal Server Error: /api/estabelecimentos/
Traceback (most recent call last):
  File "C:\Users\amand\python-cordarme\drf-api\venv\lib\site-packages\django\db\backends\utils.py", line 85, in _execute
    return self.cursor.execute(sql, params)
  File "C:\Users\amand\python-cordarme\drf-api\venv\lib\site-packages\django\db\backends\sqlite3\base.py", line 416, in execute
    return Database.Cursor.execute(self, query, params)
sqlite3.IntegrityError: UNIQUE constraint failed: agenda_estabelecimento.nome_estabelecimento

The above exception was the direct cause of the following exception:

Traceback (most recent call last):
  File "C:\Users\amand\python-cordarme\drf-api\venv\lib\site-packages\django\core\handlers\exception.py", line 47, in inner
    response = get_response(request)
  File "C:\Users\amand\python-cordarme\drf-api\venv\lib\site-packages\django\core\handlers\base.py", line 181, in _get_response
    response = wrapped_callback(request, *callback_args, **callback_kwargs)
  File "C:\Users\amand\python-cordarme\drf-api\venv\lib\site-packages\django\views\decorators\csrf.py", line 54, in wrapped_view
    return view_func(*args, **kwargs)
  File "C:\Users\amand\python-cordarme\drf-api\venv\lib\site-packages\django\views\generic\base.py", line 69, in view
    return self.dispatch(request, *args, **kwargs)
  File "C:\Users\amand\python-cordarme\drf-api\venv\lib\site-packages\rest_framework\views.py", line 509, in dispatch
    response = self.handle_exception(exc)
  File "C:\Users\amand\python-cordarme\drf-api\venv\lib\site-packages\rest_framework\views.py", line 469, in handle_exception
    self.raise_uncaught_exception(exc)
  File "C:\Users\amand\python-cordarme\drf-api\venv\lib\site-packages\rest_framework\views.py", line 480, in raise_uncaught_exception
    raise exc
  File "C:\Users\amand\python-cordarme\drf-api\venv\lib\site-packages\rest_framework\views.py", line 506, in dispatch
    response = handler(request, *args, **kwargs)
  File "C:\Users\amand\python-cordarme\drf-api\venv\lib\site-packages\rest_framework\generics.py", line 242, in post
    return self.create(request, *args, **kwargs)
  File "C:\Users\amand\python-cordarme\drf-api\venv\lib\site-packages\rest_framework\mixins.py", line 19, in create
    self.perform_create(serializer)
  File "C:\Users\amand\python-cordarme\drf-api\venv\lib\site-packages\rest_framework\mixins.py", line 24, in perform_create
    serializer.save()
  File "C:\Users\amand\python-cordarme\drf-api\venv\lib\site-packages\rest_framework\serializers.py", line 212, in save
    self.instance = self.create(validated_data)
  File "C:\Users\amand\python-cordarme\drf-api\venv\lib\site-packages\rest_framework\serializers.py", line 962, in create
    instance = ModelClass._default_manager.create(**validated_data)
  File "C:\Users\amand\python-cordarme\drf-api\venv\lib\site-packages\django\db\models\manager.py", line 85, in manager_method
    return getattr(self.get_queryset(), name)(*args, **kwargs)
  File "C:\Users\amand\python-cordarme\drf-api\venv\lib\site-packages\django\db\models\query.py", line 457, in create
    obj.save(force_insert=True, using=self.db)
  File "C:\Users\amand\python-cordarme\drf-api\venv\lib\site-packages\django\db\models\base.py", line 743, in save
    self.save_base(using=using, force_insert=force_insert,
  File "C:\Users\amand\python-cordarme\drf-api\venv\lib\site-packages\django\db\models\base.py", line 780, in save_base
    updated = self._save_table(
  File "C:\Users\amand\python-cordarme\drf-api\venv\lib\site-packages\django\db\models\base.py", line 885, in _save_table
    results = self._do_insert(cls._base_manager, using, fields, returning_fields, raw)
  File "C:\Users\amand\python-cordarme\drf-api\venv\lib\site-packages\django\db\models\base.py", line 923, in _do_insert
    return manager._insert(
  File "C:\Users\amand\python-cordarme\drf-api\venv\lib\site-packages\django\db\models\manager.py", line 85, in manager_method
    return getattr(self.get_queryset(), name)(*args, **kwargs)
  File "C:\Users\amand\python-cordarme\drf-api\venv\lib\site-packages\django\db\models\query.py", line 1301, in _insert
    return query.get_compiler(using=using).execute_sql(returning_fields)
  File "C:\Users\amand\python-cordarme\drf-api\venv\lib\site-packages\django\db\models\sql\compiler.py", line 1441, in execute_sql
    cursor.execute(sql, params)
  File "C:\Users\amand\python-cordarme\drf-api\venv\lib\site-packages\django\db\backends\utils.py", line 99, in execute
    return super().execute(sql, params)
  File "C:\Users\amand\python-cordarme\drf-api\venv\lib\site-packages\django\db\backends\utils.py", line 67, in execute
    return self._execute_with_wrappers(sql, params, many=False, executor=self._execute)
  File "C:\Users\amand\python-cordarme\drf-api\venv\lib\site-packages\django\db\backends\utils.py", line 76, in _execute_with_wrappers
    return executor(sql, params, many, context)
  File "C:\Users\amand\python-cordarme\drf-api\venv\lib\site-packages\django\db\backends\utils.py", line 80, in _execute
    with self.db.wrap_database_errors:
  File "C:\Users\amand\python-cordarme\drf-api\venv\lib\site-packages\django\db\utils.py", line 90, in __exit__
    raise dj_exc_value.with_traceback(traceback) from exc_value
  File "C:\Users\amand\python-cordarme\drf-api\venv\lib\site-packages\django\db\backends\utils.py", line 85, in _execute
    return self.cursor.execute(sql, params)
  File "C:\Users\amand\python-cordarme\drf-api\venv\lib\site-packages\django\db\backends\sqlite3\base.py", line 416, in execute
    return Database.Cursor.execute(self, query, params)
django.db.utils.IntegrityError: UNIQUE constraint failed: agenda_estabelecimento.nome_estabelecimento
2022-05-04 21:52:52,686 django.request WARNING  Bad Request: /api/servicos/
2022-05-04 21:53:49,328 django.utils.autoreload INFO     C:\Users\amand\python-cordarme\drf-api\agenda\serializers.py changed, reloading.
2022-05-04 21:53:50,233 django.utils.autoreload INFO     Watching for file changes with StatReloader
2022-05-04 21:53:57,398 django.request ERROR    Internal Server Error: /api/estabelecimentos/
Traceback (most recent call last):
  File "C:\Users\amand\python-cordarme\drf-api\venv\lib\site-packages\django\core\handlers\exception.py", line 47, in inner
    response = get_response(request)
  File "C:\Users\amand\python-cordarme\drf-api\venv\lib\site-packages\django\core\handlers\base.py", line 181, in _get_response
    response = wrapped_callback(request, *callback_args, **callback_kwargs)
  File "C:\Users\amand\python-cordarme\drf-api\venv\lib\site-packages\django\views\decorators\csrf.py", line 54, in wrapped_view
    return view_func(*args, **kwargs)
  File "C:\Users\amand\python-cordarme\drf-api\venv\lib\site-packages\django\views\generic\base.py", line 69, in view
    return self.dispatch(request, *args, **kwargs)
  File "C:\Users\amand\python-cordarme\drf-api\venv\lib\site-packages\rest_framework\views.py", line 509, in dispatch
    response = self.handle_exception(exc)
  File "C:\Users\amand\python-cordarme\drf-api\venv\lib\site-packages\rest_framework\views.py", line 469, in handle_exception
    self.raise_uncaught_exception(exc)
  File "C:\Users\amand\python-cordarme\drf-api\venv\lib\site-packages\rest_framework\views.py", line 480, in raise_uncaught_exception
    raise exc
  File "C:\Users\amand\python-cordarme\drf-api\venv\lib\site-packages\rest_framework\views.py", line 506, in dispatch
    response = handler(request, *args, **kwargs)
  File "C:\Users\amand\python-cordarme\drf-api\venv\lib\site-packages\rest_framework\generics.py", line 242, in post
    return self.create(request, *args, **kwargs)
  File "C:\Users\amand\python-cordarme\drf-api\venv\lib\site-packages\rest_framework\mixins.py", line 18, in create
    serializer.is_valid(raise_exception=True)
  File "C:\Users\amand\python-cordarme\drf-api\venv\lib\site-packages\rest_framework\serializers.py", line 227, in is_valid
    self._validated_data = self.run_validation(self.initial_data)
  File "C:\Users\amand\python-cordarme\drf-api\venv\lib\site-packages\rest_framework\serializers.py", line 429, in run_validation
    value = self.validate(value)
  File "C:\Users\amand\python-cordarme\drf-api\agenda\serializers.py", line 195, in validate
    if Estabelecimento.objects.filter(servico=estabelecimento_request).exists():
  File "C:\Users\amand\python-cordarme\drf-api\venv\lib\site-packages\django\db\models\manager.py", line 85, in manager_method
    return getattr(self.get_queryset(), name)(*args, **kwargs)
  File "C:\Users\amand\python-cordarme\drf-api\venv\lib\site-packages\django\db\models\query.py", line 974, in filter
    return self._filter_or_exclude(False, args, kwargs)
  File "C:\Users\amand\python-cordarme\drf-api\venv\lib\site-packages\django\db\models\query.py", line 992, in _filter_or_exclude
    clone._filter_or_exclude_inplace(negate, args, kwargs)
  File "C:\Users\amand\python-cordarme\drf-api\venv\lib\site-packages\django\db\models\query.py", line 999, in _filter_or_exclude_inplace
    self._query.add_q(Q(*args, **kwargs))
  File "C:\Users\amand\python-cordarme\drf-api\venv\lib\site-packages\django\db\models\sql\query.py", line 1375, in add_q
    clause, _ = self._add_q(q_object, self.used_aliases)
  File "C:\Users\amand\python-cordarme\drf-api\venv\lib\site-packages\django\db\models\sql\query.py", line 1396, in _add_q
    child_clause, needed_inner = self.build_filter(
  File "C:\Users\amand\python-cordarme\drf-api\venv\lib\site-packages\django\db\models\sql\query.py", line 1271, in build_filter
    lookups, parts, reffed_expression = self.solve_lookup_type(arg)
  File "C:\Users\amand\python-cordarme\drf-api\venv\lib\site-packages\django\db\models\sql\query.py", line 1099, in solve_lookup_type
    _, field, _, lookup_parts = self.names_to_path(lookup_splitted, self.get_meta())
  File "C:\Users\amand\python-cordarme\drf-api\venv\lib\site-packages\django\db\models\sql\query.py", line 1522, in names_to_path
    raise FieldError("Cannot resolve keyword '%s' into field. "
django.core.exceptions.FieldError: Cannot resolve keyword 'servico' into field. Choices are: agendamento, funcionarios, id, nome_estabelecimento
2022-05-04 21:54:04,342 django.request ERROR    Internal Server Error: /api/estabelecimentos/
Traceback (most recent call last):
  File "C:\Users\amand\python-cordarme\drf-api\venv\lib\site-packages\django\core\handlers\exception.py", line 47, in inner
    response = get_response(request)
  File "C:\Users\amand\python-cordarme\drf-api\venv\lib\site-packages\django\core\handlers\base.py", line 181, in _get_response
    response = wrapped_callback(request, *callback_args, **callback_kwargs)
  File "C:\Users\amand\python-cordarme\drf-api\venv\lib\site-packages\django\views\decorators\csrf.py", line 54, in wrapped_view
    return view_func(*args, **kwargs)
  File "C:\Users\amand\python-cordarme\drf-api\venv\lib\site-packages\django\views\generic\base.py", line 69, in view
    return self.dispatch(request, *args, **kwargs)
  File "C:\Users\amand\python-cordarme\drf-api\venv\lib\site-packages\rest_framework\views.py", line 509, in dispatch
    response = self.handle_exception(exc)
  File "C:\Users\amand\python-cordarme\drf-api\venv\lib\site-packages\rest_framework\views.py", line 469, in handle_exception
    self.raise_uncaught_exception(exc)
  File "C:\Users\amand\python-cordarme\drf-api\venv\lib\site-packages\rest_framework\views.py", line 480, in raise_uncaught_exception
    raise exc
  File "C:\Users\amand\python-cordarme\drf-api\venv\lib\site-packages\rest_framework\views.py", line 506, in dispatch
    response = handler(request, *args, **kwargs)
  File "C:\Users\amand\python-cordarme\drf-api\venv\lib\site-packages\rest_framework\generics.py", line 242, in post
    return self.create(request, *args, **kwargs)
  File "C:\Users\amand\python-cordarme\drf-api\venv\lib\site-packages\rest_framework\mixins.py", line 18, in create
    serializer.is_valid(raise_exception=True)
  File "C:\Users\amand\python-cordarme\drf-api\venv\lib\site-packages\rest_framework\serializers.py", line 227, in is_valid
    self._validated_data = self.run_validation(self.initial_data)
  File "C:\Users\amand\python-cordarme\drf-api\venv\lib\site-packages\rest_framework\serializers.py", line 429, in run_validation
    value = self.validate(value)
  File "C:\Users\amand\python-cordarme\drf-api\agenda\serializers.py", line 195, in validate
    if Estabelecimento.objects.filter(servico=estabelecimento_request).exists():
  File "C:\Users\amand\python-cordarme\drf-api\venv\lib\site-packages\django\db\models\manager.py", line 85, in manager_method
    return getattr(self.get_queryset(), name)(*args, **kwargs)
  File "C:\Users\amand\python-cordarme\drf-api\venv\lib\site-packages\django\db\models\query.py", line 974, in filter
    return self._filter_or_exclude(False, args, kwargs)
  File "C:\Users\amand\python-cordarme\drf-api\venv\lib\site-packages\django\db\models\query.py", line 992, in _filter_or_exclude
    clone._filter_or_exclude_inplace(negate, args, kwargs)
  File "C:\Users\amand\python-cordarme\drf-api\venv\lib\site-packages\django\db\models\query.py", line 999, in _filter_or_exclude_inplace
    self._query.add_q(Q(*args, **kwargs))
  File "C:\Users\amand\python-cordarme\drf-api\venv\lib\site-packages\django\db\models\sql\query.py", line 1375, in add_q
    clause, _ = self._add_q(q_object, self.used_aliases)
  File "C:\Users\amand\python-cordarme\drf-api\venv\lib\site-packages\django\db\models\sql\query.py", line 1396, in _add_q
    child_clause, needed_inner = self.build_filter(
  File "C:\Users\amand\python-cordarme\drf-api\venv\lib\site-packages\django\db\models\sql\query.py", line 1271, in build_filter
    lookups, parts, reffed_expression = self.solve_lookup_type(arg)
  File "C:\Users\amand\python-cordarme\drf-api\venv\lib\site-packages\django\db\models\sql\query.py", line 1099, in solve_lookup_type
    _, field, _, lookup_parts = self.names_to_path(lookup_splitted, self.get_meta())
  File "C:\Users\amand\python-cordarme\drf-api\venv\lib\site-packages\django\db\models\sql\query.py", line 1522, in names_to_path
    raise FieldError("Cannot resolve keyword '%s' into field. "
django.core.exceptions.FieldError: Cannot resolve keyword 'servico' into field. Choices are: agendamento, funcionarios, id, nome_estabelecimento
2022-05-04 21:54:25,696 django.utils.autoreload INFO     C:\Users\amand\python-cordarme\drf-api\agenda\serializers.py changed, reloading.
2022-05-04 21:54:26,752 django.utils.autoreload INFO     Watching for file changes with StatReloader
2022-05-04 21:54:27,905 django.request ERROR    Internal Server Error: /api/estabelecimentos/
Traceback (most recent call last):
  File "C:\Users\amand\python-cordarme\drf-api\venv\lib\site-packages\django\core\handlers\exception.py", line 47, in inner
    response = get_response(request)
  File "C:\Users\amand\python-cordarme\drf-api\venv\lib\site-packages\django\core\handlers\base.py", line 181, in _get_response
    response = wrapped_callback(request, *callback_args, **callback_kwargs)
  File "C:\Users\amand\python-cordarme\drf-api\venv\lib\site-packages\django\views\decorators\csrf.py", line 54, in wrapped_view
    return view_func(*args, **kwargs)
  File "C:\Users\amand\python-cordarme\drf-api\venv\lib\site-packages\django\views\generic\base.py", line 69, in view
    return self.dispatch(request, *args, **kwargs)
  File "C:\Users\amand\python-cordarme\drf-api\venv\lib\site-packages\rest_framework\views.py", line 509, in dispatch
    response = self.handle_exception(exc)
  File "C:\Users\amand\python-cordarme\drf-api\venv\lib\site-packages\rest_framework\views.py", line 469, in handle_exception
    self.raise_uncaught_exception(exc)
  File "C:\Users\amand\python-cordarme\drf-api\venv\lib\site-packages\rest_framework\views.py", line 480, in raise_uncaught_exception
    raise exc
  File "C:\Users\amand\python-cordarme\drf-api\venv\lib\site-packages\rest_framework\views.py", line 506, in dispatch
    response = handler(request, *args, **kwargs)
  File "C:\Users\amand\python-cordarme\drf-api\venv\lib\site-packages\rest_framework\generics.py", line 242, in post
    return self.create(request, *args, **kwargs)
  File "C:\Users\amand\python-cordarme\drf-api\venv\lib\site-packages\rest_framework\mixins.py", line 18, in create
    serializer.is_valid(raise_exception=True)
  File "C:\Users\amand\python-cordarme\drf-api\venv\lib\site-packages\rest_framework\serializers.py", line 227, in is_valid
    self._validated_data = self.run_validation(self.initial_data)
  File "C:\Users\amand\python-cordarme\drf-api\venv\lib\site-packages\rest_framework\serializers.py", line 429, in run_validation
    value = self.validate(value)
  File "C:\Users\amand\python-cordarme\drf-api\agenda\serializers.py", line 195, in validate
    if Estabelecimento.objects.filter(
  File "C:\Users\amand\python-cordarme\drf-api\venv\lib\site-packages\django\db\models\manager.py", line 85, in manager_method
    return getattr(self.get_queryset(), name)(*args, **kwargs)
  File "C:\Users\amand\python-cordarme\drf-api\venv\lib\site-packages\django\db\models\query.py", line 974, in filter
    return self._filter_or_exclude(False, args, kwargs)
  File "C:\Users\amand\python-cordarme\drf-api\venv\lib\site-packages\django\db\models\query.py", line 992, in _filter_or_exclude
    clone._filter_or_exclude_inplace(negate, args, kwargs)
  File "C:\Users\amand\python-cordarme\drf-api\venv\lib\site-packages\django\db\models\query.py", line 999, in _filter_or_exclude_inplace
    self._query.add_q(Q(*args, **kwargs))
  File "C:\Users\amand\python-cordarme\drf-api\venv\lib\site-packages\django\db\models\sql\query.py", line 1375, in add_q
    clause, _ = self._add_q(q_object, self.used_aliases)
  File "C:\Users\amand\python-cordarme\drf-api\venv\lib\site-packages\django\db\models\sql\query.py", line 1396, in _add_q
    child_clause, needed_inner = self.build_filter(
  File "C:\Users\amand\python-cordarme\drf-api\venv\lib\site-packages\django\db\models\sql\query.py", line 1271, in build_filter
    lookups, parts, reffed_expression = self.solve_lookup_type(arg)
  File "C:\Users\amand\python-cordarme\drf-api\venv\lib\site-packages\django\db\models\sql\query.py", line 1099, in solve_lookup_type
    _, field, _, lookup_parts = self.names_to_path(lookup_splitted, self.get_meta())
  File "C:\Users\amand\python-cordarme\drf-api\venv\lib\site-packages\django\db\models\sql\query.py", line 1522, in names_to_path
    raise FieldError("Cannot resolve keyword '%s' into field. "
django.core.exceptions.FieldError: Cannot resolve keyword 'estabelecimento' into field. Choices are: agendamento, funcionarios, id, nome_estabelecimento
2022-05-04 21:54:29,499 django.request ERROR    Internal Server Error: /api/estabelecimentos/
Traceback (most recent call last):
  File "C:\Users\amand\python-cordarme\drf-api\venv\lib\site-packages\django\core\handlers\exception.py", line 47, in inner
    response = get_response(request)
  File "C:\Users\amand\python-cordarme\drf-api\venv\lib\site-packages\django\core\handlers\base.py", line 181, in _get_response
    response = wrapped_callback(request, *callback_args, **callback_kwargs)
  File "C:\Users\amand\python-cordarme\drf-api\venv\lib\site-packages\django\views\decorators\csrf.py", line 54, in wrapped_view
    return view_func(*args, **kwargs)
  File "C:\Users\amand\python-cordarme\drf-api\venv\lib\site-packages\django\views\generic\base.py", line 69, in view
    return self.dispatch(request, *args, **kwargs)
  File "C:\Users\amand\python-cordarme\drf-api\venv\lib\site-packages\rest_framework\views.py", line 509, in dispatch
    response = self.handle_exception(exc)
  File "C:\Users\amand\python-cordarme\drf-api\venv\lib\site-packages\rest_framework\views.py", line 469, in handle_exception
    self.raise_uncaught_exception(exc)
  File "C:\Users\amand\python-cordarme\drf-api\venv\lib\site-packages\rest_framework\views.py", line 480, in raise_uncaught_exception
    raise exc
  File "C:\Users\amand\python-cordarme\drf-api\venv\lib\site-packages\rest_framework\views.py", line 506, in dispatch
    response = handler(request, *args, **kwargs)
  File "C:\Users\amand\python-cordarme\drf-api\venv\lib\site-packages\rest_framework\generics.py", line 242, in post
    return self.create(request, *args, **kwargs)
  File "C:\Users\amand\python-cordarme\drf-api\venv\lib\site-packages\rest_framework\mixins.py", line 18, in create
    serializer.is_valid(raise_exception=True)
  File "C:\Users\amand\python-cordarme\drf-api\venv\lib\site-packages\rest_framework\serializers.py", line 227, in is_valid
    self._validated_data = self.run_validation(self.initial_data)
  File "C:\Users\amand\python-cordarme\drf-api\venv\lib\site-packages\rest_framework\serializers.py", line 429, in run_validation
    value = self.validate(value)
  File "C:\Users\amand\python-cordarme\drf-api\agenda\serializers.py", line 195, in validate
    if Estabelecimento.objects.filter(
  File "C:\Users\amand\python-cordarme\drf-api\venv\lib\site-packages\django\db\models\manager.py", line 85, in manager_method
    return getattr(self.get_queryset(), name)(*args, **kwargs)
  File "C:\Users\amand\python-cordarme\drf-api\venv\lib\site-packages\django\db\models\query.py", line 974, in filter
    return self._filter_or_exclude(False, args, kwargs)
  File "C:\Users\amand\python-cordarme\drf-api\venv\lib\site-packages\django\db\models\query.py", line 992, in _filter_or_exclude
    clone._filter_or_exclude_inplace(negate, args, kwargs)
  File "C:\Users\amand\python-cordarme\drf-api\venv\lib\site-packages\django\db\models\query.py", line 999, in _filter_or_exclude_inplace
    self._query.add_q(Q(*args, **kwargs))
  File "C:\Users\amand\python-cordarme\drf-api\venv\lib\site-packages\django\db\models\sql\query.py", line 1375, in add_q
    clause, _ = self._add_q(q_object, self.used_aliases)
  File "C:\Users\amand\python-cordarme\drf-api\venv\lib\site-packages\django\db\models\sql\query.py", line 1396, in _add_q
    child_clause, needed_inner = self.build_filter(
  File "C:\Users\amand\python-cordarme\drf-api\venv\lib\site-packages\django\db\models\sql\query.py", line 1271, in build_filter
    lookups, parts, reffed_expression = self.solve_lookup_type(arg)
  File "C:\Users\amand\python-cordarme\drf-api\venv\lib\site-packages\django\db\models\sql\query.py", line 1099, in solve_lookup_type
    _, field, _, lookup_parts = self.names_to_path(lookup_splitted, self.get_meta())
  File "C:\Users\amand\python-cordarme\drf-api\venv\lib\site-packages\django\db\models\sql\query.py", line 1522, in names_to_path
    raise FieldError("Cannot resolve keyword '%s' into field. "
django.core.exceptions.FieldError: Cannot resolve keyword 'estabelecimento' into field. Choices are: agendamento, funcionarios, id, nome_estabelecimento
2022-05-04 21:54:35,119 django.utils.autoreload INFO     C:\Users\amand\python-cordarme\drf-api\agenda\serializers.py changed, reloading.
2022-05-04 21:54:35,937 django.utils.autoreload INFO     Watching for file changes with StatReloader
2022-05-04 21:54:58,029 django.utils.autoreload INFO     C:\Users\amand\python-cordarme\drf-api\agenda\serializers.py changed, reloading.
2022-05-04 21:54:58,865 django.utils.autoreload INFO     Watching for file changes with StatReloader
2022-05-04 21:55:12,628 django.utils.autoreload INFO     C:\Users\amand\python-cordarme\drf-api\agenda\serializers.py changed, reloading.
2022-05-04 21:55:13,553 django.utils.autoreload INFO     Watching for file changes with StatReloader
2022-05-04 21:55:15,258 django.request WARNING  Bad Request: /api/estabelecimentos/
2022-05-04 21:56:58,969 django.request ERROR    Internal Server Error: /api/funcionarios/
Traceback (most recent call last):
  File "C:\Users\amand\python-cordarme\drf-api\venv\lib\site-packages\django\db\backends\utils.py", line 85, in _execute
    return self.cursor.execute(sql, params)
  File "C:\Users\amand\python-cordarme\drf-api\venv\lib\site-packages\django\db\backends\sqlite3\base.py", line 416, in execute
    return Database.Cursor.execute(self, query, params)
sqlite3.IntegrityError: NOT NULL constraint failed: agenda_funcionarios.prestador_id

The above exception was the direct cause of the following exception:

Traceback (most recent call last):
  File "C:\Users\amand\python-cordarme\drf-api\venv\lib\site-packages\django\core\handlers\exception.py", line 47, in inner
    response = get_response(request)
  File "C:\Users\amand\python-cordarme\drf-api\venv\lib\site-packages\django\core\handlers\base.py", line 181, in _get_response
    response = wrapped_callback(request, *callback_args, **callback_kwargs)
  File "C:\Users\amand\python-cordarme\drf-api\venv\lib\site-packages\django\views\decorators\csrf.py", line 54, in wrapped_view
    return view_func(*args, **kwargs)
  File "C:\Users\amand\python-cordarme\drf-api\venv\lib\site-packages\django\views\generic\base.py", line 69, in view
    return self.dispatch(request, *args, **kwargs)
  File "C:\Users\amand\python-cordarme\drf-api\venv\lib\site-packages\rest_framework\views.py", line 509, in dispatch
    response = self.handle_exception(exc)
  File "C:\Users\amand\python-cordarme\drf-api\venv\lib\site-packages\rest_framework\views.py", line 469, in handle_exception
    self.raise_uncaught_exception(exc)
  File "C:\Users\amand\python-cordarme\drf-api\venv\lib\site-packages\rest_framework\views.py", line 480, in raise_uncaught_exception
    raise exc
  File "C:\Users\amand\python-cordarme\drf-api\venv\lib\site-packages\rest_framework\views.py", line 506, in dispatch
    response = handler(request, *args, **kwargs)
  File "C:\Users\amand\python-cordarme\drf-api\agenda\views.py", line 158, in post
    Funcionarios.objects.create(
  File "C:\Users\amand\python-cordarme\drf-api\venv\lib\site-packages\django\db\models\manager.py", line 85, in manager_method
    return getattr(self.get_queryset(), name)(*args, **kwargs)
  File "C:\Users\amand\python-cordarme\drf-api\venv\lib\site-packages\django\db\models\query.py", line 457, in create
    obj.save(force_insert=True, using=self.db)
  File "C:\Users\amand\python-cordarme\drf-api\venv\lib\site-packages\django\db\models\base.py", line 743, in save
    self.save_base(using=using, force_insert=force_insert,
  File "C:\Users\amand\python-cordarme\drf-api\venv\lib\site-packages\django\db\models\base.py", line 780, in save_base
    updated = self._save_table(
  File "C:\Users\amand\python-cordarme\drf-api\venv\lib\site-packages\django\db\models\base.py", line 885, in _save_table
    results = self._do_insert(cls._base_manager, using, fields, returning_fields, raw)
  File "C:\Users\amand\python-cordarme\drf-api\venv\lib\site-packages\django\db\models\base.py", line 923, in _do_insert
    return manager._insert(
  File "C:\Users\amand\python-cordarme\drf-api\venv\lib\site-packages\django\db\models\manager.py", line 85, in manager_method
    return getattr(self.get_queryset(), name)(*args, **kwargs)
  File "C:\Users\amand\python-cordarme\drf-api\venv\lib\site-packages\django\db\models\query.py", line 1301, in _insert
    return query.get_compiler(using=using).execute_sql(returning_fields)
  File "C:\Users\amand\python-cordarme\drf-api\venv\lib\site-packages\django\db\models\sql\compiler.py", line 1441, in execute_sql
    cursor.execute(sql, params)
  File "C:\Users\amand\python-cordarme\drf-api\venv\lib\site-packages\django\db\backends\utils.py", line 99, in execute
    return super().execute(sql, params)
  File "C:\Users\amand\python-cordarme\drf-api\venv\lib\site-packages\django\db\backends\utils.py", line 67, in execute
    return self._execute_with_wrappers(sql, params, many=False, executor=self._execute)
  File "C:\Users\amand\python-cordarme\drf-api\venv\lib\site-packages\django\db\backends\utils.py", line 76, in _execute_with_wrappers
    return executor(sql, params, many, context)
  File "C:\Users\amand\python-cordarme\drf-api\venv\lib\site-packages\django\db\backends\utils.py", line 80, in _execute
    with self.db.wrap_database_errors:
  File "C:\Users\amand\python-cordarme\drf-api\venv\lib\site-packages\django\db\utils.py", line 90, in __exit__
    raise dj_exc_value.with_traceback(traceback) from exc_value
  File "C:\Users\amand\python-cordarme\drf-api\venv\lib\site-packages\django\db\backends\utils.py", line 85, in _execute
    return self.cursor.execute(sql, params)
  File "C:\Users\amand\python-cordarme\drf-api\venv\lib\site-packages\django\db\backends\sqlite3\base.py", line 416, in execute
    return Database.Cursor.execute(self, query, params)
django.db.utils.IntegrityError: NOT NULL constraint failed: agenda_funcionarios.prestador_id
2022-05-04 21:58:21,482 django.request ERROR    Internal Server Error: /api/funcionarios/
Traceback (most recent call last):
  File "C:\Users\amand\python-cordarme\drf-api\venv\lib\site-packages\django\db\backends\utils.py", line 85, in _execute
    return self.cursor.execute(sql, params)
  File "C:\Users\amand\python-cordarme\drf-api\venv\lib\site-packages\django\db\backends\sqlite3\base.py", line 416, in execute
    return Database.Cursor.execute(self, query, params)
sqlite3.IntegrityError: UNIQUE constraint failed: agenda_funcionarios.prestador_id, agenda_funcionarios.estabelecimento_id

The above exception was the direct cause of the following exception:

Traceback (most recent call last):
  File "C:\Users\amand\python-cordarme\drf-api\venv\lib\site-packages\django\core\handlers\exception.py", line 47, in inner
    response = get_response(request)
  File "C:\Users\amand\python-cordarme\drf-api\venv\lib\site-packages\django\core\handlers\base.py", line 181, in _get_response
    response = wrapped_callback(request, *callback_args, **callback_kwargs)
  File "C:\Users\amand\python-cordarme\drf-api\venv\lib\site-packages\django\views\decorators\csrf.py", line 54, in wrapped_view
    return view_func(*args, **kwargs)
  File "C:\Users\amand\python-cordarme\drf-api\venv\lib\site-packages\django\views\generic\base.py", line 69, in view
    return self.dispatch(request, *args, **kwargs)
  File "C:\Users\amand\python-cordarme\drf-api\venv\lib\site-packages\rest_framework\views.py", line 509, in dispatch
    response = self.handle_exception(exc)
  File "C:\Users\amand\python-cordarme\drf-api\venv\lib\site-packages\rest_framework\views.py", line 469, in handle_exception
    self.raise_uncaught_exception(exc)
  File "C:\Users\amand\python-cordarme\drf-api\venv\lib\site-packages\rest_framework\views.py", line 480, in raise_uncaught_exception
    raise exc
  File "C:\Users\amand\python-cordarme\drf-api\venv\lib\site-packages\rest_framework\views.py", line 506, in dispatch
    response = handler(request, *args, **kwargs)
  File "C:\Users\amand\python-cordarme\drf-api\agenda\views.py", line 158, in post
    Funcionarios.objects.create(
  File "C:\Users\amand\python-cordarme\drf-api\venv\lib\site-packages\django\db\models\manager.py", line 85, in manager_method
    return getattr(self.get_queryset(), name)(*args, **kwargs)
  File "C:\Users\amand\python-cordarme\drf-api\venv\lib\site-packages\django\db\models\query.py", line 457, in create
    obj.save(force_insert=True, using=self.db)
  File "C:\Users\amand\python-cordarme\drf-api\venv\lib\site-packages\django\db\models\base.py", line 743, in save
    self.save_base(using=using, force_insert=force_insert,
  File "C:\Users\amand\python-cordarme\drf-api\venv\lib\site-packages\django\db\models\base.py", line 780, in save_base
    updated = self._save_table(
  File "C:\Users\amand\python-cordarme\drf-api\venv\lib\site-packages\django\db\models\base.py", line 885, in _save_table
    results = self._do_insert(cls._base_manager, using, fields, returning_fields, raw)
  File "C:\Users\amand\python-cordarme\drf-api\venv\lib\site-packages\django\db\models\base.py", line 923, in _do_insert
    return manager._insert(
  File "C:\Users\amand\python-cordarme\drf-api\venv\lib\site-packages\django\db\models\manager.py", line 85, in manager_method
    return getattr(self.get_queryset(), name)(*args, **kwargs)
  File "C:\Users\amand\python-cordarme\drf-api\venv\lib\site-packages\django\db\models\query.py", line 1301, in _insert
    return query.get_compiler(using=using).execute_sql(returning_fields)
  File "C:\Users\amand\python-cordarme\drf-api\venv\lib\site-packages\django\db\models\sql\compiler.py", line 1441, in execute_sql
    cursor.execute(sql, params)
  File "C:\Users\amand\python-cordarme\drf-api\venv\lib\site-packages\django\db\backends\utils.py", line 99, in execute
    return super().execute(sql, params)
  File "C:\Users\amand\python-cordarme\drf-api\venv\lib\site-packages\django\db\backends\utils.py", line 67, in execute
    return self._execute_with_wrappers(sql, params, many=False, executor=self._execute)
  File "C:\Users\amand\python-cordarme\drf-api\venv\lib\site-packages\django\db\backends\utils.py", line 76, in _execute_with_wrappers
    return executor(sql, params, many, context)
  File "C:\Users\amand\python-cordarme\drf-api\venv\lib\site-packages\django\db\backends\utils.py", line 80, in _execute
    with self.db.wrap_database_errors:
  File "C:\Users\amand\python-cordarme\drf-api\venv\lib\site-packages\django\db\utils.py", line 90, in __exit__
    raise dj_exc_value.with_traceback(traceback) from exc_value
  File "C:\Users\amand\python-cordarme\drf-api\venv\lib\site-packages\django\db\backends\utils.py", line 85, in _execute
    return self.cursor.execute(sql, params)
  File "C:\Users\amand\python-cordarme\drf-api\venv\lib\site-packages\django\db\backends\sqlite3\base.py", line 416, in execute
    return Database.Cursor.execute(self, query, params)
django.db.utils.IntegrityError: UNIQUE constraint failed: agenda_funcionarios.prestador_id, agenda_funcionarios.estabelecimento_id
2022-05-04 21:58:46,413 root         INFO     Fazendo requisição para BrasilAPI para a data: 2022-04-12
2022-05-04 21:58:46,435 urllib3.connectionpool DEBUG    Starting new HTTPS connection (1): brasilapi.com.br:443
2022-05-04 21:58:47,128 urllib3.connectionpool DEBUG    https://brasilapi.com.br:443 "GET /api/feriados/v1/2022 HTTP/1.1" 200 None
2022-05-22 22:24:12,663 django.utils.autoreload INFO     Watching for file changes with StatReloader
2022-05-23 16:27:30,881 django.utils.autoreload INFO     Watching for file changes with StatReloader
2022-05-25 17:12:39,477 django.utils.autoreload INFO     Watching for file changes with StatReloader
2022-05-25 17:13:44,173 django.request ERROR    Internal Server Error: /api/endereco/
Traceback (most recent call last):
  File "C:\Users\amand\python-cordarme\drf-api\venv\lib\site-packages\django\db\backends\utils.py", line 85, in _execute
    return self.cursor.execute(sql, params)
  File "C:\Users\amand\python-cordarme\drf-api\venv\lib\site-packages\django\db\backends\sqlite3\base.py", line 416, in execute
    return Database.Cursor.execute(self, query, params)
sqlite3.OperationalError: no such table: agenda_endereco

The above exception was the direct cause of the following exception:

Traceback (most recent call last):
  File "C:\Users\amand\python-cordarme\drf-api\venv\lib\site-packages\django\core\handlers\exception.py", line 47, in inner
    response = get_response(request)
  File "C:\Users\amand\python-cordarme\drf-api\venv\lib\site-packages\django\core\handlers\base.py", line 181, in _get_response
    response = wrapped_callback(request, *callback_args, **callback_kwargs)
  File "C:\Users\amand\python-cordarme\drf-api\venv\lib\site-packages\django\views\decorators\csrf.py", line 54, in wrapped_view
    return view_func(*args, **kwargs)
  File "C:\Users\amand\python-cordarme\drf-api\venv\lib\site-packages\django\views\generic\base.py", line 69, in view
    return self.dispatch(request, *args, **kwargs)
  File "C:\Users\amand\python-cordarme\drf-api\venv\lib\site-packages\rest_framework\views.py", line 509, in dispatch
    response = self.handle_exception(exc)
  File "C:\Users\amand\python-cordarme\drf-api\venv\lib\site-packages\rest_framework\views.py", line 469, in handle_exception
    self.raise_uncaught_exception(exc)
  File "C:\Users\amand\python-cordarme\drf-api\venv\lib\site-packages\rest_framework\views.py", line 480, in raise_uncaught_exception
    raise exc
  File "C:\Users\amand\python-cordarme\drf-api\venv\lib\site-packages\rest_framework\views.py", line 506, in dispatch
    response = handler(request, *args, **kwargs)
  File "C:\Users\amand\python-cordarme\drf-api\venv\lib\site-packages\rest_framework\generics.py", line 239, in get
    return self.list(request, *args, **kwargs)
  File "C:\Users\amand\python-cordarme\drf-api\venv\lib\site-packages\rest_framework\mixins.py", line 46, in list
    return Response(serializer.data)
  File "C:\Users\amand\python-cordarme\drf-api\venv\lib\site-packages\rest_framework\serializers.py", line 768, in data
    ret = super().data
  File "C:\Users\amand\python-cordarme\drf-api\venv\lib\site-packages\rest_framework\serializers.py", line 253, in data
    self._data = self.to_representation(self.instance)
  File "C:\Users\amand\python-cordarme\drf-api\venv\lib\site-packages\rest_framework\serializers.py", line 686, in to_representation
    return [
  File "C:\Users\amand\python-cordarme\drf-api\venv\lib\site-packages\django\db\models\query.py", line 280, in __iter__
    self._fetch_all()
  File "C:\Users\amand\python-cordarme\drf-api\venv\lib\site-packages\django\db\models\query.py", line 1354, in _fetch_all
    self._result_cache = list(self._iterable_class(self))
  File "C:\Users\amand\python-cordarme\drf-api\venv\lib\site-packages\django\db\models\query.py", line 51, in __iter__
    results = compiler.execute_sql(chunked_fetch=self.chunked_fetch, chunk_size=self.chunk_size)
  File "C:\Users\amand\python-cordarme\drf-api\venv\lib\site-packages\django\db\models\sql\compiler.py", line 1202, in execute_sql
    cursor.execute(sql, params)
  File "C:\Users\amand\python-cordarme\drf-api\venv\lib\site-packages\django\db\backends\utils.py", line 99, in execute
    return super().execute(sql, params)
  File "C:\Users\amand\python-cordarme\drf-api\venv\lib\site-packages\django\db\backends\utils.py", line 67, in execute
    return self._execute_with_wrappers(sql, params, many=False, executor=self._execute)
  File "C:\Users\amand\python-cordarme\drf-api\venv\lib\site-packages\django\db\backends\utils.py", line 76, in _execute_with_wrappers
    return executor(sql, params, many, context)
  File "C:\Users\amand\python-cordarme\drf-api\venv\lib\site-packages\django\db\backends\utils.py", line 80, in _execute
    with self.db.wrap_database_errors:
  File "C:\Users\amand\python-cordarme\drf-api\venv\lib\site-packages\django\db\utils.py", line 90, in __exit__
    raise dj_exc_value.with_traceback(traceback) from exc_value
  File "C:\Users\amand\python-cordarme\drf-api\venv\lib\site-packages\django\db\backends\utils.py", line 85, in _execute
    return self.cursor.execute(sql, params)
  File "C:\Users\amand\python-cordarme\drf-api\venv\lib\site-packages\django\db\backends\sqlite3\base.py", line 416, in execute
    return Database.Cursor.execute(self, query, params)
django.db.utils.OperationalError: no such table: agenda_endereco
2022-05-25 17:13:48,956 django.request ERROR    Internal Server Error: /api/endereco/
Traceback (most recent call last):
  File "C:\Users\amand\python-cordarme\drf-api\venv\lib\site-packages\django\db\backends\utils.py", line 85, in _execute
    return self.cursor.execute(sql, params)
  File "C:\Users\amand\python-cordarme\drf-api\venv\lib\site-packages\django\db\backends\sqlite3\base.py", line 416, in execute
    return Database.Cursor.execute(self, query, params)
sqlite3.OperationalError: no such table: agenda_endereco

The above exception was the direct cause of the following exception:

Traceback (most recent call last):
  File "C:\Users\amand\python-cordarme\drf-api\venv\lib\site-packages\django\core\handlers\exception.py", line 47, in inner
    response = get_response(request)
  File "C:\Users\amand\python-cordarme\drf-api\venv\lib\site-packages\django\core\handlers\base.py", line 181, in _get_response
    response = wrapped_callback(request, *callback_args, **callback_kwargs)
  File "C:\Users\amand\python-cordarme\drf-api\venv\lib\site-packages\django\views\decorators\csrf.py", line 54, in wrapped_view
    return view_func(*args, **kwargs)
  File "C:\Users\amand\python-cordarme\drf-api\venv\lib\site-packages\django\views\generic\base.py", line 69, in view
    return self.dispatch(request, *args, **kwargs)
  File "C:\Users\amand\python-cordarme\drf-api\venv\lib\site-packages\rest_framework\views.py", line 509, in dispatch
    response = self.handle_exception(exc)
  File "C:\Users\amand\python-cordarme\drf-api\venv\lib\site-packages\rest_framework\views.py", line 469, in handle_exception
    self.raise_uncaught_exception(exc)
  File "C:\Users\amand\python-cordarme\drf-api\venv\lib\site-packages\rest_framework\views.py", line 480, in raise_uncaught_exception
    raise exc
  File "C:\Users\amand\python-cordarme\drf-api\venv\lib\site-packages\rest_framework\views.py", line 506, in dispatch
    response = handler(request, *args, **kwargs)
  File "C:\Users\amand\python-cordarme\drf-api\venv\lib\site-packages\rest_framework\generics.py", line 239, in get
    return self.list(request, *args, **kwargs)
  File "C:\Users\amand\python-cordarme\drf-api\venv\lib\site-packages\rest_framework\mixins.py", line 46, in list
    return Response(serializer.data)
  File "C:\Users\amand\python-cordarme\drf-api\venv\lib\site-packages\rest_framework\serializers.py", line 768, in data
    ret = super().data
  File "C:\Users\amand\python-cordarme\drf-api\venv\lib\site-packages\rest_framework\serializers.py", line 253, in data
    self._data = self.to_representation(self.instance)
  File "C:\Users\amand\python-cordarme\drf-api\venv\lib\site-packages\rest_framework\serializers.py", line 686, in to_representation
    return [
  File "C:\Users\amand\python-cordarme\drf-api\venv\lib\site-packages\django\db\models\query.py", line 280, in __iter__
    self._fetch_all()
  File "C:\Users\amand\python-cordarme\drf-api\venv\lib\site-packages\django\db\models\query.py", line 1354, in _fetch_all
    self._result_cache = list(self._iterable_class(self))
  File "C:\Users\amand\python-cordarme\drf-api\venv\lib\site-packages\django\db\models\query.py", line 51, in __iter__
    results = compiler.execute_sql(chunked_fetch=self.chunked_fetch, chunk_size=self.chunk_size)
  File "C:\Users\amand\python-cordarme\drf-api\venv\lib\site-packages\django\db\models\sql\compiler.py", line 1202, in execute_sql
    cursor.execute(sql, params)
  File "C:\Users\amand\python-cordarme\drf-api\venv\lib\site-packages\django\db\backends\utils.py", line 99, in execute
    return super().execute(sql, params)
  File "C:\Users\amand\python-cordarme\drf-api\venv\lib\site-packages\django\db\backends\utils.py", line 67, in execute
    return self._execute_with_wrappers(sql, params, many=False, executor=self._execute)
  File "C:\Users\amand\python-cordarme\drf-api\venv\lib\site-packages\django\db\backends\utils.py", line 76, in _execute_with_wrappers
    return executor(sql, params, many, context)
  File "C:\Users\amand\python-cordarme\drf-api\venv\lib\site-packages\django\db\backends\utils.py", line 80, in _execute
    with self.db.wrap_database_errors:
  File "C:\Users\amand\python-cordarme\drf-api\venv\lib\site-packages\django\db\utils.py", line 90, in __exit__
    raise dj_exc_value.with_traceback(traceback) from exc_value
  File "C:\Users\amand\python-cordarme\drf-api\venv\lib\site-packages\django\db\backends\utils.py", line 85, in _execute
    return self.cursor.execute(sql, params)
  File "C:\Users\amand\python-cordarme\drf-api\venv\lib\site-packages\django\db\backends\sqlite3\base.py", line 416, in execute
    return Database.Cursor.execute(self, query, params)
django.db.utils.OperationalError: no such table: agenda_endereco
2022-05-25 17:14:09,397 django.utils.autoreload INFO     C:\Users\amand\python-cordarme\drf-api\agenda\views.py changed, reloading.
2022-05-25 17:14:10,368 django.utils.autoreload INFO     Watching for file changes with StatReloader
2022-05-25 17:16:22,101 django.request WARNING  Forbidden: /api/servicos/
2022-05-25 17:16:29,389 django.request WARNING  Bad Request: /api/servicos/
2022-05-25 17:16:39,326 django.request ERROR    Internal Server Error: /api/endereco/
Traceback (most recent call last):
  File "C:\Users\amand\python-cordarme\drf-api\venv\lib\site-packages\django\core\handlers\exception.py", line 47, in inner
    response = get_response(request)
  File "C:\Users\amand\python-cordarme\drf-api\venv\lib\site-packages\django\core\handlers\base.py", line 181, in _get_response
    response = wrapped_callback(request, *callback_args, **callback_kwargs)
  File "C:\Users\amand\python-cordarme\drf-api\venv\lib\site-packages\django\views\decorators\csrf.py", line 54, in wrapped_view
    return view_func(*args, **kwargs)
  File "C:\Users\amand\python-cordarme\drf-api\venv\lib\site-packages\django\views\generic\base.py", line 69, in view
    return self.dispatch(request, *args, **kwargs)
  File "C:\Users\amand\python-cordarme\drf-api\venv\lib\site-packages\rest_framework\views.py", line 509, in dispatch
    response = self.handle_exception(exc)
  File "C:\Users\amand\python-cordarme\drf-api\venv\lib\site-packages\rest_framework\views.py", line 469, in handle_exception
    self.raise_uncaught_exception(exc)
  File "C:\Users\amand\python-cordarme\drf-api\venv\lib\site-packages\rest_framework\views.py", line 480, in raise_uncaught_exception
    raise exc
  File "C:\Users\amand\python-cordarme\drf-api\venv\lib\site-packages\rest_framework\views.py", line 506, in dispatch
    response = handler(request, *args, **kwargs)
  File "C:\Users\amand\python-cordarme\drf-api\venv\lib\site-packages\rest_framework\generics.py", line 242, in post
    return self.create(request, *args, **kwargs)
  File "C:\Users\amand\python-cordarme\drf-api\venv\lib\site-packages\rest_framework\mixins.py", line 19, in create
    self.perform_create(serializer)
  File "C:\Users\amand\python-cordarme\drf-api\venv\lib\site-packages\rest_framework\mixins.py", line 24, in perform_create
    serializer.save()
  File "C:\Users\amand\python-cordarme\drf-api\venv\lib\site-packages\rest_framework\serializers.py", line 212, in save
    self.instance = self.create(validated_data)
  File "C:\Users\amand\python-cordarme\drf-api\venv\lib\site-packages\rest_framework\serializers.py", line 962, in create
    instance = ModelClass._default_manager.create(**validated_data)
  File "C:\Users\amand\python-cordarme\drf-api\venv\lib\site-packages\django\db\models\manager.py", line 85, in manager_method
    return getattr(self.get_queryset(), name)(*args, **kwargs)
  File "C:\Users\amand\python-cordarme\drf-api\venv\lib\site-packages\django\db\models\query.py", line 455, in create
    obj = self.model(**kwargs)
  File "C:\Users\amand\python-cordarme\drf-api\venv\lib\site-packages\django\db\models\base.py", line 489, in __init__
    _setattr(self, field.name, rel_obj)
  File "C:\Users\amand\python-cordarme\drf-api\venv\lib\site-packages\django\db\models\fields\related_descriptors.py", line 215, in __set__
    raise ValueError(
ValueError: Cannot assign "'salão da maria'": "Endereco.estabelecimento" must be a "Estabelecimento" instance.
2022-05-25 17:16:50,579 django.request ERROR    Internal Server Error: /api/endereco/
Traceback (most recent call last):
  File "C:\Users\amand\python-cordarme\drf-api\venv\lib\site-packages\django\core\handlers\exception.py", line 47, in inner
    response = get_response(request)
  File "C:\Users\amand\python-cordarme\drf-api\venv\lib\site-packages\django\core\handlers\base.py", line 181, in _get_response
    response = wrapped_callback(request, *callback_args, **callback_kwargs)
  File "C:\Users\amand\python-cordarme\drf-api\venv\lib\site-packages\django\views\decorators\csrf.py", line 54, in wrapped_view
    return view_func(*args, **kwargs)
  File "C:\Users\amand\python-cordarme\drf-api\venv\lib\site-packages\django\views\generic\base.py", line 69, in view
    return self.dispatch(request, *args, **kwargs)
  File "C:\Users\amand\python-cordarme\drf-api\venv\lib\site-packages\rest_framework\views.py", line 509, in dispatch
    response = self.handle_exception(exc)
  File "C:\Users\amand\python-cordarme\drf-api\venv\lib\site-packages\rest_framework\views.py", line 469, in handle_exception
    self.raise_uncaught_exception(exc)
  File "C:\Users\amand\python-cordarme\drf-api\venv\lib\site-packages\rest_framework\views.py", line 480, in raise_uncaught_exception
    raise exc
  File "C:\Users\amand\python-cordarme\drf-api\venv\lib\site-packages\rest_framework\views.py", line 506, in dispatch
    response = handler(request, *args, **kwargs)
  File "C:\Users\amand\python-cordarme\drf-api\venv\lib\site-packages\rest_framework\generics.py", line 242, in post
    return self.create(request, *args, **kwargs)
  File "C:\Users\amand\python-cordarme\drf-api\venv\lib\site-packages\rest_framework\mixins.py", line 19, in create
    self.perform_create(serializer)
  File "C:\Users\amand\python-cordarme\drf-api\venv\lib\site-packages\rest_framework\mixins.py", line 24, in perform_create
    serializer.save()
  File "C:\Users\amand\python-cordarme\drf-api\venv\lib\site-packages\rest_framework\serializers.py", line 212, in save
    self.instance = self.create(validated_data)
  File "C:\Users\amand\python-cordarme\drf-api\venv\lib\site-packages\rest_framework\serializers.py", line 962, in create
    instance = ModelClass._default_manager.create(**validated_data)
  File "C:\Users\amand\python-cordarme\drf-api\venv\lib\site-packages\django\db\models\manager.py", line 85, in manager_method
    return getattr(self.get_queryset(), name)(*args, **kwargs)
  File "C:\Users\amand\python-cordarme\drf-api\venv\lib\site-packages\django\db\models\query.py", line 455, in create
    obj = self.model(**kwargs)
  File "C:\Users\amand\python-cordarme\drf-api\venv\lib\site-packages\django\db\models\base.py", line 489, in __init__
    _setattr(self, field.name, rel_obj)
  File "C:\Users\amand\python-cordarme\drf-api\venv\lib\site-packages\django\db\models\fields\related_descriptors.py", line 215, in __set__
    raise ValueError(
ValueError: Cannot assign "'salão da Maria'": "Endereco.estabelecimento" must be a "Estabelecimento" instance.
2022-05-25 17:17:11,101 django.request ERROR    Internal Server Error: /api/endereco/
Traceback (most recent call last):
  File "C:\Users\amand\python-cordarme\drf-api\venv\lib\site-packages\django\core\handlers\exception.py", line 47, in inner
    response = get_response(request)
  File "C:\Users\amand\python-cordarme\drf-api\venv\lib\site-packages\django\core\handlers\base.py", line 181, in _get_response
    response = wrapped_callback(request, *callback_args, **callback_kwargs)
  File "C:\Users\amand\python-cordarme\drf-api\venv\lib\site-packages\django\views\decorators\csrf.py", line 54, in wrapped_view
    return view_func(*args, **kwargs)
  File "C:\Users\amand\python-cordarme\drf-api\venv\lib\site-packages\django\views\generic\base.py", line 69, in view
    return self.dispatch(request, *args, **kwargs)
  File "C:\Users\amand\python-cordarme\drf-api\venv\lib\site-packages\rest_framework\views.py", line 509, in dispatch
    response = self.handle_exception(exc)
  File "C:\Users\amand\python-cordarme\drf-api\venv\lib\site-packages\rest_framework\views.py", line 469, in handle_exception
    self.raise_uncaught_exception(exc)
  File "C:\Users\amand\python-cordarme\drf-api\venv\lib\site-packages\rest_framework\views.py", line 480, in raise_uncaught_exception
    raise exc
  File "C:\Users\amand\python-cordarme\drf-api\venv\lib\site-packages\rest_framework\views.py", line 506, in dispatch
    response = handler(request, *args, **kwargs)
  File "C:\Users\amand\python-cordarme\drf-api\venv\lib\site-packages\rest_framework\generics.py", line 242, in post
    return self.create(request, *args, **kwargs)
  File "C:\Users\amand\python-cordarme\drf-api\venv\lib\site-packages\rest_framework\mixins.py", line 19, in create
    self.perform_create(serializer)
  File "C:\Users\amand\python-cordarme\drf-api\venv\lib\site-packages\rest_framework\mixins.py", line 24, in perform_create
    serializer.save()
  File "C:\Users\amand\python-cordarme\drf-api\venv\lib\site-packages\rest_framework\serializers.py", line 212, in save
    self.instance = self.create(validated_data)
  File "C:\Users\amand\python-cordarme\drf-api\venv\lib\site-packages\rest_framework\serializers.py", line 962, in create
    instance = ModelClass._default_manager.create(**validated_data)
  File "C:\Users\amand\python-cordarme\drf-api\venv\lib\site-packages\django\db\models\manager.py", line 85, in manager_method
    return getattr(self.get_queryset(), name)(*args, **kwargs)
  File "C:\Users\amand\python-cordarme\drf-api\venv\lib\site-packages\django\db\models\query.py", line 455, in create
    obj = self.model(**kwargs)
  File "C:\Users\amand\python-cordarme\drf-api\venv\lib\site-packages\django\db\models\base.py", line 489, in __init__
    _setattr(self, field.name, rel_obj)
  File "C:\Users\amand\python-cordarme\drf-api\venv\lib\site-packages\django\db\models\fields\related_descriptors.py", line 215, in __set__
    raise ValueError(
ValueError: Cannot assign "'Salão da Maria'": "Endereco.estabelecimento" must be a "Estabelecimento" instance.
2022-05-25 17:21:07,272 django.utils.autoreload INFO     C:\Users\amand\python-cordarme\drf-api\agenda\serializers.py changed, reloading.
2022-05-25 17:21:08,501 django.utils.autoreload INFO     Watching for file changes with StatReloader
2022-05-25 17:21:12,383 django.request ERROR    Internal Server Error: /api/endereco/
Traceback (most recent call last):
  File "C:\Users\amand\python-cordarme\drf-api\venv\lib\site-packages\django\db\backends\utils.py", line 85, in _execute
    return self.cursor.execute(sql, params)
  File "C:\Users\amand\python-cordarme\drf-api\venv\lib\site-packages\django\db\backends\sqlite3\base.py", line 416, in execute
    return Database.Cursor.execute(self, query, params)
sqlite3.OperationalError: no such table: agenda_endereco

The above exception was the direct cause of the following exception:

Traceback (most recent call last):
  File "C:\Users\amand\python-cordarme\drf-api\venv\lib\site-packages\django\core\handlers\exception.py", line 47, in inner
    response = get_response(request)
  File "C:\Users\amand\python-cordarme\drf-api\venv\lib\site-packages\django\core\handlers\base.py", line 181, in _get_response
    response = wrapped_callback(request, *callback_args, **callback_kwargs)
  File "C:\Users\amand\python-cordarme\drf-api\venv\lib\site-packages\django\views\decorators\csrf.py", line 54, in wrapped_view
    return view_func(*args, **kwargs)
  File "C:\Users\amand\python-cordarme\drf-api\venv\lib\site-packages\django\views\generic\base.py", line 69, in view
    return self.dispatch(request, *args, **kwargs)
  File "C:\Users\amand\python-cordarme\drf-api\venv\lib\site-packages\rest_framework\views.py", line 509, in dispatch
    response = self.handle_exception(exc)
  File "C:\Users\amand\python-cordarme\drf-api\venv\lib\site-packages\rest_framework\views.py", line 469, in handle_exception
    self.raise_uncaught_exception(exc)
  File "C:\Users\amand\python-cordarme\drf-api\venv\lib\site-packages\rest_framework\views.py", line 480, in raise_uncaught_exception
    raise exc
  File "C:\Users\amand\python-cordarme\drf-api\venv\lib\site-packages\rest_framework\views.py", line 506, in dispatch
    response = handler(request, *args, **kwargs)
  File "C:\Users\amand\python-cordarme\drf-api\venv\lib\site-packages\rest_framework\generics.py", line 242, in post
    return self.create(request, *args, **kwargs)
  File "C:\Users\amand\python-cordarme\drf-api\venv\lib\site-packages\rest_framework\mixins.py", line 19, in create
    self.perform_create(serializer)
  File "C:\Users\amand\python-cordarme\drf-api\venv\lib\site-packages\rest_framework\mixins.py", line 24, in perform_create
    serializer.save()
  File "C:\Users\amand\python-cordarme\drf-api\venv\lib\site-packages\rest_framework\serializers.py", line 212, in save
    self.instance = self.create(validated_data)
  File "C:\Users\amand\python-cordarme\drf-api\venv\lib\site-packages\rest_framework\serializers.py", line 962, in create
    instance = ModelClass._default_manager.create(**validated_data)
  File "C:\Users\amand\python-cordarme\drf-api\venv\lib\site-packages\django\db\models\manager.py", line 85, in manager_method
    return getattr(self.get_queryset(), name)(*args, **kwargs)
  File "C:\Users\amand\python-cordarme\drf-api\venv\lib\site-packages\django\db\models\query.py", line 457, in create
    obj.save(force_insert=True, using=self.db)
  File "C:\Users\amand\python-cordarme\drf-api\venv\lib\site-packages\django\db\models\base.py", line 743, in save
    self.save_base(using=using, force_insert=force_insert,
  File "C:\Users\amand\python-cordarme\drf-api\venv\lib\site-packages\django\db\models\base.py", line 780, in save_base
    updated = self._save_table(
  File "C:\Users\amand\python-cordarme\drf-api\venv\lib\site-packages\django\db\models\base.py", line 885, in _save_table
    results = self._do_insert(cls._base_manager, using, fields, returning_fields, raw)
  File "C:\Users\amand\python-cordarme\drf-api\venv\lib\site-packages\django\db\models\base.py", line 923, in _do_insert
    return manager._insert(
  File "C:\Users\amand\python-cordarme\drf-api\venv\lib\site-packages\django\db\models\manager.py", line 85, in manager_method
    return getattr(self.get_queryset(), name)(*args, **kwargs)
  File "C:\Users\amand\python-cordarme\drf-api\venv\lib\site-packages\django\db\models\query.py", line 1301, in _insert
    return query.get_compiler(using=using).execute_sql(returning_fields)
  File "C:\Users\amand\python-cordarme\drf-api\venv\lib\site-packages\django\db\models\sql\compiler.py", line 1441, in execute_sql
    cursor.execute(sql, params)
  File "C:\Users\amand\python-cordarme\drf-api\venv\lib\site-packages\django\db\backends\utils.py", line 99, in execute
    return super().execute(sql, params)
  File "C:\Users\amand\python-cordarme\drf-api\venv\lib\site-packages\django\db\backends\utils.py", line 67, in execute
    return self._execute_with_wrappers(sql, params, many=False, executor=self._execute)
  File "C:\Users\amand\python-cordarme\drf-api\venv\lib\site-packages\django\db\backends\utils.py", line 76, in _execute_with_wrappers
    return executor(sql, params, many, context)
  File "C:\Users\amand\python-cordarme\drf-api\venv\lib\site-packages\django\db\backends\utils.py", line 80, in _execute
    with self.db.wrap_database_errors:
  File "C:\Users\amand\python-cordarme\drf-api\venv\lib\site-packages\django\db\utils.py", line 90, in __exit__
    raise dj_exc_value.with_traceback(traceback) from exc_value
  File "C:\Users\amand\python-cordarme\drf-api\venv\lib\site-packages\django\db\backends\utils.py", line 85, in _execute
    return self.cursor.execute(sql, params)
  File "C:\Users\amand\python-cordarme\drf-api\venv\lib\site-packages\django\db\backends\sqlite3\base.py", line 416, in execute
    return Database.Cursor.execute(self, query, params)
django.db.utils.OperationalError: no such table: agenda_endereco
2022-05-25 17:21:16,187 django.request ERROR    Internal Server Error: /api/endereco/
Traceback (most recent call last):
  File "C:\Users\amand\python-cordarme\drf-api\venv\lib\site-packages\django\db\backends\utils.py", line 85, in _execute
    return self.cursor.execute(sql, params)
  File "C:\Users\amand\python-cordarme\drf-api\venv\lib\site-packages\django\db\backends\sqlite3\base.py", line 416, in execute
    return Database.Cursor.execute(self, query, params)
sqlite3.OperationalError: no such table: agenda_endereco

The above exception was the direct cause of the following exception:

Traceback (most recent call last):
  File "C:\Users\amand\python-cordarme\drf-api\venv\lib\site-packages\django\core\handlers\exception.py", line 47, in inner
    response = get_response(request)
  File "C:\Users\amand\python-cordarme\drf-api\venv\lib\site-packages\django\core\handlers\base.py", line 181, in _get_response
    response = wrapped_callback(request, *callback_args, **callback_kwargs)
  File "C:\Users\amand\python-cordarme\drf-api\venv\lib\site-packages\django\views\decorators\csrf.py", line 54, in wrapped_view
    return view_func(*args, **kwargs)
  File "C:\Users\amand\python-cordarme\drf-api\venv\lib\site-packages\django\views\generic\base.py", line 69, in view
    return self.dispatch(request, *args, **kwargs)
  File "C:\Users\amand\python-cordarme\drf-api\venv\lib\site-packages\rest_framework\views.py", line 509, in dispatch
    response = self.handle_exception(exc)
  File "C:\Users\amand\python-cordarme\drf-api\venv\lib\site-packages\rest_framework\views.py", line 469, in handle_exception
    self.raise_uncaught_exception(exc)
  File "C:\Users\amand\python-cordarme\drf-api\venv\lib\site-packages\rest_framework\views.py", line 480, in raise_uncaught_exception
    raise exc
  File "C:\Users\amand\python-cordarme\drf-api\venv\lib\site-packages\rest_framework\views.py", line 506, in dispatch
    response = handler(request, *args, **kwargs)
  File "C:\Users\amand\python-cordarme\drf-api\venv\lib\site-packages\rest_framework\generics.py", line 242, in post
    return self.create(request, *args, **kwargs)
  File "C:\Users\amand\python-cordarme\drf-api\venv\lib\site-packages\rest_framework\mixins.py", line 19, in create
    self.perform_create(serializer)
  File "C:\Users\amand\python-cordarme\drf-api\venv\lib\site-packages\rest_framework\mixins.py", line 24, in perform_create
    serializer.save()
  File "C:\Users\amand\python-cordarme\drf-api\venv\lib\site-packages\rest_framework\serializers.py", line 212, in save
    self.instance = self.create(validated_data)
  File "C:\Users\amand\python-cordarme\drf-api\venv\lib\site-packages\rest_framework\serializers.py", line 962, in create
    instance = ModelClass._default_manager.create(**validated_data)
  File "C:\Users\amand\python-cordarme\drf-api\venv\lib\site-packages\django\db\models\manager.py", line 85, in manager_method
    return getattr(self.get_queryset(), name)(*args, **kwargs)
  File "C:\Users\amand\python-cordarme\drf-api\venv\lib\site-packages\django\db\models\query.py", line 457, in create
    obj.save(force_insert=True, using=self.db)
  File "C:\Users\amand\python-cordarme\drf-api\venv\lib\site-packages\django\db\models\base.py", line 743, in save
    self.save_base(using=using, force_insert=force_insert,
  File "C:\Users\amand\python-cordarme\drf-api\venv\lib\site-packages\django\db\models\base.py", line 780, in save_base
    updated = self._save_table(
  File "C:\Users\amand\python-cordarme\drf-api\venv\lib\site-packages\django\db\models\base.py", line 885, in _save_table
    results = self._do_insert(cls._base_manager, using, fields, returning_fields, raw)
  File "C:\Users\amand\python-cordarme\drf-api\venv\lib\site-packages\django\db\models\base.py", line 923, in _do_insert
    return manager._insert(
  File "C:\Users\amand\python-cordarme\drf-api\venv\lib\site-packages\django\db\models\manager.py", line 85, in manager_method
    return getattr(self.get_queryset(), name)(*args, **kwargs)
  File "C:\Users\amand\python-cordarme\drf-api\venv\lib\site-packages\django\db\models\query.py", line 1301, in _insert
    return query.get_compiler(using=using).execute_sql(returning_fields)
  File "C:\Users\amand\python-cordarme\drf-api\venv\lib\site-packages\django\db\models\sql\compiler.py", line 1441, in execute_sql
    cursor.execute(sql, params)
  File "C:\Users\amand\python-cordarme\drf-api\venv\lib\site-packages\django\db\backends\utils.py", line 99, in execute
    return super().execute(sql, params)
  File "C:\Users\amand\python-cordarme\drf-api\venv\lib\site-packages\django\db\backends\utils.py", line 67, in execute
    return self._execute_with_wrappers(sql, params, many=False, executor=self._execute)
  File "C:\Users\amand\python-cordarme\drf-api\venv\lib\site-packages\django\db\backends\utils.py", line 76, in _execute_with_wrappers
    return executor(sql, params, many, context)
  File "C:\Users\amand\python-cordarme\drf-api\venv\lib\site-packages\django\db\backends\utils.py", line 80, in _execute
    with self.db.wrap_database_errors:
  File "C:\Users\amand\python-cordarme\drf-api\venv\lib\site-packages\django\db\utils.py", line 90, in __exit__
    raise dj_exc_value.with_traceback(traceback) from exc_value
  File "C:\Users\amand\python-cordarme\drf-api\venv\lib\site-packages\django\db\backends\utils.py", line 85, in _execute
    return self.cursor.execute(sql, params)
  File "C:\Users\amand\python-cordarme\drf-api\venv\lib\site-packages\django\db\backends\sqlite3\base.py", line 416, in execute
    return Database.Cursor.execute(self, query, params)
django.db.utils.OperationalError: no such table: agenda_endereco
2022-05-25 17:22:31,809 django.utils.autoreload INFO     C:\Users\amand\python-cordarme\drf-api\agenda\serializers.py changed, reloading.
2022-05-25 17:22:33,286 django.utils.autoreload INFO     Watching for file changes with StatReloader
2022-05-25 22:38:33,833 django.utils.autoreload INFO     C:\Users\amand\python-cordarme\drf-api\agenda\serializers.py changed, reloading.
2022-05-25 22:38:35,037 django.utils.autoreload INFO     Watching for file changes with StatReloader
2022-05-25 22:38:37,625 django.utils.autoreload INFO     C:\Users\amand\python-cordarme\drf-api\agenda\models.py changed, reloading.
2022-05-25 22:38:39,815 django.utils.autoreload INFO     Watching for file changes with StatReloader
2022-05-26 12:13:19,874 django.utils.autoreload INFO     Watching for file changes with StatReloader
2022-05-26 12:13:50,865 django.request ERROR    Internal Server Error: /api/endereco/
Traceback (most recent call last):
  File "C:\Users\amand\python-cordarme\drf-api\venv\lib\site-packages\django\core\handlers\exception.py", line 47, in inner
    response = get_response(request)
  File "C:\Users\amand\python-cordarme\drf-api\venv\lib\site-packages\django\core\handlers\base.py", line 181, in _get_response
    response = wrapped_callback(request, *callback_args, **callback_kwargs)
  File "C:\Users\amand\python-cordarme\drf-api\venv\lib\site-packages\django\views\decorators\csrf.py", line 54, in wrapped_view
    return view_func(*args, **kwargs)
  File "C:\Users\amand\python-cordarme\drf-api\venv\lib\site-packages\django\views\generic\base.py", line 69, in view
    return self.dispatch(request, *args, **kwargs)
  File "C:\Users\amand\python-cordarme\drf-api\venv\lib\site-packages\rest_framework\views.py", line 509, in dispatch
    response = self.handle_exception(exc)
  File "C:\Users\amand\python-cordarme\drf-api\venv\lib\site-packages\rest_framework\views.py", line 469, in handle_exception
    self.raise_uncaught_exception(exc)
  File "C:\Users\amand\python-cordarme\drf-api\venv\lib\site-packages\rest_framework\views.py", line 480, in raise_uncaught_exception
    raise exc
  File "C:\Users\amand\python-cordarme\drf-api\venv\lib\site-packages\rest_framework\views.py", line 506, in dispatch
    response = handler(request, *args, **kwargs)
  File "C:\Users\amand\python-cordarme\drf-api\venv\lib\site-packages\rest_framework\generics.py", line 242, in post
    return self.create(request, *args, **kwargs)
  File "C:\Users\amand\python-cordarme\drf-api\venv\lib\site-packages\rest_framework\mixins.py", line 18, in create
    serializer.is_valid(raise_exception=True)
  File "C:\Users\amand\python-cordarme\drf-api\venv\lib\site-packages\rest_framework\serializers.py", line 227, in is_valid
    self._validated_data = self.run_validation(self.initial_data)
  File "C:\Users\amand\python-cordarme\drf-api\venv\lib\site-packages\rest_framework\serializers.py", line 426, in run_validation
    value = self.to_internal_value(data)
  File "C:\Users\amand\python-cordarme\drf-api\venv\lib\site-packages\rest_framework\serializers.py", line 485, in to_internal_value
    validated_value = validate_method(validated_value)
  File "C:\Users\amand\python-cordarme\drf-api\agenda\serializers.py", line 249, in validate_cep
    if value != verifica_cep:
UnboundLocalError: local variable 'verifica_cep' referenced before assignment
2022-05-26 12:14:35,997 django.utils.autoreload INFO     C:\Users\amand\python-cordarme\drf-api\agenda\serializers.py changed, reloading.
2022-05-26 12:14:36,876 django.utils.autoreload INFO     Watching for file changes with StatReloader
2022-05-26 12:14:44,111 django.request ERROR    Internal Server Error: /api/endereco/
Traceback (most recent call last):
  File "C:\Users\amand\python-cordarme\drf-api\venv\lib\site-packages\django\core\handlers\exception.py", line 47, in inner
    response = get_response(request)
  File "C:\Users\amand\python-cordarme\drf-api\venv\lib\site-packages\django\core\handlers\base.py", line 181, in _get_response
    response = wrapped_callback(request, *callback_args, **callback_kwargs)
  File "C:\Users\amand\python-cordarme\drf-api\venv\lib\site-packages\django\views\decorators\csrf.py", line 54, in wrapped_view
    return view_func(*args, **kwargs)
  File "C:\Users\amand\python-cordarme\drf-api\venv\lib\site-packages\django\views\generic\base.py", line 69, in view
    return self.dispatch(request, *args, **kwargs)
  File "C:\Users\amand\python-cordarme\drf-api\venv\lib\site-packages\rest_framework\views.py", line 509, in dispatch
    response = self.handle_exception(exc)
  File "C:\Users\amand\python-cordarme\drf-api\venv\lib\site-packages\rest_framework\views.py", line 469, in handle_exception
    self.raise_uncaught_exception(exc)
  File "C:\Users\amand\python-cordarme\drf-api\venv\lib\site-packages\rest_framework\views.py", line 480, in raise_uncaught_exception
    raise exc
  File "C:\Users\amand\python-cordarme\drf-api\venv\lib\site-packages\rest_framework\views.py", line 506, in dispatch
    response = handler(request, *args, **kwargs)
  File "C:\Users\amand\python-cordarme\drf-api\venv\lib\site-packages\rest_framework\generics.py", line 242, in post
    return self.create(request, *args, **kwargs)
  File "C:\Users\amand\python-cordarme\drf-api\venv\lib\site-packages\rest_framework\mixins.py", line 18, in create
    serializer.is_valid(raise_exception=True)
  File "C:\Users\amand\python-cordarme\drf-api\venv\lib\site-packages\rest_framework\serializers.py", line 227, in is_valid
    self._validated_data = self.run_validation(self.initial_data)
  File "C:\Users\amand\python-cordarme\drf-api\venv\lib\site-packages\rest_framework\serializers.py", line 426, in run_validation
    value = self.to_internal_value(data)
  File "C:\Users\amand\python-cordarme\drf-api\venv\lib\site-packages\rest_framework\serializers.py", line 485, in to_internal_value
    validated_value = validate_method(validated_value)
  File "C:\Users\amand\python-cordarme\drf-api\agenda\serializers.py", line 249, in validate_cep
    if value != verifica_caracteres:
UnboundLocalError: local variable 'verifica_caracteres' referenced before assignment
2022-05-26 12:15:05,000 django.utils.autoreload INFO     C:\Users\amand\python-cordarme\drf-api\agenda\serializers.py changed, reloading.
2022-05-26 12:15:06,587 django.utils.autoreload INFO     Watching for file changes with StatReloader
2022-05-26 12:15:08,834 root         INFO     Fazendo requisição para BrasilAPI com o CEP: 82710080
2022-05-26 12:15:08,863 urllib3.connectionpool DEBUG    Starting new HTTPS connection (1): brasilapi.com.br:443
2022-05-26 12:15:10,313 urllib3.connectionpool DEBUG    https://brasilapi.com.br:443 "GET /api/cep/v2/82710080 HTTP/1.1" 200 None
2022-05-26 12:15:10,561 django.request ERROR    Internal Server Error: /api/endereco/
Traceback (most recent call last):
  File "C:\Users\amand\python-cordarme\drf-api\venv\lib\site-packages\django\db\backends\utils.py", line 85, in _execute
    return self.cursor.execute(sql, params)
  File "C:\Users\amand\python-cordarme\drf-api\venv\lib\site-packages\django\db\backends\sqlite3\base.py", line 416, in execute
    return Database.Cursor.execute(self, query, params)
sqlite3.OperationalError: no such table: agenda_endereco

The above exception was the direct cause of the following exception:

Traceback (most recent call last):
  File "C:\Users\amand\python-cordarme\drf-api\venv\lib\site-packages\django\core\handlers\exception.py", line 47, in inner
    response = get_response(request)
  File "C:\Users\amand\python-cordarme\drf-api\venv\lib\site-packages\django\core\handlers\base.py", line 181, in _get_response
    response = wrapped_callback(request, *callback_args, **callback_kwargs)
  File "C:\Users\amand\python-cordarme\drf-api\venv\lib\site-packages\django\views\decorators\csrf.py", line 54, in wrapped_view
    return view_func(*args, **kwargs)
  File "C:\Users\amand\python-cordarme\drf-api\venv\lib\site-packages\django\views\generic\base.py", line 69, in view
    return self.dispatch(request, *args, **kwargs)
  File "C:\Users\amand\python-cordarme\drf-api\venv\lib\site-packages\rest_framework\views.py", line 509, in dispatch
    response = self.handle_exception(exc)
  File "C:\Users\amand\python-cordarme\drf-api\venv\lib\site-packages\rest_framework\views.py", line 469, in handle_exception
    self.raise_uncaught_exception(exc)
  File "C:\Users\amand\python-cordarme\drf-api\venv\lib\site-packages\rest_framework\views.py", line 480, in raise_uncaught_exception
    raise exc
  File "C:\Users\amand\python-cordarme\drf-api\venv\lib\site-packages\rest_framework\views.py", line 506, in dispatch
    response = handler(request, *args, **kwargs)
  File "C:\Users\amand\python-cordarme\drf-api\venv\lib\site-packages\rest_framework\generics.py", line 242, in post
    return self.create(request, *args, **kwargs)
  File "C:\Users\amand\python-cordarme\drf-api\venv\lib\site-packages\rest_framework\mixins.py", line 19, in create
    self.perform_create(serializer)
  File "C:\Users\amand\python-cordarme\drf-api\venv\lib\site-packages\rest_framework\mixins.py", line 24, in perform_create
    serializer.save()
  File "C:\Users\amand\python-cordarme\drf-api\venv\lib\site-packages\rest_framework\serializers.py", line 212, in save
    self.instance = self.create(validated_data)
  File "C:\Users\amand\python-cordarme\drf-api\venv\lib\site-packages\rest_framework\serializers.py", line 962, in create
    instance = ModelClass._default_manager.create(**validated_data)
  File "C:\Users\amand\python-cordarme\drf-api\venv\lib\site-packages\django\db\models\manager.py", line 85, in manager_method
    return getattr(self.get_queryset(), name)(*args, **kwargs)
  File "C:\Users\amand\python-cordarme\drf-api\venv\lib\site-packages\django\db\models\query.py", line 457, in create
    obj.save(force_insert=True, using=self.db)
  File "C:\Users\amand\python-cordarme\drf-api\venv\lib\site-packages\django\db\models\base.py", line 743, in save
    self.save_base(using=using, force_insert=force_insert,
  File "C:\Users\amand\python-cordarme\drf-api\venv\lib\site-packages\django\db\models\base.py", line 780, in save_base
    updated = self._save_table(
  File "C:\Users\amand\python-cordarme\drf-api\venv\lib\site-packages\django\db\models\base.py", line 885, in _save_table
    results = self._do_insert(cls._base_manager, using, fields, returning_fields, raw)
  File "C:\Users\amand\python-cordarme\drf-api\venv\lib\site-packages\django\db\models\base.py", line 923, in _do_insert
    return manager._insert(
  File "C:\Users\amand\python-cordarme\drf-api\venv\lib\site-packages\django\db\models\manager.py", line 85, in manager_method
    return getattr(self.get_queryset(), name)(*args, **kwargs)
  File "C:\Users\amand\python-cordarme\drf-api\venv\lib\site-packages\django\db\models\query.py", line 1301, in _insert
    return query.get_compiler(using=using).execute_sql(returning_fields)
  File "C:\Users\amand\python-cordarme\drf-api\venv\lib\site-packages\django\db\models\sql\compiler.py", line 1441, in execute_sql
    cursor.execute(sql, params)
  File "C:\Users\amand\python-cordarme\drf-api\venv\lib\site-packages\django\db\backends\utils.py", line 99, in execute
    return super().execute(sql, params)
  File "C:\Users\amand\python-cordarme\drf-api\venv\lib\site-packages\django\db\backends\utils.py", line 67, in execute
    return self._execute_with_wrappers(sql, params, many=False, executor=self._execute)
  File "C:\Users\amand\python-cordarme\drf-api\venv\lib\site-packages\django\db\backends\utils.py", line 76, in _execute_with_wrappers
    return executor(sql, params, many, context)
  File "C:\Users\amand\python-cordarme\drf-api\venv\lib\site-packages\django\db\backends\utils.py", line 80, in _execute
    with self.db.wrap_database_errors:
  File "C:\Users\amand\python-cordarme\drf-api\venv\lib\site-packages\django\db\utils.py", line 90, in __exit__
    raise dj_exc_value.with_traceback(traceback) from exc_value
  File "C:\Users\amand\python-cordarme\drf-api\venv\lib\site-packages\django\db\backends\utils.py", line 85, in _execute
    return self.cursor.execute(sql, params)
  File "C:\Users\amand\python-cordarme\drf-api\venv\lib\site-packages\django\db\backends\sqlite3\base.py", line 416, in execute
    return Database.Cursor.execute(self, query, params)
django.db.utils.OperationalError: no such table: agenda_endereco
2022-05-26 12:17:11,785 root         INFO     Fazendo requisição para BrasilAPI com o CEP: 82710080
2022-05-26 12:17:11,788 urllib3.connectionpool DEBUG    Starting new HTTPS connection (1): brasilapi.com.br:443
2022-05-26 12:17:11,938 urllib3.connectionpool DEBUG    https://brasilapi.com.br:443 "GET /api/cep/v2/82710080 HTTP/1.1" 200 None
2022-05-26 12:17:27,405 django.request WARNING  Bad Request: /api/endereco/
2022-05-26 12:17:56,060 root         INFO     Fazendo requisição para BrasilAPI com o CEP: 82710099
2022-05-26 12:17:56,063 urllib3.connectionpool DEBUG    Starting new HTTPS connection (1): brasilapi.com.br:443
2022-05-26 12:18:18,205 urllib3.connectionpool DEBUG    https://brasilapi.com.br:443 "GET /api/cep/v2/82710099 HTTP/1.1" 404 None
2022-05-26 12:18:18,207 root         ERROR    Algum erro ocorreu na Brasil API
2022-05-26 12:18:18,211 django.request WARNING  Bad Request: /api/endereco/
2022-05-26 12:20:24,424 django.utils.autoreload INFO     C:\Users\amand\python-cordarme\drf-api\agenda\models.py changed, reloading.
2022-05-26 12:20:25,301 django.utils.autoreload INFO     Watching for file changes with StatReloader
2022-05-26 12:24:28,951 django.utils.autoreload INFO     C:\Users\amand\python-cordarme\drf-api\agenda\serializers.py changed, reloading.
2022-05-26 12:24:29,951 django.utils.autoreload INFO     Watching for file changes with StatReloader
2022-05-26 12:24:31,986 django.utils.autoreload INFO     C:\Users\amand\python-cordarme\drf-api\agenda\serializers.py changed, reloading.
2022-05-26 12:24:32,880 django.utils.autoreload INFO     Watching for file changes with StatReloader
2022-05-26 12:24:40,306 django.utils.autoreload INFO     C:\Users\amand\python-cordarme\drf-api\agenda\serializers.py changed, reloading.
2022-05-26 12:24:41,096 django.utils.autoreload INFO     Watching for file changes with StatReloader
2022-05-26 12:25:17,327 django.utils.autoreload INFO     C:\Users\amand\python-cordarme\drf-api\agenda\serializers.py changed, reloading.
2022-05-26 12:25:18,132 django.utils.autoreload INFO     Watching for file changes with StatReloader
2022-05-26 12:25:41,420 django.utils.autoreload INFO     C:\Users\amand\python-cordarme\drf-api\agenda\serializers.py changed, reloading.
2022-05-26 12:25:42,566 django.utils.autoreload INFO     Watching for file changes with StatReloader
2022-05-26 12:26:03,769 django.utils.autoreload INFO     C:\Users\amand\python-cordarme\drf-api\agenda\serializers.py changed, reloading.
2022-05-26 12:26:05,124 django.utils.autoreload INFO     Watching for file changes with StatReloader
2022-05-26 12:26:07,741 root         INFO     Fazendo requisição para BrasilAPI com o CEP: 82710099
2022-05-26 12:26:07,747 urllib3.connectionpool DEBUG    Starting new HTTPS connection (1): brasilapi.com.br:443
2022-05-26 12:26:07,942 urllib3.connectionpool DEBUG    https://brasilapi.com.br:443 "GET /api/cep/v2/82710099 HTTP/1.1" 404 None
2022-05-26 12:26:07,944 root         ERROR    Algum erro ocorreu na Brasil API
2022-05-26 12:26:07,946 django.request WARNING  Bad Request: /api/endereco/
2022-05-26 12:26:22,991 root         INFO     Fazendo requisição para BrasilAPI com o CEP: 82710099
2022-05-26 12:26:22,998 urllib3.connectionpool DEBUG    Starting new HTTPS connection (1): brasilapi.com.br:443
2022-05-26 12:26:23,170 urllib3.connectionpool DEBUG    https://brasilapi.com.br:443 "GET /api/cep/v2/82710099 HTTP/1.1" 404 None
2022-05-26 12:26:23,173 root         ERROR    Algum erro ocorreu na Brasil API
2022-05-26 12:26:23,174 django.request WARNING  Bad Request: /api/endereco/
2022-05-26 12:26:29,914 root         INFO     Fazendo requisição para BrasilAPI com o CEP: 82710099
2022-05-26 12:26:29,916 urllib3.connectionpool DEBUG    Starting new HTTPS connection (1): brasilapi.com.br:443
2022-05-26 12:26:30,046 urllib3.connectionpool DEBUG    https://brasilapi.com.br:443 "GET /api/cep/v2/82710099 HTTP/1.1" 404 None
2022-05-26 12:26:30,054 root         ERROR    Algum erro ocorreu na Brasil API
2022-05-26 12:26:30,056 django.request WARNING  Bad Request: /api/endereco/
2022-05-26 12:26:40,993 django.utils.autoreload INFO     C:\Users\amand\python-cordarme\drf-api\agenda\serializers.py changed, reloading.
2022-05-26 12:26:41,902 django.utils.autoreload INFO     Watching for file changes with StatReloader
2022-05-26 12:26:50,173 root         INFO     Fazendo requisição para BrasilAPI com o CEP: 82710099
2022-05-26 12:26:50,179 urllib3.connectionpool DEBUG    Starting new HTTPS connection (1): brasilapi.com.br:443
2022-05-26 12:26:50,333 urllib3.connectionpool DEBUG    https://brasilapi.com.br:443 "GET /api/cep/v2/82710099 HTTP/1.1" 404 None
2022-05-26 12:26:50,339 root         ERROR    Algum erro ocorreu na Brasil API
2022-05-26 12:26:50,341 django.request WARNING  Bad Request: /api/endereco/
2022-05-26 12:27:09,972 django.utils.autoreload INFO     C:\Users\amand\python-cordarme\drf-api\agenda\serializers.py changed, reloading.
2022-05-26 12:27:10,826 django.utils.autoreload INFO     Watching for file changes with StatReloader
2022-05-26 12:27:13,916 root         INFO     Fazendo requisição para BrasilAPI com o CEP: 82710099
2022-05-26 12:27:13,924 urllib3.connectionpool DEBUG    Starting new HTTPS connection (1): brasilapi.com.br:443
2022-05-26 12:27:35,128 urllib3.connectionpool DEBUG    https://brasilapi.com.br:443 "GET /api/cep/v2/82710099 HTTP/1.1" 404 None
2022-05-26 12:27:35,130 root         ERROR    Algum erro ocorreu na Brasil API
2022-05-26 12:27:35,132 django.request WARNING  Bad Request: /api/endereco/
2022-05-26 12:27:42,486 root         INFO     Fazendo requisição para BrasilAPI com o CEP: 82710099
2022-05-26 12:27:42,490 urllib3.connectionpool DEBUG    Starting new HTTPS connection (1): brasilapi.com.br:443
2022-05-26 12:27:42,683 urllib3.connectionpool DEBUG    https://brasilapi.com.br:443 "GET /api/cep/v2/82710099 HTTP/1.1" 404 None
2022-05-26 12:27:42,688 root         ERROR    Algum erro ocorreu na Brasil API
2022-05-26 12:27:42,690 django.request WARNING  Bad Request: /api/endereco/
2022-05-26 12:29:00,513 django.utils.autoreload INFO     C:\Users\amand\python-cordarme\drf-api\agenda\serializers.py changed, reloading.
2022-05-26 12:29:01,467 django.utils.autoreload INFO     Watching for file changes with StatReloader
2022-05-26 12:29:06,705 django.utils.autoreload INFO     C:\Users\amand\python-cordarme\drf-api\agenda\serializers.py changed, reloading.
2022-05-26 12:29:07,518 django.utils.autoreload INFO     Watching for file changes with StatReloader
2022-05-26 12:30:50,513 django.utils.autoreload INFO     C:\Users\amand\python-cordarme\drf-api\agenda\serializers.py changed, reloading.
2022-05-26 12:30:51,355 django.utils.autoreload INFO     Watching for file changes with StatReloader
2022-05-26 12:36:18,755 django.utils.autoreload INFO     C:\Users\amand\python-cordarme\drf-api\agenda\serializers.py changed, reloading.
2022-05-26 12:36:19,790 django.utils.autoreload INFO     Watching for file changes with StatReloader
2022-05-26 12:38:16,944 django.utils.autoreload INFO     C:\Users\amand\python-cordarme\drf-api\agenda\serializers.py changed, reloading.
2022-05-26 12:38:18,212 django.utils.autoreload INFO     Watching for file changes with StatReloader
2022-05-26 12:40:18,247 django.utils.autoreload INFO     C:\Users\amand\python-cordarme\drf-api\agenda\serializers.py changed, reloading.
2022-05-26 12:40:19,123 django.utils.autoreload INFO     Watching for file changes with StatReloader
2022-05-26 12:42:03,785 django.utils.autoreload INFO     C:\Users\amand\python-cordarme\drf-api\agenda\serializers.py changed, reloading.
2022-05-26 12:42:04,711 django.utils.autoreload INFO     Watching for file changes with StatReloader
2022-05-26 12:42:34,292 django.utils.autoreload INFO     C:\Users\amand\python-cordarme\drf-api\agenda\serializers.py changed, reloading.
2022-05-26 12:42:35,223 django.utils.autoreload INFO     Watching for file changes with StatReloader
2022-05-26 12:42:46,964 root         INFO     Fazendo requisição para BrasilAPI com o CEP: 82710099
2022-05-26 12:42:46,970 urllib3.connectionpool DEBUG    Starting new HTTPS connection (1): brasilapi.com.br:443
2022-05-26 12:42:47,130 urllib3.connectionpool DEBUG    https://brasilapi.com.br:443 "GET /api/cep/v2/82710099 HTTP/1.1" 404 None
2022-05-26 12:42:47,134 root         ERROR    Algum erro ocorreu na Brasil API
2022-05-26 12:42:47,136 django.request WARNING  Bad Request: /api/endereco/
2022-05-26 12:43:05,511 root         INFO     Fazendo requisição para BrasilAPI com o CEP: 82710080
2022-05-26 12:43:05,515 urllib3.connectionpool DEBUG    Starting new HTTPS connection (1): brasilapi.com.br:443
2022-05-26 12:43:05,629 urllib3.connectionpool DEBUG    https://brasilapi.com.br:443 "GET /api/cep/v2/82710080 HTTP/1.1" 200 None
2022-05-26 12:43:05,632 root         INFO     Fazendo requisição para BrasilAPI com o CEP: 82710080
2022-05-26 12:43:05,638 urllib3.connectionpool DEBUG    Starting new HTTPS connection (1): brasilapi.com.br:443
2022-05-26 12:43:05,797 urllib3.connectionpool DEBUG    https://brasilapi.com.br:443 "GET /api/cep/v2/82710080 HTTP/1.1" 200 None
2022-05-26 12:43:05,874 django.request ERROR    Internal Server Error: /api/endereco/
Traceback (most recent call last):
  File "C:\Users\amand\python-cordarme\drf-api\venv\lib\site-packages\django\core\handlers\exception.py", line 47, in inner
    response = get_response(request)
  File "C:\Users\amand\python-cordarme\drf-api\venv\lib\site-packages\django\core\handlers\base.py", line 181, in _get_response
    response = wrapped_callback(request, *callback_args, **callback_kwargs)
  File "C:\Users\amand\python-cordarme\drf-api\venv\lib\site-packages\django\views\decorators\csrf.py", line 54, in wrapped_view
    return view_func(*args, **kwargs)
  File "C:\Users\amand\python-cordarme\drf-api\venv\lib\site-packages\django\views\generic\base.py", line 69, in view
    return self.dispatch(request, *args, **kwargs)
  File "C:\Users\amand\python-cordarme\drf-api\venv\lib\site-packages\rest_framework\views.py", line 509, in dispatch
    response = self.handle_exception(exc)
  File "C:\Users\amand\python-cordarme\drf-api\venv\lib\site-packages\rest_framework\views.py", line 469, in handle_exception
    self.raise_uncaught_exception(exc)
  File "C:\Users\amand\python-cordarme\drf-api\venv\lib\site-packages\rest_framework\views.py", line 480, in raise_uncaught_exception
    raise exc
  File "C:\Users\amand\python-cordarme\drf-api\venv\lib\site-packages\rest_framework\views.py", line 506, in dispatch
    response = handler(request, *args, **kwargs)
  File "C:\Users\amand\python-cordarme\drf-api\venv\lib\site-packages\rest_framework\generics.py", line 242, in post
    return self.create(request, *args, **kwargs)
  File "C:\Users\amand\python-cordarme\drf-api\venv\lib\site-packages\rest_framework\mixins.py", line 18, in create
    serializer.is_valid(raise_exception=True)
  File "C:\Users\amand\python-cordarme\drf-api\venv\lib\site-packages\rest_framework\serializers.py", line 227, in is_valid
    self._validated_data = self.run_validation(self.initial_data)
  File "C:\Users\amand\python-cordarme\drf-api\venv\lib\site-packages\rest_framework\serializers.py", line 429, in run_validation
    value = self.validate(value)
  File "C:\Users\amand\python-cordarme\drf-api\agenda\serializers.py", line 318, in validate
    verifica_estado = verifica_valores["estado"]
KeyError: 'estado'
2022-05-26 12:44:19,093 django.utils.autoreload INFO     C:\Users\amand\python-cordarme\drf-api\agenda\serializers.py changed, reloading.
2022-05-26 12:44:20,015 django.utils.autoreload INFO     Watching for file changes with StatReloader
2022-05-26 12:47:59,486 django.utils.autoreload INFO     C:\Users\amand\python-cordarme\drf-api\agenda\serializers.py changed, reloading.
2022-05-26 12:48:00,507 django.utils.autoreload INFO     Watching for file changes with StatReloader
2022-05-26 12:48:06,221 root         INFO     Fazendo requisição para BrasilAPI com o CEP: 82710080
2022-05-26 12:48:06,227 urllib3.connectionpool DEBUG    Starting new HTTPS connection (1): brasilapi.com.br:443
2022-05-26 12:48:27,486 urllib3.connectionpool DEBUG    https://brasilapi.com.br:443 "GET /api/cep/v2/82710080 HTTP/1.1" 200 None
2022-05-26 12:48:27,488 root         INFO     Fazendo requisição para BrasilAPI com o CEP: 82710080
2022-05-26 12:48:27,492 urllib3.connectionpool DEBUG    Starting new HTTPS connection (1): brasilapi.com.br:443
2022-05-26 12:48:27,630 urllib3.connectionpool DEBUG    https://brasilapi.com.br:443 "GET /api/cep/v2/82710080 HTTP/1.1" 200 None
2022-05-26 12:48:27,723 django.request ERROR    Internal Server Error: /api/endereco/
Traceback (most recent call last):
  File "C:\Users\amand\python-cordarme\drf-api\venv\lib\site-packages\django\db\backends\utils.py", line 85, in _execute
    return self.cursor.execute(sql, params)
  File "C:\Users\amand\python-cordarme\drf-api\venv\lib\site-packages\django\db\backends\sqlite3\base.py", line 416, in execute
    return Database.Cursor.execute(self, query, params)
sqlite3.IntegrityError: NOT NULL constraint failed: agenda_endereco.cidade

The above exception was the direct cause of the following exception:

Traceback (most recent call last):
  File "C:\Users\amand\python-cordarme\drf-api\venv\lib\site-packages\django\core\handlers\exception.py", line 47, in inner
    response = get_response(request)
  File "C:\Users\amand\python-cordarme\drf-api\venv\lib\site-packages\django\core\handlers\base.py", line 181, in _get_response
    response = wrapped_callback(request, *callback_args, **callback_kwargs)
  File "C:\Users\amand\python-cordarme\drf-api\venv\lib\site-packages\django\views\decorators\csrf.py", line 54, in wrapped_view
    return view_func(*args, **kwargs)
  File "C:\Users\amand\python-cordarme\drf-api\venv\lib\site-packages\django\views\generic\base.py", line 69, in view
    return self.dispatch(request, *args, **kwargs)
  File "C:\Users\amand\python-cordarme\drf-api\venv\lib\site-packages\rest_framework\views.py", line 509, in dispatch
    response = self.handle_exception(exc)
  File "C:\Users\amand\python-cordarme\drf-api\venv\lib\site-packages\rest_framework\views.py", line 469, in handle_exception
    self.raise_uncaught_exception(exc)
  File "C:\Users\amand\python-cordarme\drf-api\venv\lib\site-packages\rest_framework\views.py", line 480, in raise_uncaught_exception
    raise exc
  File "C:\Users\amand\python-cordarme\drf-api\venv\lib\site-packages\rest_framework\views.py", line 506, in dispatch
    response = handler(request, *args, **kwargs)
  File "C:\Users\amand\python-cordarme\drf-api\venv\lib\site-packages\rest_framework\generics.py", line 242, in post
    return self.create(request, *args, **kwargs)
  File "C:\Users\amand\python-cordarme\drf-api\venv\lib\site-packages\rest_framework\mixins.py", line 19, in create
    self.perform_create(serializer)
  File "C:\Users\amand\python-cordarme\drf-api\venv\lib\site-packages\rest_framework\mixins.py", line 24, in perform_create
    serializer.save()
  File "C:\Users\amand\python-cordarme\drf-api\venv\lib\site-packages\rest_framework\serializers.py", line 212, in save
    self.instance = self.create(validated_data)
  File "C:\Users\amand\python-cordarme\drf-api\venv\lib\site-packages\rest_framework\serializers.py", line 962, in create
    instance = ModelClass._default_manager.create(**validated_data)
  File "C:\Users\amand\python-cordarme\drf-api\venv\lib\site-packages\django\db\models\manager.py", line 85, in manager_method
    return getattr(self.get_queryset(), name)(*args, **kwargs)
  File "C:\Users\amand\python-cordarme\drf-api\venv\lib\site-packages\django\db\models\query.py", line 457, in create
    obj.save(force_insert=True, using=self.db)
  File "C:\Users\amand\python-cordarme\drf-api\venv\lib\site-packages\django\db\models\base.py", line 743, in save
    self.save_base(using=using, force_insert=force_insert,
  File "C:\Users\amand\python-cordarme\drf-api\venv\lib\site-packages\django\db\models\base.py", line 780, in save_base
    updated = self._save_table(
  File "C:\Users\amand\python-cordarme\drf-api\venv\lib\site-packages\django\db\models\base.py", line 885, in _save_table
    results = self._do_insert(cls._base_manager, using, fields, returning_fields, raw)
  File "C:\Users\amand\python-cordarme\drf-api\venv\lib\site-packages\django\db\models\base.py", line 923, in _do_insert
    return manager._insert(
  File "C:\Users\amand\python-cordarme\drf-api\venv\lib\site-packages\django\db\models\manager.py", line 85, in manager_method
    return getattr(self.get_queryset(), name)(*args, **kwargs)
  File "C:\Users\amand\python-cordarme\drf-api\venv\lib\site-packages\django\db\models\query.py", line 1301, in _insert
    return query.get_compiler(using=using).execute_sql(returning_fields)
  File "C:\Users\amand\python-cordarme\drf-api\venv\lib\site-packages\django\db\models\sql\compiler.py", line 1441, in execute_sql
    cursor.execute(sql, params)
  File "C:\Users\amand\python-cordarme\drf-api\venv\lib\site-packages\django\db\backends\utils.py", line 99, in execute
    return super().execute(sql, params)
  File "C:\Users\amand\python-cordarme\drf-api\venv\lib\site-packages\django\db\backends\utils.py", line 67, in execute
    return self._execute_with_wrappers(sql, params, many=False, executor=self._execute)
  File "C:\Users\amand\python-cordarme\drf-api\venv\lib\site-packages\django\db\backends\utils.py", line 76, in _execute_with_wrappers
    return executor(sql, params, many, context)
  File "C:\Users\amand\python-cordarme\drf-api\venv\lib\site-packages\django\db\backends\utils.py", line 80, in _execute
    with self.db.wrap_database_errors:
  File "C:\Users\amand\python-cordarme\drf-api\venv\lib\site-packages\django\db\utils.py", line 90, in __exit__
    raise dj_exc_value.with_traceback(traceback) from exc_value
  File "C:\Users\amand\python-cordarme\drf-api\venv\lib\site-packages\django\db\backends\utils.py", line 85, in _execute
    return self.cursor.execute(sql, params)
  File "C:\Users\amand\python-cordarme\drf-api\venv\lib\site-packages\django\db\backends\sqlite3\base.py", line 416, in execute
    return Database.Cursor.execute(self, query, params)
django.db.utils.IntegrityError: NOT NULL constraint failed: agenda_endereco.cidade
2022-05-26 12:51:35,633 root         INFO     Fazendo requisição para BrasilAPI com o CEP: 82710080
2022-05-26 12:51:35,636 urllib3.connectionpool DEBUG    Starting new HTTPS connection (1): brasilapi.com.br:443
2022-05-26 12:51:35,805 urllib3.connectionpool DEBUG    https://brasilapi.com.br:443 "GET /api/cep/v2/82710080 HTTP/1.1" 200 None
2022-05-26 12:51:35,816 root         INFO     Fazendo requisição para BrasilAPI com o CEP: 82710080
2022-05-26 12:51:35,819 urllib3.connectionpool DEBUG    Starting new HTTPS connection (1): brasilapi.com.br:443
2022-05-26 12:51:35,959 urllib3.connectionpool DEBUG    https://brasilapi.com.br:443 "GET /api/cep/v2/82710080 HTTP/1.1" 200 None
2022-05-26 12:51:36,067 django.request ERROR    Internal Server Error: /api/endereco/
Traceback (most recent call last):
  File "C:\Users\amand\python-cordarme\drf-api\venv\lib\site-packages\django\db\backends\utils.py", line 85, in _execute
    return self.cursor.execute(sql, params)
  File "C:\Users\amand\python-cordarme\drf-api\venv\lib\site-packages\django\db\backends\sqlite3\base.py", line 416, in execute
    return Database.Cursor.execute(self, query, params)
sqlite3.IntegrityError: NOT NULL constraint failed: agenda_endereco.cidade

The above exception was the direct cause of the following exception:

Traceback (most recent call last):
  File "C:\Users\amand\python-cordarme\drf-api\venv\lib\site-packages\django\core\handlers\exception.py", line 47, in inner
    response = get_response(request)
  File "C:\Users\amand\python-cordarme\drf-api\venv\lib\site-packages\django\core\handlers\base.py", line 181, in _get_response
    response = wrapped_callback(request, *callback_args, **callback_kwargs)
  File "C:\Users\amand\python-cordarme\drf-api\venv\lib\site-packages\django\views\decorators\csrf.py", line 54, in wrapped_view
    return view_func(*args, **kwargs)
  File "C:\Users\amand\python-cordarme\drf-api\venv\lib\site-packages\django\views\generic\base.py", line 69, in view
    return self.dispatch(request, *args, **kwargs)
  File "C:\Users\amand\python-cordarme\drf-api\venv\lib\site-packages\rest_framework\views.py", line 509, in dispatch
    response = self.handle_exception(exc)
  File "C:\Users\amand\python-cordarme\drf-api\venv\lib\site-packages\rest_framework\views.py", line 469, in handle_exception
    self.raise_uncaught_exception(exc)
  File "C:\Users\amand\python-cordarme\drf-api\venv\lib\site-packages\rest_framework\views.py", line 480, in raise_uncaught_exception
    raise exc
  File "C:\Users\amand\python-cordarme\drf-api\venv\lib\site-packages\rest_framework\views.py", line 506, in dispatch
    response = handler(request, *args, **kwargs)
  File "C:\Users\amand\python-cordarme\drf-api\venv\lib\site-packages\rest_framework\generics.py", line 242, in post
    return self.create(request, *args, **kwargs)
  File "C:\Users\amand\python-cordarme\drf-api\venv\lib\site-packages\rest_framework\mixins.py", line 19, in create
    self.perform_create(serializer)
  File "C:\Users\amand\python-cordarme\drf-api\venv\lib\site-packages\rest_framework\mixins.py", line 24, in perform_create
    serializer.save()
  File "C:\Users\amand\python-cordarme\drf-api\venv\lib\site-packages\rest_framework\serializers.py", line 212, in save
    self.instance = self.create(validated_data)
  File "C:\Users\amand\python-cordarme\drf-api\venv\lib\site-packages\rest_framework\serializers.py", line 962, in create
    instance = ModelClass._default_manager.create(**validated_data)
  File "C:\Users\amand\python-cordarme\drf-api\venv\lib\site-packages\django\db\models\manager.py", line 85, in manager_method
    return getattr(self.get_queryset(), name)(*args, **kwargs)
  File "C:\Users\amand\python-cordarme\drf-api\venv\lib\site-packages\django\db\models\query.py", line 457, in create
    obj.save(force_insert=True, using=self.db)
  File "C:\Users\amand\python-cordarme\drf-api\venv\lib\site-packages\django\db\models\base.py", line 743, in save
    self.save_base(using=using, force_insert=force_insert,
  File "C:\Users\amand\python-cordarme\drf-api\venv\lib\site-packages\django\db\models\base.py", line 780, in save_base
    updated = self._save_table(
  File "C:\Users\amand\python-cordarme\drf-api\venv\lib\site-packages\django\db\models\base.py", line 885, in _save_table
    results = self._do_insert(cls._base_manager, using, fields, returning_fields, raw)
  File "C:\Users\amand\python-cordarme\drf-api\venv\lib\site-packages\django\db\models\base.py", line 923, in _do_insert
    return manager._insert(
  File "C:\Users\amand\python-cordarme\drf-api\venv\lib\site-packages\django\db\models\manager.py", line 85, in manager_method
    return getattr(self.get_queryset(), name)(*args, **kwargs)
  File "C:\Users\amand\python-cordarme\drf-api\venv\lib\site-packages\django\db\models\query.py", line 1301, in _insert
    return query.get_compiler(using=using).execute_sql(returning_fields)
  File "C:\Users\amand\python-cordarme\drf-api\venv\lib\site-packages\django\db\models\sql\compiler.py", line 1441, in execute_sql
    cursor.execute(sql, params)
  File "C:\Users\amand\python-cordarme\drf-api\venv\lib\site-packages\django\db\backends\utils.py", line 99, in execute
    return super().execute(sql, params)
  File "C:\Users\amand\python-cordarme\drf-api\venv\lib\site-packages\django\db\backends\utils.py", line 67, in execute
    return self._execute_with_wrappers(sql, params, many=False, executor=self._execute)
  File "C:\Users\amand\python-cordarme\drf-api\venv\lib\site-packages\django\db\backends\utils.py", line 76, in _execute_with_wrappers
    return executor(sql, params, many, context)
  File "C:\Users\amand\python-cordarme\drf-api\venv\lib\site-packages\django\db\backends\utils.py", line 80, in _execute
    with self.db.wrap_database_errors:
  File "C:\Users\amand\python-cordarme\drf-api\venv\lib\site-packages\django\db\utils.py", line 90, in __exit__
    raise dj_exc_value.with_traceback(traceback) from exc_value
  File "C:\Users\amand\python-cordarme\drf-api\venv\lib\site-packages\django\db\backends\utils.py", line 85, in _execute
    return self.cursor.execute(sql, params)
  File "C:\Users\amand\python-cordarme\drf-api\venv\lib\site-packages\django\db\backends\sqlite3\base.py", line 416, in execute
    return Database.Cursor.execute(self, query, params)
django.db.utils.IntegrityError: NOT NULL constraint failed: agenda_endereco.cidade
2022-05-26 12:51:44,186 root         INFO     Fazendo requisição para BrasilAPI com o CEP: 82710080
2022-05-26 12:51:44,189 urllib3.connectionpool DEBUG    Starting new HTTPS connection (1): brasilapi.com.br:443
2022-05-26 12:51:44,327 urllib3.connectionpool DEBUG    https://brasilapi.com.br:443 "GET /api/cep/v2/82710080 HTTP/1.1" 200 None
2022-05-26 12:51:44,331 root         INFO     Fazendo requisição para BrasilAPI com o CEP: 82710080
2022-05-26 12:51:44,334 urllib3.connectionpool DEBUG    Starting new HTTPS connection (1): brasilapi.com.br:443
2022-05-26 12:51:44,484 urllib3.connectionpool DEBUG    https://brasilapi.com.br:443 "GET /api/cep/v2/82710080 HTTP/1.1" 200 None
2022-05-26 12:51:44,586 django.request ERROR    Internal Server Error: /api/endereco/
Traceback (most recent call last):
  File "C:\Users\amand\python-cordarme\drf-api\venv\lib\site-packages\django\db\backends\utils.py", line 85, in _execute
    return self.cursor.execute(sql, params)
  File "C:\Users\amand\python-cordarme\drf-api\venv\lib\site-packages\django\db\backends\sqlite3\base.py", line 416, in execute
    return Database.Cursor.execute(self, query, params)
sqlite3.IntegrityError: NOT NULL constraint failed: agenda_endereco.cidade

The above exception was the direct cause of the following exception:

Traceback (most recent call last):
  File "C:\Users\amand\python-cordarme\drf-api\venv\lib\site-packages\django\core\handlers\exception.py", line 47, in inner
    response = get_response(request)
  File "C:\Users\amand\python-cordarme\drf-api\venv\lib\site-packages\django\core\handlers\base.py", line 181, in _get_response
    response = wrapped_callback(request, *callback_args, **callback_kwargs)
  File "C:\Users\amand\python-cordarme\drf-api\venv\lib\site-packages\django\views\decorators\csrf.py", line 54, in wrapped_view
    return view_func(*args, **kwargs)
  File "C:\Users\amand\python-cordarme\drf-api\venv\lib\site-packages\django\views\generic\base.py", line 69, in view
    return self.dispatch(request, *args, **kwargs)
  File "C:\Users\amand\python-cordarme\drf-api\venv\lib\site-packages\rest_framework\views.py", line 509, in dispatch
    response = self.handle_exception(exc)
  File "C:\Users\amand\python-cordarme\drf-api\venv\lib\site-packages\rest_framework\views.py", line 469, in handle_exception
    self.raise_uncaught_exception(exc)
  File "C:\Users\amand\python-cordarme\drf-api\venv\lib\site-packages\rest_framework\views.py", line 480, in raise_uncaught_exception
    raise exc
  File "C:\Users\amand\python-cordarme\drf-api\venv\lib\site-packages\rest_framework\views.py", line 506, in dispatch
    response = handler(request, *args, **kwargs)
  File "C:\Users\amand\python-cordarme\drf-api\venv\lib\site-packages\rest_framework\generics.py", line 242, in post
    return self.create(request, *args, **kwargs)
  File "C:\Users\amand\python-cordarme\drf-api\venv\lib\site-packages\rest_framework\mixins.py", line 19, in create
    self.perform_create(serializer)
  File "C:\Users\amand\python-cordarme\drf-api\venv\lib\site-packages\rest_framework\mixins.py", line 24, in perform_create
    serializer.save()
  File "C:\Users\amand\python-cordarme\drf-api\venv\lib\site-packages\rest_framework\serializers.py", line 212, in save
    self.instance = self.create(validated_data)
  File "C:\Users\amand\python-cordarme\drf-api\venv\lib\site-packages\rest_framework\serializers.py", line 962, in create
    instance = ModelClass._default_manager.create(**validated_data)
  File "C:\Users\amand\python-cordarme\drf-api\venv\lib\site-packages\django\db\models\manager.py", line 85, in manager_method
    return getattr(self.get_queryset(), name)(*args, **kwargs)
  File "C:\Users\amand\python-cordarme\drf-api\venv\lib\site-packages\django\db\models\query.py", line 457, in create
    obj.save(force_insert=True, using=self.db)
  File "C:\Users\amand\python-cordarme\drf-api\venv\lib\site-packages\django\db\models\base.py", line 743, in save
    self.save_base(using=using, force_insert=force_insert,
  File "C:\Users\amand\python-cordarme\drf-api\venv\lib\site-packages\django\db\models\base.py", line 780, in save_base
    updated = self._save_table(
  File "C:\Users\amand\python-cordarme\drf-api\venv\lib\site-packages\django\db\models\base.py", line 885, in _save_table
    results = self._do_insert(cls._base_manager, using, fields, returning_fields, raw)
  File "C:\Users\amand\python-cordarme\drf-api\venv\lib\site-packages\django\db\models\base.py", line 923, in _do_insert
    return manager._insert(
  File "C:\Users\amand\python-cordarme\drf-api\venv\lib\site-packages\django\db\models\manager.py", line 85, in manager_method
    return getattr(self.get_queryset(), name)(*args, **kwargs)
  File "C:\Users\amand\python-cordarme\drf-api\venv\lib\site-packages\django\db\models\query.py", line 1301, in _insert
    return query.get_compiler(using=using).execute_sql(returning_fields)
  File "C:\Users\amand\python-cordarme\drf-api\venv\lib\site-packages\django\db\models\sql\compiler.py", line 1441, in execute_sql
    cursor.execute(sql, params)
  File "C:\Users\amand\python-cordarme\drf-api\venv\lib\site-packages\django\db\backends\utils.py", line 99, in execute
    return super().execute(sql, params)
  File "C:\Users\amand\python-cordarme\drf-api\venv\lib\site-packages\django\db\backends\utils.py", line 67, in execute
    return self._execute_with_wrappers(sql, params, many=False, executor=self._execute)
  File "C:\Users\amand\python-cordarme\drf-api\venv\lib\site-packages\django\db\backends\utils.py", line 76, in _execute_with_wrappers
    return executor(sql, params, many, context)
  File "C:\Users\amand\python-cordarme\drf-api\venv\lib\site-packages\django\db\backends\utils.py", line 80, in _execute
    with self.db.wrap_database_errors:
  File "C:\Users\amand\python-cordarme\drf-api\venv\lib\site-packages\django\db\utils.py", line 90, in __exit__
    raise dj_exc_value.with_traceback(traceback) from exc_value
  File "C:\Users\amand\python-cordarme\drf-api\venv\lib\site-packages\django\db\backends\utils.py", line 85, in _execute
    return self.cursor.execute(sql, params)
  File "C:\Users\amand\python-cordarme\drf-api\venv\lib\site-packages\django\db\backends\sqlite3\base.py", line 416, in execute
    return Database.Cursor.execute(self, query, params)
django.db.utils.IntegrityError: NOT NULL constraint failed: agenda_endereco.cidade
2022-05-26 12:55:47,954 django.utils.autoreload INFO     C:\Users\amand\python-cordarme\drf-api\agenda\serializers.py changed, reloading.
2022-05-26 12:55:49,004 django.utils.autoreload INFO     Watching for file changes with StatReloader
2022-05-26 12:55:51,081 root         INFO     Fazendo requisição para BrasilAPI com o CEP: 82710080
2022-05-26 12:55:51,088 urllib3.connectionpool DEBUG    Starting new HTTPS connection (1): brasilapi.com.br:443
2022-05-26 12:55:51,270 urllib3.connectionpool DEBUG    https://brasilapi.com.br:443 "GET /api/cep/v2/82710080 HTTP/1.1" 200 None
2022-05-26 12:55:51,280 root         INFO     Fazendo requisição para BrasilAPI com o CEP: 82710080
2022-05-26 12:55:51,283 urllib3.connectionpool DEBUG    Starting new HTTPS connection (1): brasilapi.com.br:443
2022-05-26 12:55:51,428 urllib3.connectionpool DEBUG    https://brasilapi.com.br:443 "GET /api/cep/v2/82710080 HTTP/1.1" 200 None
2022-05-26 12:55:51,515 django.request ERROR    Internal Server Error: /api/endereco/
Traceback (most recent call last):
  File "C:\Users\amand\python-cordarme\drf-api\venv\lib\site-packages\django\db\backends\utils.py", line 85, in _execute
    return self.cursor.execute(sql, params)
  File "C:\Users\amand\python-cordarme\drf-api\venv\lib\site-packages\django\db\backends\sqlite3\base.py", line 416, in execute
    return Database.Cursor.execute(self, query, params)
sqlite3.IntegrityError: NOT NULL constraint failed: agenda_endereco.bairro

The above exception was the direct cause of the following exception:

Traceback (most recent call last):
  File "C:\Users\amand\python-cordarme\drf-api\venv\lib\site-packages\django\core\handlers\exception.py", line 47, in inner
    response = get_response(request)
  File "C:\Users\amand\python-cordarme\drf-api\venv\lib\site-packages\django\core\handlers\base.py", line 181, in _get_response
    response = wrapped_callback(request, *callback_args, **callback_kwargs)
  File "C:\Users\amand\python-cordarme\drf-api\venv\lib\site-packages\django\views\decorators\csrf.py", line 54, in wrapped_view
    return view_func(*args, **kwargs)
  File "C:\Users\amand\python-cordarme\drf-api\venv\lib\site-packages\django\views\generic\base.py", line 69, in view
    return self.dispatch(request, *args, **kwargs)
  File "C:\Users\amand\python-cordarme\drf-api\venv\lib\site-packages\rest_framework\views.py", line 509, in dispatch
    response = self.handle_exception(exc)
  File "C:\Users\amand\python-cordarme\drf-api\venv\lib\site-packages\rest_framework\views.py", line 469, in handle_exception
    self.raise_uncaught_exception(exc)
  File "C:\Users\amand\python-cordarme\drf-api\venv\lib\site-packages\rest_framework\views.py", line 480, in raise_uncaught_exception
    raise exc
  File "C:\Users\amand\python-cordarme\drf-api\venv\lib\site-packages\rest_framework\views.py", line 506, in dispatch
    response = handler(request, *args, **kwargs)
  File "C:\Users\amand\python-cordarme\drf-api\venv\lib\site-packages\rest_framework\generics.py", line 242, in post
    return self.create(request, *args, **kwargs)
  File "C:\Users\amand\python-cordarme\drf-api\venv\lib\site-packages\rest_framework\mixins.py", line 19, in create
    self.perform_create(serializer)
  File "C:\Users\amand\python-cordarme\drf-api\venv\lib\site-packages\rest_framework\mixins.py", line 24, in perform_create
    serializer.save()
  File "C:\Users\amand\python-cordarme\drf-api\venv\lib\site-packages\rest_framework\serializers.py", line 212, in save
    self.instance = self.create(validated_data)
  File "C:\Users\amand\python-cordarme\drf-api\venv\lib\site-packages\rest_framework\serializers.py", line 962, in create
    instance = ModelClass._default_manager.create(**validated_data)
  File "C:\Users\amand\python-cordarme\drf-api\venv\lib\site-packages\django\db\models\manager.py", line 85, in manager_method
    return getattr(self.get_queryset(), name)(*args, **kwargs)
  File "C:\Users\amand\python-cordarme\drf-api\venv\lib\site-packages\django\db\models\query.py", line 457, in create
    obj.save(force_insert=True, using=self.db)
  File "C:\Users\amand\python-cordarme\drf-api\venv\lib\site-packages\django\db\models\base.py", line 743, in save
    self.save_base(using=using, force_insert=force_insert,
  File "C:\Users\amand\python-cordarme\drf-api\venv\lib\site-packages\django\db\models\base.py", line 780, in save_base
    updated = self._save_table(
  File "C:\Users\amand\python-cordarme\drf-api\venv\lib\site-packages\django\db\models\base.py", line 885, in _save_table
    results = self._do_insert(cls._base_manager, using, fields, returning_fields, raw)
  File "C:\Users\amand\python-cordarme\drf-api\venv\lib\site-packages\django\db\models\base.py", line 923, in _do_insert
    return manager._insert(
  File "C:\Users\amand\python-cordarme\drf-api\venv\lib\site-packages\django\db\models\manager.py", line 85, in manager_method
    return getattr(self.get_queryset(), name)(*args, **kwargs)
  File "C:\Users\amand\python-cordarme\drf-api\venv\lib\site-packages\django\db\models\query.py", line 1301, in _insert
    return query.get_compiler(using=using).execute_sql(returning_fields)
  File "C:\Users\amand\python-cordarme\drf-api\venv\lib\site-packages\django\db\models\sql\compiler.py", line 1441, in execute_sql
    cursor.execute(sql, params)
  File "C:\Users\amand\python-cordarme\drf-api\venv\lib\site-packages\django\db\backends\utils.py", line 99, in execute
    return super().execute(sql, params)
  File "C:\Users\amand\python-cordarme\drf-api\venv\lib\site-packages\django\db\backends\utils.py", line 67, in execute
    return self._execute_with_wrappers(sql, params, many=False, executor=self._execute)
  File "C:\Users\amand\python-cordarme\drf-api\venv\lib\site-packages\django\db\backends\utils.py", line 76, in _execute_with_wrappers
    return executor(sql, params, many, context)
  File "C:\Users\amand\python-cordarme\drf-api\venv\lib\site-packages\django\db\backends\utils.py", line 80, in _execute
    with self.db.wrap_database_errors:
  File "C:\Users\amand\python-cordarme\drf-api\venv\lib\site-packages\django\db\utils.py", line 90, in __exit__
    raise dj_exc_value.with_traceback(traceback) from exc_value
  File "C:\Users\amand\python-cordarme\drf-api\venv\lib\site-packages\django\db\backends\utils.py", line 85, in _execute
    return self.cursor.execute(sql, params)
  File "C:\Users\amand\python-cordarme\drf-api\venv\lib\site-packages\django\db\backends\sqlite3\base.py", line 416, in execute
    return Database.Cursor.execute(self, query, params)
django.db.utils.IntegrityError: NOT NULL constraint failed: agenda_endereco.bairro
2022-05-26 12:56:16,412 django.utils.autoreload INFO     C:\Users\amand\python-cordarme\drf-api\agenda\serializers.py changed, reloading.
2022-05-26 12:56:17,448 django.utils.autoreload INFO     Watching for file changes with StatReloader
2022-05-26 12:56:33,522 root         INFO     Fazendo requisição para BrasilAPI com o CEP: 82710080
2022-05-26 12:56:33,531 urllib3.connectionpool DEBUG    Starting new HTTPS connection (1): brasilapi.com.br:443
2022-05-26 12:56:33,699 urllib3.connectionpool DEBUG    https://brasilapi.com.br:443 "GET /api/cep/v2/82710080 HTTP/1.1" 200 None
2022-05-26 12:56:33,703 root         INFO     Fazendo requisição para BrasilAPI com o CEP: 82710080
2022-05-26 12:56:33,707 urllib3.connectionpool DEBUG    Starting new HTTPS connection (1): brasilapi.com.br:443
2022-05-26 12:56:33,850 urllib3.connectionpool DEBUG    https://brasilapi.com.br:443 "GET /api/cep/v2/82710080 HTTP/1.1" 200 None
2022-05-26 12:56:33,854 root         WARNING  Bairro informado não coincide com o CEP!
2022-05-26 12:56:33,855 root         WARNING  Rua informada não coincide com o CEP!
2022-05-26 12:56:55,394 root         INFO     Fazendo requisição para BrasilAPI com o CEP: 82710080
2022-05-26 12:56:55,397 urllib3.connectionpool DEBUG    Starting new HTTPS connection (1): brasilapi.com.br:443
2022-05-26 12:57:16,598 urllib3.connectionpool DEBUG    https://brasilapi.com.br:443 "GET /api/cep/v2/82710080 HTTP/1.1" 200 None
2022-05-26 12:57:16,604 root         INFO     Fazendo requisição para BrasilAPI com o CEP: 82710080
2022-05-26 12:57:16,607 urllib3.connectionpool DEBUG    Starting new HTTPS connection (1): brasilapi.com.br:443
2022-05-26 12:57:16,769 urllib3.connectionpool DEBUG    https://brasilapi.com.br:443 "GET /api/cep/v2/82710080 HTTP/1.1" 200 None
2022-05-26 12:57:16,773 root         WARNING  Rua informada não coincide com o CEP!
2022-05-26 12:58:51,921 django.utils.autoreload INFO     C:\Users\amand\python-cordarme\drf-api\agenda\utils.py changed, reloading.
2022-05-26 12:58:53,025 django.utils.autoreload INFO     Watching for file changes with StatReloader
2022-06-09 11:37:13,193 django.utils.autoreload INFO     Watching for file changes with StatReloader
2022-06-09 12:04:25,528 asyncio      DEBUG    Using proactor: IocpProactor
2022-06-09 12:04:26,007 asyncio      DEBUG    Using proactor: IocpProactor
2022-06-09 12:08:53,196 django.utils.autoreload INFO     C:\Users\amand\python-cordarme\drf-api\agenda\views.py changed, reloading.
2022-06-09 12:08:54,121 django.utils.autoreload INFO     Watching for file changes with StatReloader
2022-06-09 12:12:55,726 django.utils.autoreload INFO     C:\Users\amand\python-cordarme\drf-api\agenda\views.py changed, reloading.
2022-06-09 12:12:56,601 django.utils.autoreload INFO     Watching for file changes with StatReloader
2022-06-09 12:13:06,486 django.utils.autoreload INFO     C:\Users\amand\python-cordarme\drf-api\agenda\views.py changed, reloading.
2022-06-09 12:13:07,281 django.utils.autoreload INFO     Watching for file changes with StatReloader
2022-06-09 12:13:15,987 django.utils.autoreload INFO     C:\Users\amand\python-cordarme\drf-api\agenda\views.py changed, reloading.
2022-06-09 12:13:16,789 django.utils.autoreload INFO     Watching for file changes with StatReloader
2022-06-09 12:13:34,171 django.utils.autoreload INFO     Watching for file changes with StatReloader
2022-06-09 12:14:17,505 django.request WARNING  Not Found: /api/users/
2022-06-09 12:14:25,871 django.request WARNING  Not Found: /api/users/
2022-06-09 12:14:32,265 django.utils.autoreload INFO     C:\Users\amand\python-cordarme\drf-api\agenda\urls.py changed, reloading.
2022-06-09 12:14:32,691 django.utils.autoreload INFO     C:\Users\amand\python-cordarme\drf-api\agenda\urls.py changed, reloading.
2022-06-09 12:14:33,354 django.utils.autoreload INFO     Watching for file changes with StatReloader
2022-06-09 12:14:33,934 django.utils.autoreload INFO     Watching for file changes with StatReloader
2022-06-09 12:14:36,116 django.request WARNING  Forbidden: /api/users/
2022-06-09 12:14:52,706 django.request WARNING  Forbidden: /api/users/
2022-06-09 12:15:03,359 django.request ERROR    Internal Server Error: /api/users/
Traceback (most recent call last):
  File "C:\Users\amand\python-cordarme\drf-api\venv\lib\site-packages\django\core\handlers\exception.py", line 47, in inner
    response = get_response(request)
  File "C:\Users\amand\python-cordarme\drf-api\venv\lib\site-packages\django\core\handlers\base.py", line 181, in _get_response
    response = wrapped_callback(request, *callback_args, **callback_kwargs)
  File "C:\Users\amand\python-cordarme\drf-api\venv\lib\site-packages\django\views\decorators\csrf.py", line 54, in wrapped_view
    return view_func(*args, **kwargs)
  File "C:\Users\amand\python-cordarme\drf-api\venv\lib\site-packages\django\views\generic\base.py", line 69, in view
    return self.dispatch(request, *args, **kwargs)
  File "C:\Users\amand\python-cordarme\drf-api\venv\lib\site-packages\rest_framework\views.py", line 509, in dispatch
    response = self.handle_exception(exc)
  File "C:\Users\amand\python-cordarme\drf-api\venv\lib\site-packages\rest_framework\views.py", line 469, in handle_exception
    self.raise_uncaught_exception(exc)
  File "C:\Users\amand\python-cordarme\drf-api\venv\lib\site-packages\rest_framework\views.py", line 480, in raise_uncaught_exception
    raise exc
  File "C:\Users\amand\python-cordarme\drf-api\venv\lib\site-packages\rest_framework\views.py", line 506, in dispatch
    response = handler(request, *args, **kwargs)
  File "C:\Users\amand\python-cordarme\drf-api\venv\lib\site-packages\rest_framework\decorators.py", line 50, in handler
    return func(*args, **kwargs)
  File "C:\Users\amand\python-cordarme\drf-api\agenda\views.py", line 247, in users
    qs = users.objects.all()
AttributeError: 'function' object has no attribute 'objects'
2022-06-09 12:15:07,149 django.request ERROR    Internal Server Error: /api/users/
Traceback (most recent call last):
  File "C:\Users\amand\python-cordarme\drf-api\venv\lib\site-packages\django\core\handlers\exception.py", line 47, in inner
    response = get_response(request)
  File "C:\Users\amand\python-cordarme\drf-api\venv\lib\site-packages\django\core\handlers\base.py", line 181, in _get_response
    response = wrapped_callback(request, *callback_args, **callback_kwargs)
  File "C:\Users\amand\python-cordarme\drf-api\venv\lib\site-packages\django\views\decorators\csrf.py", line 54, in wrapped_view
    return view_func(*args, **kwargs)
  File "C:\Users\amand\python-cordarme\drf-api\venv\lib\site-packages\django\views\generic\base.py", line 69, in view
    return self.dispatch(request, *args, **kwargs)
  File "C:\Users\amand\python-cordarme\drf-api\venv\lib\site-packages\rest_framework\views.py", line 509, in dispatch
    response = self.handle_exception(exc)
  File "C:\Users\amand\python-cordarme\drf-api\venv\lib\site-packages\rest_framework\views.py", line 469, in handle_exception
    self.raise_uncaught_exception(exc)
  File "C:\Users\amand\python-cordarme\drf-api\venv\lib\site-packages\rest_framework\views.py", line 480, in raise_uncaught_exception
    raise exc
  File "C:\Users\amand\python-cordarme\drf-api\venv\lib\site-packages\rest_framework\views.py", line 506, in dispatch
    response = handler(request, *args, **kwargs)
  File "C:\Users\amand\python-cordarme\drf-api\venv\lib\site-packages\rest_framework\decorators.py", line 50, in handler
    return func(*args, **kwargs)
  File "C:\Users\amand\python-cordarme\drf-api\agenda\views.py", line 247, in users
    qs = users.objects.all()
AttributeError: 'function' object has no attribute 'objects'
2022-06-09 12:15:35,813 django.utils.autoreload INFO     C:\Users\amand\python-cordarme\drf-api\agenda\views.py changed, reloading.
2022-06-09 12:15:35,841 django.utils.autoreload INFO     C:\Users\amand\python-cordarme\drf-api\agenda\views.py changed, reloading.
2022-06-09 12:15:36,725 django.utils.autoreload INFO     Watching for file changes with StatReloader
2022-06-09 12:15:36,753 django.utils.autoreload INFO     Watching for file changes with StatReloader
2022-06-09 12:15:41,099 django.request ERROR    Internal Server Error: /api/users/
Traceback (most recent call last):
  File "C:\Users\amand\python-cordarme\drf-api\venv\lib\site-packages\django\core\handlers\exception.py", line 47, in inner
    response = get_response(request)
  File "C:\Users\amand\python-cordarme\drf-api\venv\lib\site-packages\django\core\handlers\base.py", line 181, in _get_response
    response = wrapped_callback(request, *callback_args, **callback_kwargs)
  File "C:\Users\amand\python-cordarme\drf-api\venv\lib\site-packages\django\views\decorators\csrf.py", line 54, in wrapped_view
    return view_func(*args, **kwargs)
  File "C:\Users\amand\python-cordarme\drf-api\venv\lib\site-packages\django\views\generic\base.py", line 69, in view
    return self.dispatch(request, *args, **kwargs)
  File "C:\Users\amand\python-cordarme\drf-api\venv\lib\site-packages\rest_framework\views.py", line 509, in dispatch
    response = self.handle_exception(exc)
  File "C:\Users\amand\python-cordarme\drf-api\venv\lib\site-packages\rest_framework\views.py", line 469, in handle_exception
    self.raise_uncaught_exception(exc)
  File "C:\Users\amand\python-cordarme\drf-api\venv\lib\site-packages\rest_framework\views.py", line 480, in raise_uncaught_exception
    raise exc
  File "C:\Users\amand\python-cordarme\drf-api\venv\lib\site-packages\rest_framework\views.py", line 506, in dispatch
    response = handler(request, *args, **kwargs)
  File "C:\Users\amand\python-cordarme\drf-api\venv\lib\site-packages\rest_framework\decorators.py", line 50, in handler
    return func(*args, **kwargs)
  File "C:\Users\amand\python-cordarme\drf-api\agenda\views.py", line 255, in users
    return JsonResponse(users_list)
  File "C:\Users\amand\python-cordarme\drf-api\venv\lib\site-packages\django\http\response.py", line 599, in __init__
    raise TypeError(
TypeError: In order to allow non-dict objects to be serialized set the safe parameter to False.
2022-06-09 12:15:46,782 django.request ERROR    Internal Server Error: /api/users/
Traceback (most recent call last):
  File "C:\Users\amand\python-cordarme\drf-api\venv\lib\site-packages\django\core\handlers\exception.py", line 47, in inner
    response = get_response(request)
  File "C:\Users\amand\python-cordarme\drf-api\venv\lib\site-packages\django\core\handlers\base.py", line 181, in _get_response
    response = wrapped_callback(request, *callback_args, **callback_kwargs)
  File "C:\Users\amand\python-cordarme\drf-api\venv\lib\site-packages\django\views\decorators\csrf.py", line 54, in wrapped_view
    return view_func(*args, **kwargs)
  File "C:\Users\amand\python-cordarme\drf-api\venv\lib\site-packages\django\views\generic\base.py", line 69, in view
    return self.dispatch(request, *args, **kwargs)
  File "C:\Users\amand\python-cordarme\drf-api\venv\lib\site-packages\rest_framework\views.py", line 509, in dispatch
    response = self.handle_exception(exc)
  File "C:\Users\amand\python-cordarme\drf-api\venv\lib\site-packages\rest_framework\views.py", line 469, in handle_exception
    self.raise_uncaught_exception(exc)
  File "C:\Users\amand\python-cordarme\drf-api\venv\lib\site-packages\rest_framework\views.py", line 480, in raise_uncaught_exception
    raise exc
  File "C:\Users\amand\python-cordarme\drf-api\venv\lib\site-packages\rest_framework\views.py", line 506, in dispatch
    response = handler(request, *args, **kwargs)
  File "C:\Users\amand\python-cordarme\drf-api\venv\lib\site-packages\rest_framework\decorators.py", line 50, in handler
    return func(*args, **kwargs)
  File "C:\Users\amand\python-cordarme\drf-api\agenda\views.py", line 255, in users
    return JsonResponse(users_list)
  File "C:\Users\amand\python-cordarme\drf-api\venv\lib\site-packages\django\http\response.py", line 599, in __init__
    raise TypeError(
TypeError: In order to allow non-dict objects to be serialized set the safe parameter to False.
2022-06-09 12:16:03,377 django.request ERROR    Internal Server Error: /api/users/
Traceback (most recent call last):
  File "C:\Users\amand\python-cordarme\drf-api\venv\lib\site-packages\django\core\handlers\exception.py", line 47, in inner
    response = get_response(request)
  File "C:\Users\amand\python-cordarme\drf-api\venv\lib\site-packages\django\core\handlers\base.py", line 181, in _get_response
    response = wrapped_callback(request, *callback_args, **callback_kwargs)
  File "C:\Users\amand\python-cordarme\drf-api\venv\lib\site-packages\django\views\decorators\csrf.py", line 54, in wrapped_view
    return view_func(*args, **kwargs)
  File "C:\Users\amand\python-cordarme\drf-api\venv\lib\site-packages\django\views\generic\base.py", line 69, in view
    return self.dispatch(request, *args, **kwargs)
  File "C:\Users\amand\python-cordarme\drf-api\venv\lib\site-packages\rest_framework\views.py", line 509, in dispatch
    response = self.handle_exception(exc)
  File "C:\Users\amand\python-cordarme\drf-api\venv\lib\site-packages\rest_framework\views.py", line 469, in handle_exception
    self.raise_uncaught_exception(exc)
  File "C:\Users\amand\python-cordarme\drf-api\venv\lib\site-packages\rest_framework\views.py", line 480, in raise_uncaught_exception
    raise exc
  File "C:\Users\amand\python-cordarme\drf-api\venv\lib\site-packages\rest_framework\views.py", line 506, in dispatch
    response = handler(request, *args, **kwargs)
  File "C:\Users\amand\python-cordarme\drf-api\venv\lib\site-packages\rest_framework\decorators.py", line 50, in handler
    return func(*args, **kwargs)
  File "C:\Users\amand\python-cordarme\drf-api\agenda\views.py", line 255, in users
    return JsonResponse(users_list)
  File "C:\Users\amand\python-cordarme\drf-api\venv\lib\site-packages\django\http\response.py", line 599, in __init__
    raise TypeError(
TypeError: In order to allow non-dict objects to be serialized set the safe parameter to False.
2022-06-09 12:16:10,929 django.request ERROR    Internal Server Error: /api/users/
Traceback (most recent call last):
  File "C:\Users\amand\python-cordarme\drf-api\venv\lib\site-packages\django\core\handlers\exception.py", line 47, in inner
    response = get_response(request)
  File "C:\Users\amand\python-cordarme\drf-api\venv\lib\site-packages\django\core\handlers\base.py", line 181, in _get_response
    response = wrapped_callback(request, *callback_args, **callback_kwargs)
  File "C:\Users\amand\python-cordarme\drf-api\venv\lib\site-packages\django\views\decorators\csrf.py", line 54, in wrapped_view
    return view_func(*args, **kwargs)
  File "C:\Users\amand\python-cordarme\drf-api\venv\lib\site-packages\django\views\generic\base.py", line 69, in view
    return self.dispatch(request, *args, **kwargs)
  File "C:\Users\amand\python-cordarme\drf-api\venv\lib\site-packages\rest_framework\views.py", line 509, in dispatch
    response = self.handle_exception(exc)
  File "C:\Users\amand\python-cordarme\drf-api\venv\lib\site-packages\rest_framework\views.py", line 469, in handle_exception
    self.raise_uncaught_exception(exc)
  File "C:\Users\amand\python-cordarme\drf-api\venv\lib\site-packages\rest_framework\views.py", line 480, in raise_uncaught_exception
    raise exc
  File "C:\Users\amand\python-cordarme\drf-api\venv\lib\site-packages\rest_framework\views.py", line 506, in dispatch
    response = handler(request, *args, **kwargs)
  File "C:\Users\amand\python-cordarme\drf-api\venv\lib\site-packages\rest_framework\decorators.py", line 50, in handler
    return func(*args, **kwargs)
  File "C:\Users\amand\python-cordarme\drf-api\agenda\views.py", line 255, in users
    return JsonResponse(users_list)
  File "C:\Users\amand\python-cordarme\drf-api\venv\lib\site-packages\django\http\response.py", line 599, in __init__
    raise TypeError(
TypeError: In order to allow non-dict objects to be serialized set the safe parameter to False.
2022-06-09 12:16:14,875 django.request WARNING  Forbidden: /api/users/
2022-06-09 12:16:22,608 django.request ERROR    Internal Server Error: /api/users/
Traceback (most recent call last):
  File "C:\Users\amand\python-cordarme\drf-api\venv\lib\site-packages\django\core\handlers\exception.py", line 47, in inner
    response = get_response(request)
  File "C:\Users\amand\python-cordarme\drf-api\venv\lib\site-packages\django\core\handlers\base.py", line 181, in _get_response
    response = wrapped_callback(request, *callback_args, **callback_kwargs)
  File "C:\Users\amand\python-cordarme\drf-api\venv\lib\site-packages\django\views\decorators\csrf.py", line 54, in wrapped_view
    return view_func(*args, **kwargs)
  File "C:\Users\amand\python-cordarme\drf-api\venv\lib\site-packages\django\views\generic\base.py", line 69, in view
    return self.dispatch(request, *args, **kwargs)
  File "C:\Users\amand\python-cordarme\drf-api\venv\lib\site-packages\rest_framework\views.py", line 509, in dispatch
    response = self.handle_exception(exc)
  File "C:\Users\amand\python-cordarme\drf-api\venv\lib\site-packages\rest_framework\views.py", line 469, in handle_exception
    self.raise_uncaught_exception(exc)
  File "C:\Users\amand\python-cordarme\drf-api\venv\lib\site-packages\rest_framework\views.py", line 480, in raise_uncaught_exception
    raise exc
  File "C:\Users\amand\python-cordarme\drf-api\venv\lib\site-packages\rest_framework\views.py", line 506, in dispatch
    response = handler(request, *args, **kwargs)
  File "C:\Users\amand\python-cordarme\drf-api\venv\lib\site-packages\rest_framework\decorators.py", line 50, in handler
    return func(*args, **kwargs)
  File "C:\Users\amand\python-cordarme\drf-api\agenda\views.py", line 255, in users
    return JsonResponse(users_list)
  File "C:\Users\amand\python-cordarme\drf-api\venv\lib\site-packages\django\http\response.py", line 599, in __init__
    raise TypeError(
TypeError: In order to allow non-dict objects to be serialized set the safe parameter to False.
2022-06-09 12:17:11,319 django.utils.autoreload INFO     C:\Users\amand\python-cordarme\drf-api\agenda\views.py changed, reloading.
2022-06-09 12:17:11,803 django.utils.autoreload INFO     C:\Users\amand\python-cordarme\drf-api\agenda\views.py changed, reloading.
2022-06-09 12:17:12,446 django.utils.autoreload INFO     Watching for file changes with StatReloader
2022-06-09 12:17:12,843 django.utils.autoreload INFO     Watching for file changes with StatReloader
2022-06-09 12:19:45,428 django.utils.autoreload INFO     C:\Users\amand\python-cordarme\drf-api\agenda\views.py changed, reloading.
2022-06-09 12:19:45,468 django.utils.autoreload INFO     C:\Users\amand\python-cordarme\drf-api\agenda\views.py changed, reloading.
2022-06-09 12:19:46,369 django.utils.autoreload INFO     Watching for file changes with StatReloader
2022-06-09 12:19:46,391 django.utils.autoreload INFO     Watching for file changes with StatReloader
2022-06-09 12:20:30,254 django.utils.autoreload INFO     C:\Users\amand\python-cordarme\drf-api\agenda\views.py changed, reloading.
2022-06-09 12:20:30,271 django.utils.autoreload INFO     C:\Users\amand\python-cordarme\drf-api\agenda\views.py changed, reloading.
2022-06-09 12:20:31,303 django.utils.autoreload INFO     Watching for file changes with StatReloader
2022-06-09 12:20:31,305 django.utils.autoreload INFO     Watching for file changes with StatReloader
2022-06-09 12:20:42,684 django.utils.autoreload INFO     C:\Users\amand\python-cordarme\drf-api\agenda\views.py changed, reloading.
2022-06-09 12:20:43,018 django.utils.autoreload INFO     C:\Users\amand\python-cordarme\drf-api\agenda\views.py changed, reloading.
2022-06-09 12:20:43,670 django.utils.autoreload INFO     Watching for file changes with StatReloader
2022-06-09 12:20:43,962 django.utils.autoreload INFO     Watching for file changes with StatReloader
2022-06-09 12:28:30,290 django.utils.autoreload INFO     C:\Users\amand\python-cordarme\drf-api\agenda\views.py changed, reloading.
2022-06-09 12:28:31,112 django.utils.autoreload INFO     Watching for file changes with StatReloader
2022-06-09 12:28:31,167 django.utils.autoreload INFO     C:\Users\amand\python-cordarme\drf-api\agenda\views.py changed, reloading.
2022-06-09 12:28:32,019 django.utils.autoreload INFO     Watching for file changes with StatReloader
2022-06-09 12:30:38,750 django.utils.autoreload INFO     C:\Users\amand\python-cordarme\drf-api\agenda\views.py changed, reloading.
2022-06-09 12:30:38,861 django.utils.autoreload INFO     C:\Users\amand\python-cordarme\drf-api\agenda\views.py changed, reloading.
2022-06-09 12:30:39,577 django.utils.autoreload INFO     Watching for file changes with StatReloader
2022-06-09 12:30:39,700 django.utils.autoreload INFO     Watching for file changes with StatReloader
2022-06-09 12:31:22,619 django.utils.autoreload INFO     C:\Users\amand\python-cordarme\drf-api\agenda\views.py changed, reloading.
2022-06-09 12:31:22,970 django.utils.autoreload INFO     C:\Users\amand\python-cordarme\drf-api\agenda\views.py changed, reloading.
2022-06-09 12:31:23,687 django.utils.autoreload INFO     Watching for file changes with StatReloader
2022-06-09 12:31:23,978 django.utils.autoreload INFO     Watching for file changes with StatReloader
2022-06-09 12:31:34,072 django.request ERROR    Internal Server Error: /api/users/
Traceback (most recent call last):
  File "C:\Users\amand\python-cordarme\drf-api\venv\lib\site-packages\django\db\backends\utils.py", line 85, in _execute
    return self.cursor.execute(sql, params)
  File "C:\Users\amand\python-cordarme\drf-api\venv\lib\site-packages\django\db\backends\sqlite3\base.py", line 416, in execute
    return Database.Cursor.execute(self, query, params)
sqlite3.IntegrityError: UNIQUE constraint failed: auth_user.username

The above exception was the direct cause of the following exception:

Traceback (most recent call last):
  File "C:\Users\amand\python-cordarme\drf-api\venv\lib\site-packages\django\core\handlers\exception.py", line 47, in inner
    response = get_response(request)
  File "C:\Users\amand\python-cordarme\drf-api\venv\lib\site-packages\django\core\handlers\base.py", line 181, in _get_response
    response = wrapped_callback(request, *callback_args, **callback_kwargs)
  File "C:\Users\amand\python-cordarme\drf-api\venv\lib\site-packages\django\views\decorators\csrf.py", line 54, in wrapped_view
    return view_func(*args, **kwargs)
  File "C:\Users\amand\python-cordarme\drf-api\venv\lib\site-packages\django\views\generic\base.py", line 69, in view
    return self.dispatch(request, *args, **kwargs)
  File "C:\Users\amand\python-cordarme\drf-api\venv\lib\site-packages\rest_framework\views.py", line 509, in dispatch
    response = self.handle_exception(exc)
  File "C:\Users\amand\python-cordarme\drf-api\venv\lib\site-packages\rest_framework\views.py", line 469, in handle_exception
    self.raise_uncaught_exception(exc)
  File "C:\Users\amand\python-cordarme\drf-api\venv\lib\site-packages\rest_framework\views.py", line 480, in raise_uncaught_exception
    raise exc
  File "C:\Users\amand\python-cordarme\drf-api\venv\lib\site-packages\rest_framework\views.py", line 506, in dispatch
    response = handler(request, *args, **kwargs)
  File "C:\Users\amand\python-cordarme\drf-api\venv\lib\site-packages\rest_framework\decorators.py", line 50, in handler
    return func(*args, **kwargs)
  File "C:\Users\amand\python-cordarme\drf-api\agenda\views.py", line 233, in users
    user_obj = User.objects.create_user(
  File "C:\Users\amand\python-cordarme\drf-api\venv\lib\site-packages\django\contrib\auth\models.py", line 152, in create_user
    return self._create_user(username, email, password, **extra_fields)
  File "C:\Users\amand\python-cordarme\drf-api\venv\lib\site-packages\django\contrib\auth\models.py", line 146, in _create_user
    user.save(using=self._db)
  File "C:\Users\amand\python-cordarme\drf-api\venv\lib\site-packages\django\contrib\auth\base_user.py", line 66, in save
    super().save(*args, **kwargs)
  File "C:\Users\amand\python-cordarme\drf-api\venv\lib\site-packages\django\db\models\base.py", line 743, in save
    self.save_base(using=using, force_insert=force_insert,
  File "C:\Users\amand\python-cordarme\drf-api\venv\lib\site-packages\django\db\models\base.py", line 780, in save_base
    updated = self._save_table(
  File "C:\Users\amand\python-cordarme\drf-api\venv\lib\site-packages\django\db\models\base.py", line 885, in _save_table
    results = self._do_insert(cls._base_manager, using, fields, returning_fields, raw)
  File "C:\Users\amand\python-cordarme\drf-api\venv\lib\site-packages\django\db\models\base.py", line 923, in _do_insert
    return manager._insert(
  File "C:\Users\amand\python-cordarme\drf-api\venv\lib\site-packages\django\db\models\manager.py", line 85, in manager_method
    return getattr(self.get_queryset(), name)(*args, **kwargs)
  File "C:\Users\amand\python-cordarme\drf-api\venv\lib\site-packages\django\db\models\query.py", line 1301, in _insert
    return query.get_compiler(using=using).execute_sql(returning_fields)
  File "C:\Users\amand\python-cordarme\drf-api\venv\lib\site-packages\django\db\models\sql\compiler.py", line 1441, in execute_sql
    cursor.execute(sql, params)
  File "C:\Users\amand\python-cordarme\drf-api\venv\lib\site-packages\django\db\backends\utils.py", line 99, in execute
    return super().execute(sql, params)
  File "C:\Users\amand\python-cordarme\drf-api\venv\lib\site-packages\django\db\backends\utils.py", line 67, in execute
    return self._execute_with_wrappers(sql, params, many=False, executor=self._execute)
  File "C:\Users\amand\python-cordarme\drf-api\venv\lib\site-packages\django\db\backends\utils.py", line 76, in _execute_with_wrappers
    return executor(sql, params, many, context)
  File "C:\Users\amand\python-cordarme\drf-api\venv\lib\site-packages\django\db\backends\utils.py", line 80, in _execute
    with self.db.wrap_database_errors:
  File "C:\Users\amand\python-cordarme\drf-api\venv\lib\site-packages\django\db\utils.py", line 90, in __exit__
    raise dj_exc_value.with_traceback(traceback) from exc_value
  File "C:\Users\amand\python-cordarme\drf-api\venv\lib\site-packages\django\db\backends\utils.py", line 85, in _execute
    return self.cursor.execute(sql, params)
  File "C:\Users\amand\python-cordarme\drf-api\venv\lib\site-packages\django\db\backends\sqlite3\base.py", line 416, in execute
    return Database.Cursor.execute(self, query, params)
django.db.utils.IntegrityError: UNIQUE constraint failed: auth_user.username
2022-06-09 12:31:40,212 django.utils.autoreload INFO     C:\Users\amand\python-cordarme\drf-api\agenda\views.py changed, reloading.
2022-06-09 12:31:40,639 django.utils.autoreload INFO     C:\Users\amand\python-cordarme\drf-api\agenda\views.py changed, reloading.
2022-06-09 12:31:41,315 django.utils.autoreload INFO     Watching for file changes with StatReloader
2022-06-09 12:31:41,786 django.utils.autoreload INFO     Watching for file changes with StatReloader
2022-06-09 12:31:46,645 django.request ERROR    Internal Server Error: /api/users/
Traceback (most recent call last):
  File "C:\Users\amand\python-cordarme\drf-api\venv\lib\site-packages\django\db\backends\utils.py", line 85, in _execute
    return self.cursor.execute(sql, params)
  File "C:\Users\amand\python-cordarme\drf-api\venv\lib\site-packages\django\db\backends\sqlite3\base.py", line 416, in execute
    return Database.Cursor.execute(self, query, params)
sqlite3.IntegrityError: UNIQUE constraint failed: auth_user.username

The above exception was the direct cause of the following exception:

Traceback (most recent call last):
  File "C:\Users\amand\python-cordarme\drf-api\venv\lib\site-packages\django\core\handlers\exception.py", line 47, in inner
    response = get_response(request)
  File "C:\Users\amand\python-cordarme\drf-api\venv\lib\site-packages\django\core\handlers\base.py", line 181, in _get_response
    response = wrapped_callback(request, *callback_args, **callback_kwargs)
  File "C:\Users\amand\python-cordarme\drf-api\venv\lib\site-packages\django\views\decorators\csrf.py", line 54, in wrapped_view
    return view_func(*args, **kwargs)
  File "C:\Users\amand\python-cordarme\drf-api\venv\lib\site-packages\django\views\generic\base.py", line 69, in view
    return self.dispatch(request, *args, **kwargs)
  File "C:\Users\amand\python-cordarme\drf-api\venv\lib\site-packages\rest_framework\views.py", line 509, in dispatch
    response = self.handle_exception(exc)
  File "C:\Users\amand\python-cordarme\drf-api\venv\lib\site-packages\rest_framework\views.py", line 469, in handle_exception
    self.raise_uncaught_exception(exc)
  File "C:\Users\amand\python-cordarme\drf-api\venv\lib\site-packages\rest_framework\views.py", line 480, in raise_uncaught_exception
    raise exc
  File "C:\Users\amand\python-cordarme\drf-api\venv\lib\site-packages\rest_framework\views.py", line 506, in dispatch
    response = handler(request, *args, **kwargs)
  File "C:\Users\amand\python-cordarme\drf-api\venv\lib\site-packages\rest_framework\decorators.py", line 50, in handler
    return func(*args, **kwargs)
  File "C:\Users\amand\python-cordarme\drf-api\agenda\views.py", line 233, in users
    user_obj = User.objects.create_user(
  File "C:\Users\amand\python-cordarme\drf-api\venv\lib\site-packages\django\contrib\auth\models.py", line 152, in create_user
    return self._create_user(username, email, password, **extra_fields)
  File "C:\Users\amand\python-cordarme\drf-api\venv\lib\site-packages\django\contrib\auth\models.py", line 146, in _create_user
    user.save(using=self._db)
  File "C:\Users\amand\python-cordarme\drf-api\venv\lib\site-packages\django\contrib\auth\base_user.py", line 66, in save
    super().save(*args, **kwargs)
  File "C:\Users\amand\python-cordarme\drf-api\venv\lib\site-packages\django\db\models\base.py", line 743, in save
    self.save_base(using=using, force_insert=force_insert,
  File "C:\Users\amand\python-cordarme\drf-api\venv\lib\site-packages\django\db\models\base.py", line 780, in save_base
    updated = self._save_table(
  File "C:\Users\amand\python-cordarme\drf-api\venv\lib\site-packages\django\db\models\base.py", line 885, in _save_table
    results = self._do_insert(cls._base_manager, using, fields, returning_fields, raw)
  File "C:\Users\amand\python-cordarme\drf-api\venv\lib\site-packages\django\db\models\base.py", line 923, in _do_insert
    return manager._insert(
  File "C:\Users\amand\python-cordarme\drf-api\venv\lib\site-packages\django\db\models\manager.py", line 85, in manager_method
    return getattr(self.get_queryset(), name)(*args, **kwargs)
  File "C:\Users\amand\python-cordarme\drf-api\venv\lib\site-packages\django\db\models\query.py", line 1301, in _insert
    return query.get_compiler(using=using).execute_sql(returning_fields)
  File "C:\Users\amand\python-cordarme\drf-api\venv\lib\site-packages\django\db\models\sql\compiler.py", line 1441, in execute_sql
    cursor.execute(sql, params)
  File "C:\Users\amand\python-cordarme\drf-api\venv\lib\site-packages\django\db\backends\utils.py", line 99, in execute
    return super().execute(sql, params)
  File "C:\Users\amand\python-cordarme\drf-api\venv\lib\site-packages\django\db\backends\utils.py", line 67, in execute
    return self._execute_with_wrappers(sql, params, many=False, executor=self._execute)
  File "C:\Users\amand\python-cordarme\drf-api\venv\lib\site-packages\django\db\backends\utils.py", line 76, in _execute_with_wrappers
    return executor(sql, params, many, context)
  File "C:\Users\amand\python-cordarme\drf-api\venv\lib\site-packages\django\db\backends\utils.py", line 80, in _execute
    with self.db.wrap_database_errors:
  File "C:\Users\amand\python-cordarme\drf-api\venv\lib\site-packages\django\db\utils.py", line 90, in __exit__
    raise dj_exc_value.with_traceback(traceback) from exc_value
  File "C:\Users\amand\python-cordarme\drf-api\venv\lib\site-packages\django\db\backends\utils.py", line 85, in _execute
    return self.cursor.execute(sql, params)
  File "C:\Users\amand\python-cordarme\drf-api\venv\lib\site-packages\django\db\backends\sqlite3\base.py", line 416, in execute
    return Database.Cursor.execute(self, query, params)
django.db.utils.IntegrityError: UNIQUE constraint failed: auth_user.username
2022-06-09 12:32:22,531 django.utils.autoreload INFO     C:\Users\amand\python-cordarme\drf-api\agenda\views.py changed, reloading.
2022-06-09 12:32:22,596 django.utils.autoreload INFO     C:\Users\amand\python-cordarme\drf-api\agenda\views.py changed, reloading.
2022-06-09 12:32:23,599 django.utils.autoreload INFO     Watching for file changes with StatReloader
2022-06-09 12:32:23,627 django.utils.autoreload INFO     Watching for file changes with StatReloader
2022-06-09 12:32:24,415 django.request WARNING  Bad Request: /api/users/
2022-06-09 12:32:32,338 django.request WARNING  Bad Request: /api/users/
2022-06-09 12:32:47,485 django.request WARNING  Bad Request: /api/users/
2022-06-09 12:32:58,935 django.utils.autoreload INFO     C:\Users\amand\python-cordarme\drf-api\agenda\views.py changed, reloading.
2022-06-09 12:32:59,026 django.utils.autoreload INFO     C:\Users\amand\python-cordarme\drf-api\agenda\views.py changed, reloading.
2022-06-09 12:33:00,048 django.utils.autoreload INFO     Watching for file changes with StatReloader
2022-06-09 12:33:00,182 django.utils.autoreload INFO     Watching for file changes with StatReloader
2022-06-09 12:33:25,438 django.utils.autoreload INFO     C:\Users\amand\python-cordarme\drf-api\agenda\views.py changed, reloading.
2022-06-09 12:33:25,476 django.utils.autoreload INFO     C:\Users\amand\python-cordarme\drf-api\agenda\views.py changed, reloading.
2022-06-09 12:33:26,475 django.utils.autoreload INFO     Watching for file changes with StatReloader
2022-06-09 12:33:26,493 django.utils.autoreload INFO     Watching for file changes with StatReloader
2022-06-09 12:36:51,482 django.request WARNING  Forbidden: /api/users/
2022-06-09 12:36:53,096 django.request WARNING  Forbidden: /api/users/
2022-06-09 12:36:58,177 django.request WARNING  Forbidden: /api/users/
2022-06-09 12:39:38,515 django.request WARNING  Forbidden: /api/users/
2022-06-09 12:39:40,015 django.request WARNING  Forbidden: /api/users/
2022-06-09 12:39:52,210 django.request WARNING  Forbidden: /api/users/
2022-06-09 12:40:03,817 django.request WARNING  Forbidden: /api/users/
2022-06-09 12:40:08,969 django.request WARNING  Forbidden: /api/users/
2022-06-09 12:40:28,662 django.request WARNING  Forbidden: /api/users/
2022-06-09 12:40:32,240 django.request WARNING  Forbidden: /api/users/
2022-06-09 12:40:53,339 django.request WARNING  Forbidden: /api/users/
2022-06-09 12:41:00,041 django.request WARNING  Forbidden: /api/users/
2022-06-09 12:41:07,234 django.utils.autoreload INFO     C:\Users\amand\python-cordarme\drf-api\agenda\urls.py changed, reloading.
2022-06-09 12:41:07,943 django.utils.autoreload INFO     C:\Users\amand\python-cordarme\drf-api\agenda\urls.py changed, reloading.
2022-06-09 12:41:08,396 django.utils.autoreload INFO     Watching for file changes with StatReloader
2022-06-09 12:41:08,867 django.utils.autoreload INFO     Watching for file changes with StatReloader
